Workbook

Sheet DUKB
A1: ULIN | C1: : | D1: NL ( AWIE )
A2: PARTAI | C2: : | D2: A/25/L02/GLI/ULIN | R2: =M3-R3 -> 14.04 | U2: Ttl vol trimming | V2: Prosentase
A3: NAMA PERUSAHAAN | C3: : | D3: PT. GEMA LESTARI INDONESIA (SAWMILL) | M3: =SUBTOTAL(109,M5:M560) -> 239.23 | O3: =SUM(O6:O560) -> 1.72 | Q3: =SUM(Q6:Q560) -> 12.32 | R3: =SUBTOTAL(109,R6:R560) -> 225.19 | U3: =O3+Q3 -> 14.04 | V3: =U3/M3 -> 0.058688292
A4: Nomor | D4: Jenis | E4: Qty | F4: Pjng | G4: Diameter | K4: Ø | L4: Ø2 | M4: Bruto | N4: Gerowong | P4: Trimming | R4: Netto | AD4: VLOOKUP(KOLOM AI, NOMOR URUT SUPPLY LOG,2,FALSE) | AF4: TRIMING | AN4: BLNC
A5: Urut | B5: Log | C5: Kode | G5: I | H5: II | I5: III | J5: IV | M5: M3 | N5: Cm | O5: M3 | P5: Pjng | Q5: M3 | R5: M31 | S5: ID BARCODE | T5: KLS DMTR | U5: IN | V5: OUT | W5: no di LL | AE5: Control No Log | AF5: A | AG5: B | AH5: C | AI5: D | AJ5: E | AK5: F | AL5: G
A6: 199 | B6: 419 | C6: NL | D6: Ulin | E6: 1 | F6: 11 | G6: 39 | H6: 43 | I6: 25 | J6: 32 | K6: =+(G6+H6+I6+J6)/4 -> 34.75 | L6: =ROUND(K6,0) -> 35 | M6: =+ROUND((L6*L6*F6*0.7854)/10000,2) -> 1.06 | O6: =ROUND(((N6*N6*(F6-P6)*0.7854)/10000),2) -> 0 | P6: 1.5 | Q6: =+ROUND((L6*L6*P6*0.7854)/10000,2) -> 0.14 | R6: =+M6-O6-Q6 -> 0.92 | T6: =IF(L6<40,"30 - 39 Cm",IF(L6<50,"40 - 49 Cm",IF(L6<60,"50 - 59 Cm",IF(L6<70,"60 - 69 Cm",IF(L6<80,"70 - 79 Cm",IF(L6<90,"80 - 89 Cm",IF(L6<100,"90 - 99 Cm",IF(L6>99,"100 Cm Up")))))))) -> 30 - 39 Cm | U6: 45968 | V6: =VLOOKUP(A6,'Supply Log'!$E$6:$V$1999,18,FALSE) -> 45971 | W6: A01- | X6: NL | Y6: U01- | AA6: /25- | AB6: =W6&C6&B6&AA6&Y6&A6 -> A01-NL419/25-U01-199 | AC6: 199 | AD6: 1 | AE6: =IF(COUNTIF($B$2:$B$46837,B6)>1,"DOUBLE","") | AF6: 4.4 | AG6: 4.3 | AH6: 2.3 | AN6: =F6-AF6-AG6-AH6-AI6-AJ6-AK6-AL6-AM6 -> 0
A7: 200 | B7: 411 | C7: NL | D7: Ulin | E7: 1 | F7: 14.2 | G7: 38 | H7: 44 | I7: 30 | J7: 34 | K7: =+(G7+H7+I7+J7)/4 -> 36.5 | L7: =ROUND(K7,0) -> 37 | M7: =+ROUND((L7*L7*F7*0.7854)/10000,2) -> 1.53 | O7: =ROUND(((N7*N7*(F7-P7)*0.7854)/10000),2) -> 0 | P7: 0.5 | Q7: =+ROUND((L7*L7*P7*0.7854)/10000,2) -> 0.05 | R7: =+M7-O7-Q7 -> 1.48 | T7: =IF(L7<40,"30 - 39 Cm",IF(L7<50,"40 - 49 Cm",IF(L7<60,"50 - 59 Cm",IF(L7<70,"60 - 69 Cm",IF(L7<80,"70 - 79 Cm",IF(L7<90,"80 - 89 Cm",IF(L7<100,"90 - 99 Cm",IF(L7>99,"100 Cm Up")))))))) -> 30 - 39 Cm | U7: 45968 | V7: =VLOOKUP(A7,'Supply Log'!$E$6:$V$1999,18,FALSE) -> 45971 | W7: A01- | X7: NL | Y7: U01- | AA7: /25- | AB7: =W7&C7&B7&AA7&Y7&A7 -> A01-NL411/25-U01-200 | AC7: 200 | AD7: 2 | AE7: =IF(COUNTIF($B$2:$B$46837,B7)>1,"DOUBLE","") | AF7: 5 | AG7: 4.9 | AH7: 4.3 | AN7: =F7-AF7-AG7-AH7-AI7-AJ7-AK7-AL7-AM7 -> -8.8817842e-16
A8: 196 | B8: 425 | C8: NL | D8: Ulin | E8: 1 | F8: 6.6 | G8: 36 | H8: 40 | I8: 31 | J8: 35 | K8: =+(G8+H8+I8+J8)/4 -> 35.5 | L8: =ROUND(K8,0) -> 36 | M8: =+ROUND((L8*L8*F8*0.7854)/10000,2) -> 0.67 | O8: =ROUND(((N8*N8*(F8-P8)*0.7854)/10000),2) -> 0 | Q8: =+ROUND((L8*L8*P8*0.7854)/10000,2) -> 0 | R8: =+M8-O8-Q8 -> 0.67 | T8: =IF(L8<40,"30 - 39 Cm",IF(L8<50,"40 - 49 Cm",IF(L8<60,"50 - 59 Cm",IF(L8<70,"60 - 69 Cm",IF(L8<80,"70 - 79 Cm",IF(L8<90,"80 - 89 Cm",IF(L8<100,"90 - 99 Cm",IF(L8>99,"100 Cm Up")))))))) -> 30 - 39 Cm | U8: 45968 | V8: =VLOOKUP(A8,'Supply Log'!$E$6:$V$1999,18,FALSE) -> 45971 | W8: A01- | X8: NL | Y8: U01- | AA8: /25- | AB8: =W8&C8&B8&AA8&Y8&A8 -> A01-NL425/25-U01-196 | AC8: 196 | AD8: 3 | AE8: =IF(COUNTIF($B$2:$B$46837,B8)>1,"DOUBLE","") | AF8: 3.7 | AG8: 2.9 | AN8: =F8-AF8-AG8-AH8-AI8-AJ8-AK8-AL8-AM8 -> -4.4408921e-16
A9: 197 | B9: 404 | C9: NL | D9: Ulin | E9: 1 | F9: 11.5 | G9: 34 | H9: 38 | I9: 26 | J9: 31 | K9: =+(G9+H9+I9+J9)/4 -> 32.25 | L9: =ROUND(K9,0) -> 32 | M9: =+ROUND((L9*L9*F9*0.7854)/10000,2) -> 0.92 | O9: =ROUND(((N9*N9*(F9-P9)*0.7854)/10000),2) -> 0 | P9: 0.5 | Q9: =+ROUND((L9*L9*P9*0.7854)/10000,2) -> 0.04 | R9: =+M9-O9-Q9 -> 0.88 | T9: =IF(L9<40,"30 - 39 Cm",IF(L9<50,"40 - 49 Cm",IF(L9<60,"50 - 59 Cm",IF(L9<70,"60 - 69 Cm",IF(L9<80,"70 - 79 Cm",IF(L9<90,"80 - 89 Cm",IF(L9<100,"90 - 99 Cm",IF(L9>99,"100 Cm Up")))))))) -> 30 - 39 Cm | U9: 45968 | V9: =VLOOKUP(A9,'Supply Log'!$E$6:$V$1999,18,FALSE) -> 45971 | W9: A01- | X9: NL | Y9: U01- | AA9: /25- | AB9: =W9&C9&B9&AA9&Y9&A9 -> A01-NL404/25-U01-197 | AC9: 197 | AD9: 4 | AE9: =IF(COUNTIF($B$2:$B$46837,B9)>1,"DOUBLE","") | AF9: 4.4 | AG9: 4.1 | AH9: 3 | AN9: =F9-AF9-AG9-AH9-AI9-AJ9-AK9-AL9-AM9 -> 0
A10: 198 | B10: 921 | C10: NL | D10: Ulin | E10: 1 | F10: 9.1 | G10: 30 | H10: 32 | I10: 41 | J10: 47 | K10: =+(G10+H10+I10+J10)/4 -> 37.5 | L10: =ROUND(K10,0) -> 38 | M10: =+ROUND((L10*L10*F10*0.7854)/10000,2) -> 1.03 | O10: =ROUND(((N10*N10*(F10-P10)*0.7854)/10000),2) -> 0 | P10: 0.5 | Q10: =+ROUND((L10*L10*P10*0.7854)/10000,2) -> 0.06 | R10: =+M10-O10-Q10 -> 0.97 | T10: =IF(L10<40,"30 - 39 Cm",IF(L10<50,"40 - 49 Cm",IF(L10<60,"50 - 59 Cm",IF(L10<70,"60 - 69 Cm",IF(L10<80,"70 - 79 Cm",IF(L10<90,"80 - 89 Cm",IF(L10<100,"90 - 99 Cm",IF(L10>99,"100 Cm Up")))))))) -> 30 - 39 Cm | U10: 45968 | V10: =VLOOKUP(A10,'Supply Log'!$E$6:$V$1999,18,FALSE) -> 45971 | W10: A01- | X10: NL | Y10: U01- | AA10: /25- | AB10: =W10&C10&B10&AA10&Y10&A10 -> A01-NL921/25-U01-198 | AC10: 198 | AD10: 5 | AE10: =IF(COUNTIF($B$2:$B$46837,B10)>1,"DOUBLE","") | AF10: 2.7 | AG10: 3.3 | AH10: 3.1 | AN10: =F10-AF10-AG10-AH10-AI10-AJ10-AK10-AL10-AM10 -> -4.4408921e-16
A11: 195 | B11: 611 | C11: NL | D11: Ulin | E11: 1 | F11: 17.9 | G11: 26 | H11: 30 | I11: 48 | J11: 49 | K11: =+(G11+H11+I11+J11)/4 -> 38.25 | L11: =ROUND(K11,0) -> 38 | M11: =+ROUND((L11*L11*F11*0.7854)/10000,2) -> 2.03 | O11: =ROUND(((N11*N11*(F11-P11)*0.7854)/10000),2) -> 0 | P11: 1 | Q11: =+ROUND((L11*L11*P11*0.7854)/10000,2) -> 0.11 | R11: =+M11-O11-Q11 -> 1.92 | T11: =IF(L11<40,"30 - 39 Cm",IF(L11<50,"40 - 49 Cm",IF(L11<60,"50 - 59 Cm",IF(L11<70,"60 - 69 Cm",IF(L11<80,"70 - 79 Cm",IF(L11<90,"80 - 89 Cm",IF(L11<100,"90 - 99 Cm",IF(L11>99,"100 Cm Up")))))))) -> 30 - 39 Cm | U11: 45968 | V11: =VLOOKUP(A11,'Supply Log'!$E$6:$V$1999,18,FALSE) -> 45971 | W11: A01- | X11: NL | Y11: U01- | AA11: /25- | AB11: =W11&C11&B11&AA11&Y11&A11 -> A01-NL611/25-U01-195 | AC11: 195 | AD11: 6 | AE11: =IF(COUNTIF($B$2:$B$46837,B11)>1,"DOUBLE","") | AF11: 3.7 | AG11: 4.3 | AH11: 4.9 | AI11: 5 | AN11: =F11-AF11-AG11-AH11-AI11-AJ11-AK11-AL11-AM11 -> -1.7763568e-15
A12: 192 | B12: 430 | C12: NL | D12: Ulin | E12: 1 | F12: 11 | G12: 28 | H12: 31 | I12: 35 | J12: 40 | K12: =+(G12+H12+I12+J12)/4 -> 33.5 | L12: =ROUND(K12,0) -> 34 | M12: =+ROUND((L12*L12*F12*0.7854)/10000,2) -> 1 | O12: =ROUND(((N12*N12*(F12-P12)*0.7854)/10000),2) -> 0 | Q12: =+ROUND((L12*L12*P12*0.7854)/10000,2) -> 0 | R12: =+M12-O12-Q12 -> 1 | T12: =IF(L12<40,"30 - 39 Cm",IF(L12<50,"40 - 49 Cm",IF(L12<60,"50 - 59 Cm",IF(L12<70,"60 - 69 Cm",IF(L12<80,"70 - 79 Cm",IF(L12<90,"80 - 89 Cm",IF(L12<100,"90 - 99 Cm",IF(L12>99,"100 Cm Up")))))))) -> 30 - 39 Cm | U12: 45968 | V12: =VLOOKUP(A12,'Supply Log'!$E$6:$V$1999,18,FALSE) -> 45971 | W12: A01- | X12: NL | Y12: U01- | AA12: /25- | AB12: =W12&C12&B12&AA12&Y12&A12 -> A01-NL430/25-U01-192 | AC12: 192 | AD12: 7 | AE12: =IF(COUNTIF($B$2:$B$46837,B12)>1,"DOUBLE","") | AF12: 2.8 | AG12: 4.1 | AH12: 4.1 | AN12: =F12-AF12-AG12-AH12-AI12-AJ12-AK12-AL12-AM12 -> 0
A13: 193 | B13: 413 | C13: NL | D13: Ulin | E13: 1 | F13: 5.3 | G13: 35 | H13: 27 | I13: 26 | J13: 31 | K13: =+(G13+H13+I13+J13)/4 -> 29.75 | L13: =ROUND(K13,0) -> 30 | M13: =+ROUND((L13*L13*F13*0.7854)/10000,2) -> 0.37 | O13: =ROUND(((N13*N13*(F13-P13)*0.7854)/10000),2) -> 0 | P13: 0.5 | Q13: =+ROUND((L13*L13*P13*0.7854)/10000,2) -> 0.04 | R13: =+M13-O13-Q13 -> 0.33 | T13: =IF(L13<40,"30 - 39 Cm",IF(L13<50,"40 - 49 Cm",IF(L13<60,"50 - 59 Cm",IF(L13<70,"60 - 69 Cm",IF(L13<80,"70 - 79 Cm",IF(L13<90,"80 - 89 Cm",IF(L13<100,"90 - 99 Cm",IF(L13>99,"100 Cm Up")))))))) -> 30 - 39 Cm | U13: 45968 | V13: =VLOOKUP(A13,'Supply Log'!$E$6:$V$1999,18,FALSE) -> 45971 | W13: A01- | X13: NL | Y13: U01- | AA13: /25- | AB13: =W13&C13&B13&AA13&Y13&A13 -> A01-NL413/25-U01-193 | AC13: 193 | AD13: 8 | AE13: =IF(COUNTIF($B$2:$B$46837,B13)>1,"DOUBLE","") | AF13: 2.95 | AG13: 2.35 | AN13: =F13-AF13-AG13-AH13-AI13-AJ13-AK13-AL13-AM13 -> -4.4408921e-16
A14: 194 | B14: 454 | C14: NL | D14: Ulin | E14: 1 | F14: 8.8 | G14: 34 | H14: 31 | I14: 33 | J14: 39 | K14: =+(G14+H14+I14+J14)/4 -> 34.25 | L14: =ROUND(K14,0) -> 34 | M14: =+ROUND((L14*L14*F14*0.7854)/10000,2) -> 0.8 | O14: =ROUND(((N14*N14*(F14-P14)*0.7854)/10000),2) -> 0 | P14: 1 | Q14: =+ROUND((L14*L14*P14*0.7854)/10000,2) -> 0.09 | R14: =+M14-O14-Q14 -> 0.71 | T14: =IF(L14<40,"30 - 39 Cm",IF(L14<50,"40 - 49 Cm",IF(L14<60,"50 - 59 Cm",IF(L14<70,"60 - 69 Cm",IF(L14<80,"70 - 79 Cm",IF(L14<90,"80 - 89 Cm",IF(L14<100,"90 - 99 Cm",IF(L14>99,"100 Cm Up")))))))) -> 30 - 39 Cm | U14: 45968 | V14: =VLOOKUP(A14,'Supply Log'!$E$6:$V$1999,18,FALSE) -> 45971 | W14: A01- | X14: NL | Y14: U01- | AA14: /25- | AB14: =W14&C14&B14&AA14&Y14&A14 -> A01-NL454/25-U01-194 | AC14: 194 | AD14: 9 | AE14: =IF(COUNTIF($B$2:$B$46837,B14)>1,"DOUBLE","") | AF14: 2.8 | AG14: 3 | AH14: 3 | AN14: =F14-AF14-AG14-AH14-AI14-AJ14-AK14-AL14-AM14 -> 8.8817842e-16
A15: 189 | B15: 402 | C15: NL | D15: Ulin | E15: 1 | F15: 13.3 | G15: 27 | H15: 32 | I15: 36 | J15: 42 | K15: =+(G15+H15+I15+J15)/4 -> 34.25 | L15: =ROUND(K15,0) -> 34 | M15: =+ROUND((L15*L15*F15*0.7854)/10000,2) -> 1.21 | O15: =ROUND(((N15*N15*(F15-P15)*0.7854)/10000),2) -> 0 | P15: 0.5 | Q15: =+ROUND((L15*L15*P15*0.7854)/10000,2) -> 0.05 | R15: =+M15-O15-Q15 -> 1.16 | T15: =IF(L15<40,"30 - 39 Cm",IF(L15<50,"40 - 49 Cm",IF(L15<60,"50 - 59 Cm",IF(L15<70,"60 - 69 Cm",IF(L15<80,"70 - 79 Cm",IF(L15<90,"80 - 89 Cm",IF(L15<100,"90 - 99 Cm",IF(L15>99,"100 Cm Up")))))))) -> 30 - 39 Cm | U15: 45968 | V15: =VLOOKUP(A15,'Supply Log'!$E$6:$V$1999,18,FALSE) -> 45971 | W15: A01- | X15: NL | Y15: U01- | AA15: /25- | AB15: =W15&C15&B15&AA15&Y15&A15 -> A01-NL402/25-U01-189 | AC15: 189 | AD15: 10 | AE15: =IF(COUNTIF($B$2:$B$46837,B15)>1,"DOUBLE","") | AF15: 3.3 | AG15: 3.3 | AH15: 3.3 | AI15: 3.4 | AN15: =F15-AF15-AG15-AH15-AI15-AJ15-AK15-AL15-AM15 -> 4.4408921e-16
A16: 190 | B16: 428 | C16: NL | D16: Ulin | E16: 1 | F16: 7.5 | G16: 31 | H16: 39 | I16: 27 | J16: 38 | K16: =+(G16+H16+I16+J16)/4 -> 33.75 | L16: =ROUND(K16,0) -> 34 | M16: =+ROUND((L16*L16*F16*0.7854)/10000,2) -> 0.68 | O16: =ROUND(((N16*N16*(F16-P16)*0.7854)/10000),2) -> 0 | P16: 0.5 | Q16: =+ROUND((L16*L16*P16*0.7854)/10000,2) -> 0.05 | R16: =+M16-O16-Q16 -> 0.63 | T16: =IF(L16<40,"30 - 39 Cm",IF(L16<50,"40 - 49 Cm",IF(L16<60,"50 - 59 Cm",IF(L16<70,"60 - 69 Cm",IF(L16<80,"70 - 79 Cm",IF(L16<90,"80 - 89 Cm",IF(L16<100,"90 - 99 Cm",IF(L16>99,"100 Cm Up")))))))) -> 30 - 39 Cm | U16: 45968 | V16: =VLOOKUP(A16,'Supply Log'!$E$6:$V$1999,18,FALSE) -> 45971 | W16: A01- | X16: NL | Y16: U01- | AA16: /25- | AB16: =W16&C16&B16&AA16&Y16&A16 -> A01-NL428/25-U01-190 | AC16: 190 | AD16: 11 | AE16: =IF(COUNTIF($B$2:$B$46837,B16)>1,"DOUBLE","") | AF16: 2.2 | AG16: 3.1 | AH16: 2.2 | AN16: =F16-AF16-AG16-AH16-AI16-AJ16-AK16-AL16-AM16 -> -4.4408921e-16
A17: 191 | B17: 451 | C17: NL | D17: Ulin | E17: 1 | F17: 8.1 | G17: 36 | H17: 41 | I17: 28 | J17: 36 | K17: =+(G17+H17+I17+J17)/4 -> 35.25 | L17: =ROUND(K17,0) -> 35 | M17: =+ROUND((L17*L17*F17*0.7854)/10000,2) -> 0.78 | O17: =ROUND(((N17*N17*(F17-P17)*0.7854)/10000),2) -> 0 | Q17: =+ROUND((L17*L17*P17*0.7854)/10000,2) -> 0 | R17: =+M17-O17-Q17 -> 0.78 | T17: =IF(L17<40,"30 - 39 Cm",IF(L17<50,"40 - 49 Cm",IF(L17<60,"50 - 59 Cm",IF(L17<70,"60 - 69 Cm",IF(L17<80,"70 - 79 Cm",IF(L17<90,"80 - 89 Cm",IF(L17<100,"90 - 99 Cm",IF(L17>99,"100 Cm Up")))))))) -> 30 - 39 Cm | U17: 45968 | V17: =VLOOKUP(A17,'Supply Log'!$E$6:$V$1999,18,FALSE) -> 45971 | W17: A01- | X17: NL | Y17: U01- | AA17: /25- | AB17: =W17&C17&B17&AA17&Y17&A17 -> A01-NL451/25-U01-191 | AC17: 191 | AD17: 12 | AE17: =IF(COUNTIF($B$2:$B$46837,B17)>1,"DOUBLE","") | AF17: 4.05 | AG17: 4.05 | AN17: =F17-AF17-AG17-AH17-AI17-AJ17-AK17-AL17-AM17 -> 0
A18: 187 | B18: 453 | C18: NL | D18: Ulin | E18: 1 | F18: 13.3 | G18: 30 | H18: 35 | I18: 43 | J18: 44 | K18: =+(G18+H18+I18+J18)/4 -> 38 | L18: =ROUND(K18,0) -> 38 | M18: =+ROUND((L18*L18*F18*0.7854)/10000,2) -> 1.51 | O18: =ROUND(((N18*N18*(F18-P18)*0.7854)/10000),2) -> 0 | P18: 1.5 | Q18: =+ROUND((L18*L18*P18*0.7854)/10000,2) -> 0.17 | R18: =+M18-O18-Q18 -> 1.34 | T18: =IF(L18<40,"30 - 39 Cm",IF(L18<50,"40 - 49 Cm",IF(L18<60,"50 - 59 Cm",IF(L18<70,"60 - 69 Cm",IF(L18<80,"70 - 79 Cm",IF(L18<90,"80 - 89 Cm",IF(L18<100,"90 - 99 Cm",IF(L18>99,"100 Cm Up")))))))) -> 30 - 39 Cm | U18: 45968 | V18: =VLOOKUP(A18,'Supply Log'!$E$6:$V$1999,18,FALSE) -> 45971 | W18: A01- | X18: NL | Y18: U01- | AA18: /25- | AB18: =W18&C18&B18&AA18&Y18&A18 -> A01-NL453/25-U01-187 | AC18: 187 | AD18: 13 | AE18: =IF(COUNTIF($B$2:$B$46837,B18)>1,"DOUBLE","") | AF18: 2.2 | AG18: 3.7 | AH18: 4.3 | AI18: 3.1 | AN18: =F18-AF18-AG18-AH18-AI18-AJ18-AK18-AL18-AM18 -> 1.3322676e-15
A19: 188 | B19: 876 | C19: NL | D19: Ulin | E19: 1 | F19: 13 | G19: 28 | H19: 25 | I19: 31 | J19: 41 | K19: =+(G19+H19+I19+J19)/4 -> 31.25 | L19: =ROUND(K19,0) -> 31 | M19: =+ROUND((L19*L19*F19*0.7854)/10000,2) -> 0.98 | O19: =ROUND(((N19*N19*(F19-P19)*0.7854)/10000),2) -> 0 | P19: 0.5 | Q19: =+ROUND((L19*L19*P19*0.7854)/10000,2) -> 0.04 | R19: =+M19-O19-Q19 -> 0.94 | T19: =IF(L19<40,"30 - 39 Cm",IF(L19<50,"40 - 49 Cm",IF(L19<60,"50 - 59 Cm",IF(L19<70,"60 - 69 Cm",IF(L19<80,"70 - 79 Cm",IF(L19<90,"80 - 89 Cm",IF(L19<100,"90 - 99 Cm",IF(L19>99,"100 Cm Up")))))))) -> 30 - 39 Cm | U19: 45968 | V19: =VLOOKUP(A19,'Supply Log'!$E$6:$V$1999,18,FALSE) -> 45971 | W19: A01- | X19: NL | Y19: U01- | AA19: /25- | AB19: =W19&C19&B19&AA19&Y19&A19 -> A01-NL876/25-U01-188 | AC19: 188 | AD19: 14 | AE19: =IF(COUNTIF($B$2:$B$46837,B19)>1,"DOUBLE","") | AF19: 3 | AG19: 2.3 | AH19: 4.1 | AI19: 3.6 | AN19: =F19-AF19-AG19-AH19-AI19-AJ19-AK19-AL19-AM19 -> 4.4408921e-16
A20: 185 | B20: 423 | C20: NL | D20: Ulin | E20: 1 | F20: 9.9 | G20: 32 | H20: 38 | I20: 39 | J20: 44 | K20: =+(G20+H20+I20+J20)/4 -> 38.25 | L20: =ROUND(K20,0) -> 38 | M20: =+ROUND((L20*L20*F20*0.7854)/10000,2) -> 1.12 | O20: =ROUND(((N20*N20*(F20-P20)*0.7854)/10000),2) -> 0 | P20: 2.7 | Q20: =+ROUND((L20*L20*P20*0.7854)/10000,2) -> 0.31 | R20: =+M20-O20-Q20 -> 0.81 | T20: =IF(L20<40,"30 - 39 Cm",IF(L20<50,"40 - 49 Cm",IF(L20<60,"50 - 59 Cm",IF(L20<70,"60 - 69 Cm",IF(L20<80,"70 - 79 Cm",IF(L20<90,"80 - 89 Cm",IF(L20<100,"90 - 99 Cm",IF(L20>99,"100 Cm Up")))))))) -> 30 - 39 Cm | U20: 45968 | V20: =VLOOKUP(A20,'Supply Log'!$E$6:$V$1999,18,FALSE) -> 45971 | W20: A01- | X20: NL | Y20: U01- | AA20: /25- | AB20: =W20&C20&B20&AA20&Y20&A20 -> A01-NL423/25-U01-185 | AC20: 185 | AD20: 15 | AE20: =IF(COUNTIF($B$2:$B$46837,B20)>1,"DOUBLE","") | AF20: 3.3 | AG20: 3.3 | AH20: 3.3 | AN20: =F20-AF20-AG20-AH20-AI20-AJ20-AK20-AL20-AM20 -> 8.8817842e-16
A21: 186 | B21: 452 | C21: NL | D21: Ulin | E21: 1 | F21: 6.3 | G21: 30 | H21: 28 | I21: 34 | J21: 38 | K21: =+(G21+H21+I21+J21)/4 -> 32.5 | L21: =ROUND(K21,0) -> 33 | M21: =+ROUND((L21*L21*F21*0.7854)/10000,2) -> 0.54 | O21: =ROUND(((N21*N21*(F21-P21)*0.7854)/10000),2) -> 0 | Q21: =+ROUND((L21*L21*P21*0.7854)/10000,2) -> 0 | R21: =+M21-O21-Q21 -> 0.54 | T21: =IF(L21<40,"30 - 39 Cm",IF(L21<50,"40 - 49 Cm",IF(L21<60,"50 - 59 Cm",IF(L21<70,"60 - 69 Cm",IF(L21<80,"70 - 79 Cm",IF(L21<90,"80 - 89 Cm",IF(L21<100,"90 - 99 Cm",IF(L21>99,"100 Cm Up")))))))) -> 30 - 39 Cm | U21: 45968 | V21: =VLOOKUP(A21,'Supply Log'!$E$6:$V$1999,18,FALSE) -> 45971 | W21: A01- | X21: NL | Y21: U01- | AA21: /25- | AB21: =W21&C21&B21&AA21&Y21&A21 -> A01-NL452/25-U01-186 | AC21: 186 | AD21: 16 | AE21: =IF(COUNTIF($B$2:$B$46837,B21)>1,"DOUBLE","") | AF21: 3 | AG21: 3.3 | AN21: =F21-AF21-AG21-AH21-AI21-AJ21-AK21-AL21-AM21 -> 0
A22: 183 | B22: 487 | C22: NL | D22: Ulin | E22: 1 | F22: 6.5 | G22: 30 | H22: 33 | I22: 40 | J22: 41 | K22: =+(G22+H22+I22+J22)/4 -> 36 | L22: =ROUND(K22,0) -> 36 | M22: =+ROUND((L22*L22*F22*0.7854)/10000,2) -> 0.66 | O22: =ROUND(((N22*N22*(F22-P22)*0.7854)/10000),2) -> 0 | P22: 0.5 | Q22: =+ROUND((L22*L22*P22*0.7854)/10000,2) -> 0.05 | R22: =+M22-O22-Q22 -> 0.61 | T22: =IF(L22<40,"30 - 39 Cm",IF(L22<50,"40 - 49 Cm",IF(L22<60,"50 - 59 Cm",IF(L22<70,"60 - 69 Cm",IF(L22<80,"70 - 79 Cm",IF(L22<90,"80 - 89 Cm",IF(L22<100,"90 - 99 Cm",IF(L22>99,"100 Cm Up")))))))) -> 30 - 39 Cm | U22: 45968 | V22: =VLOOKUP(A22,'Supply Log'!$E$6:$V$1999,18,FALSE) -> 45971 | W22: A01- | X22: NL | Y22: U01- | AA22: /25- | AB22: =W22&C22&B22&AA22&Y22&A22 -> A01-NL487/25-U01-183 | AC22: 183 | AD22: 17 | AE22: =IF(COUNTIF($B$2:$B$46837,B22)>1,"DOUBLE","") | AF22: 3.25 | AG22: 3.25 | AN22: =F22-AF22-AG22-AH22-AI22-AJ22-AK22-AL22-AM22 -> 0
A23: 181 | B23: 920 | C23: NL | D23: Ulin | E23: 1 | F23: 10.9 | G23: 29 | H23: 37 | I23: 33 | J23: 45 | K23: =+(G23+H23+I23+J23)/4 -> 36 | L23: =ROUND(K23,0) -> 36 | M23: =+ROUND((L23*L23*F23*0.7854)/10000,2) -> 1.11 | O23: =ROUND(((N23*N23*(F23-P23)*0.7854)/10000),2) -> 0 | P23: 0.7 | Q23: =+ROUND((L23*L23*P23*0.7854)/10000,2) -> 0.07 | R23: =+M23-O23-Q23 -> 1.04 | T23: =IF(L23<40,"30 - 39 Cm",IF(L23<50,"40 - 49 Cm",IF(L23<60,"50 - 59 Cm",IF(L23<70,"60 - 69 Cm",IF(L23<80,"70 - 79 Cm",IF(L23<90,"80 - 89 Cm",IF(L23<100,"90 - 99 Cm",IF(L23>99,"100 Cm Up")))))))) -> 30 - 39 Cm | U23: 45968 | V23: =VLOOKUP(A23,'Supply Log'!$E$6:$V$1999,18,FALSE) -> 45971 | W23: A01- | X23: NL | Y23: U01- | AA23: /25- | AB23: =W23&C23&B23&AA23&Y23&A23 -> A01-NL920/25-U01-181 | AC23: 181 | AD23: 18 | AE23: =IF(COUNTIF($B$2:$B$46837,B23)>1,"DOUBLE","") | AF23: 3.3 | AG23: 4 | AH23: 3.6 | AN23: =F23-AF23-AG23-AH23-AI23-AJ23-AK23-AL23-AM23 -> 4.4408921e-16
A24: 182 | B24: 789 | C24: NL | D24: Ulin | E24: 1 | F24: 11.7 | G24: 41 | H24: 47 | I24: 31 | J24: 32 | K24: =+(G24+H24+I24+J24)/4 -> 37.75 | L24: =ROUND(K24,0) -> 38 | M24: =+ROUND((L24*L24*F24*0.7854)/10000,2) -> 1.33 | O24: =ROUND(((N24*N24*(F24-P24)*0.7854)/10000),2) -> 0 | P24: 0.8 | Q24: =+ROUND((L24*L24*P24*0.7854)/10000,2) -> 0.09 | R24: =+M24-O24-Q24 -> 1.24 | T24: =IF(L24<40,"30 - 39 Cm",IF(L24<50,"40 - 49 Cm",IF(L24<60,"50 - 59 Cm",IF(L24<70,"60 - 69 Cm",IF(L24<80,"70 - 79 Cm",IF(L24<90,"80 - 89 Cm",IF(L24<100,"90 - 99 Cm",IF(L24>99,"100 Cm Up")))))))) -> 30 - 39 Cm | U24: 45968 | V24: =VLOOKUP(A24,'Supply Log'!$E$6:$V$1999,18,FALSE) -> 45971 | W24: A01- | X24: NL | Y24: U01- | AA24: /25- | AB24: =W24&C24&B24&AA24&Y24&A24 -> A01-NL789/25-U01-182 | AC24: 182 | AD24: 19 | AE24: =IF(COUNTIF($B$2:$B$46837,B24)>1,"DOUBLE","") | AF24: 3.5 | AG24: 4.1 | AH24: 4.1 | AN24: =F24-AF24-AG24-AH24-AI24-AJ24-AK24-AL24-AM24 -> 0
A25: 184 | B25: 448 | C25: NL | D25: Ulin | E25: 1 | F25: 4.9 | G25: 30 | H25: 30 | I25: 33 | J25: 35 | K25: =+(G25+H25+I25+J25)/4 -> 32 | L25: =ROUND(K25,0) -> 32 | M25: =+ROUND((L25*L25*F25*0.7854)/10000,2) -> 0.39 | O25: =ROUND(((N25*N25*(F25-P25)*0.7854)/10000),2) -> 0 | Q25: =+ROUND((L25*L25*P25*0.7854)/10000,2) -> 0 | R25: =+M25-O25-Q25 -> 0.39 | T25: =IF(L25<40,"30 - 39 Cm",IF(L25<50,"40 - 49 Cm",IF(L25<60,"50 - 59 Cm",IF(L25<70,"60 - 69 Cm",IF(L25<80,"70 - 79 Cm",IF(L25<90,"80 - 89 Cm",IF(L25<100,"90 - 99 Cm",IF(L25>99,"100 Cm Up")))))))) -> 30 - 39 Cm | U25: 45968 | V25: =VLOOKUP(A25,'Supply Log'!$E$6:$V$1999,18,FALSE) -> 45971 | W25: A01- | X25: NL | Y25: U01- | AA25: /25- | AB25: =W25&C25&B25&AA25&Y25&A25 -> A01-NL448/25-U01-184 | AC25: 184 | AD25: 20 | AE25: =IF(COUNTIF($B$2:$B$46837,B25)>1,"DOUBLE","") | AF25: 4.9 | AN25: =F25-AF25-AG25-AH25-AI25-AJ25-AK25-AL25-AM25 -> 0
A26: 178 | B26: 446 | C26: NL | D26: Ulin | E26: 1 | F26: 5.7 | G26: 30 | H26: 34 | I26: 34 | J26: 39 | K26: =+(G26+H26+I26+J26)/4 -> 34.25 | L26: =ROUND(K26,0) -> 34 | M26: =+ROUND((L26*L26*F26*0.7854)/10000,2) -> 0.52 | O26: =ROUND(((N26*N26*(F26-P26)*0.7854)/10000),2) -> 0 | P26: 0.5 | Q26: =+ROUND((L26*L26*P26*0.7854)/10000,2) -> 0.05 | R26: =+M26-O26-Q26 -> 0.47 | T26: =IF(L26<40,"30 - 39 Cm",IF(L26<50,"40 - 49 Cm",IF(L26<60,"50 - 59 Cm",IF(L26<70,"60 - 69 Cm",IF(L26<80,"70 - 79 Cm",IF(L26<90,"80 - 89 Cm",IF(L26<100,"90 - 99 Cm",IF(L26>99,"100 Cm Up")))))))) -> 30 - 39 Cm | U26: 45968 | V26: =VLOOKUP(A26,'Supply Log'!$E$6:$V$1999,18,FALSE) -> 45971 | W26: A01- | X26: NL | Y26: U01- | AA26: /25- | AB26: =W26&C26&B26&AA26&Y26&A26 -> A01-NL446/25-U01-178 | AC26: 178 | AD26: 21 | AE26: =IF(COUNTIF($B$2:$B$46837,B26)>1,"DOUBLE","") | AF26: 2.95 | AG26: 2.75 | AN26: =F26-AF26-AG26-AH26-AI26-AJ26-AK26-AL26-AM26 -> 0
A27: 179 | B27: 462 | C27: NL | D27: Ulin | E27: 1 | F27: 6 | G27: 27 | H27: 34 | I27: 33 | J27: 40 | K27: =+(G27+H27+I27+J27)/4 -> 33.5 | L27: =ROUND(K27,0) -> 34 | M27: =+ROUND((L27*L27*F27*0.7854)/10000,2) -> 0.54 | O27: =ROUND(((N27*N27*(F27-P27)*0.7854)/10000),2) -> 0 | P27: 0.5 | Q27: =+ROUND((L27*L27*P27*0.7854)/10000,2) -> 0.05 | R27: =+M27-O27-Q27 -> 0.49 | T27: =IF(L27<40,"30 - 39 Cm",IF(L27<50,"40 - 49 Cm",IF(L27<60,"50 - 59 Cm",IF(L27<70,"60 - 69 Cm",IF(L27<80,"70 - 79 Cm",IF(L27<90,"80 - 89 Cm",IF(L27<100,"90 - 99 Cm",IF(L27>99,"100 Cm Up")))))))) -> 30 - 39 Cm | U27: 45968 | V27: =VLOOKUP(A27,'Supply Log'!$E$6:$V$1999,18,FALSE) -> 45971 | W27: A01- | X27: NL | Y27: U01- | AA27: /25- | AB27: =W27&C27&B27&AA27&Y27&A27 -> A01-NL462/25-U01-179 | AC27: 179 | AD27: 22 | AE27: =IF(COUNTIF($B$2:$B$46837,B27)>1,"DOUBLE","") | AF27: 3 | AG27: 3 | AN27: =F27-AF27-AG27-AH27-AI27-AJ27-AK27-AL27-AM27 -> 0
A28: 175 | B28: 435 | C28: NL | D28: Ulin | E28: 1 | F28: 9.9 | G28: 26 | H28: 26 | I28: 36 | J28: 38 | K28: =+(G28+H28+I28+J28)/4 -> 31.5 | L28: =ROUND(K28,0) -> 32 | M28: =+ROUND((L28*L28*F28*0.7854)/10000,2) -> 0.8 | O28: =ROUND(((N28*N28*(F28-P28)*0.7854)/10000),2) -> 0 | P28: 1 | Q28: =+ROUND((L28*L28*P28*0.7854)/10000,2) -> 0.08 | R28: =+M28-O28-Q28 -> 0.72 | T28: =IF(L28<40,"30 - 39 Cm",IF(L28<50,"40 - 49 Cm",IF(L28<60,"50 - 59 Cm",IF(L28<70,"60 - 69 Cm",IF(L28<80,"70 - 79 Cm",IF(L28<90,"80 - 89 Cm",IF(L28<100,"90 - 99 Cm",IF(L28>99,"100 Cm Up")))))))) -> 30 - 39 Cm | U28: 45968 | V28: =VLOOKUP(A28,'Supply Log'!$E$6:$V$1999,18,FALSE) -> 45971 | W28: A01- | X28: NL | Y28: U01- | AA28: /25- | AB28: =W28&C28&B28&AA28&Y28&A28 -> A01-NL435/25-U01-175 | AC28: 175 | AD28: 23 | AE28: =IF(COUNTIF($B$2:$B$46837,B28)>1,"DOUBLE","") | AF28: 3.1 | AG28: 3.7 | AH28: 3.1 | AN28: =F28-AF28-AG28-AH28-AI28-AJ28-AK28-AL28-AM28 -> 4.4408921e-16
A29: 176 | B29: 436 | C29: NL | D29: Ulin | E29: 1 | F29: 9 | G29: 25 | H29: 26 | I29: 29 | J29: 35 | K29: =+(G29+H29+I29+J29)/4 -> 28.75 | L29: =ROUND(K29,0) -> 29 | M29: =+ROUND((L29*L29*F29*0.7854)/10000,2) -> 0.59 | O29: =ROUND(((N29*N29*(F29-P29)*0.7854)/10000),2) -> 0 | Q29: =+ROUND((L29*L29*P29*0.7854)/10000,2) -> 0 | R29: =+M29-O29-Q29 -> 0.59 | T29: =IF(L29<40,"30 - 39 Cm",IF(L29<50,"40 - 49 Cm",IF(L29<60,"50 - 59 Cm",IF(L29<70,"60 - 69 Cm",IF(L29<80,"70 - 79 Cm",IF(L29<90,"80 - 89 Cm",IF(L29<100,"90 - 99 Cm",IF(L29>99,"100 Cm Up")))))))) -> 30 - 39 Cm | U29: 45968 | V29: =VLOOKUP(A29,'Supply Log'!$E$6:$V$1999,18,FALSE) -> 45971 | W29: A01- | X29: NL | Y29: U01- | AA29: /25- | AB29: =W29&C29&B29&AA29&Y29&A29 -> A01-NL436/25-U01-176 | AC29: 176 | AD29: 24 | AE29: =IF(COUNTIF($B$2:$B$46837,B29)>1,"DOUBLE","") | AF29: 2.95 | AG29: 2.95 | AH29: 3.1 | AN29: =F29-AF29-AG29-AH29-AI29-AJ29-AK29-AL29-AM29 -> -4.4408921e-16
A30: 177 | B30: 438 | C30: NL | D30: Ulin | E30: 1 | F30: 11.2 | G30: 41 | H30: 40 | I30: 21 | J30: 29 | K30: =+(G30+H30+I30+J30)/4 -> 32.75 | L30: =ROUND(K30,0) -> 33 | M30: =+ROUND((L30*L30*F30*0.7854)/10000,2) -> 0.96 | O30: =ROUND(((N30*N30*(F30-P30)*0.7854)/10000),2) -> 0 | P30: 1.5 | Q30: =+ROUND((L30*L30*P30*0.7854)/10000,2) -> 0.13 | R30: =+M30-O30-Q30 -> 0.83 | T30: =IF(L30<40,"30 - 39 Cm",IF(L30<50,"40 - 49 Cm",IF(L30<60,"50 - 59 Cm",IF(L30<70,"60 - 69 Cm",IF(L30<80,"70 - 79 Cm",IF(L30<90,"80 - 89 Cm",IF(L30<100,"90 - 99 Cm",IF(L30>99,"100 Cm Up")))))))) -> 30 - 39 Cm | U30: 45968 | V30: =VLOOKUP(A30,'Supply Log'!$E$6:$V$1999,18,FALSE) -> 45971 | W30: A01- | X30: NL | Y30: U01- | AA30: /25- | AB30: =W30&C30&B30&AA30&Y30&A30 -> A01-NL438/25-U01-177 | AC30: 177 | AD30: 25 | AE30: =IF(COUNTIF($B$2:$B$46837,B30)>1,"DOUBLE","") | AF30: 3.2 | AG30: 4.1 | AH30: 3.9 | AN30: =F30-AF30-AG30-AH30-AI30-AJ30-AK30-AL30-AM30 -> -4.4408921e-16
A31: 172 | B31: 449 | C31: NL | D31: Ulin | E31: 1 | F31: 14.3 | G31: 45 | H31: 43 | I31: 26 | J31: 26 | K31: =+(G31+H31+I31+J31)/4 -> 35 | L31: =ROUND(K31,0) -> 35 | M31: =+ROUND((L31*L31*F31*0.7854)/10000,2) -> 1.38 | O31: =ROUND(((N31*N31*(F31-P31)*0.7854)/10000),2) -> 0 | P31: 0.3 | Q31: =+ROUND((L31*L31*P31*0.7854)/10000,2) -> 0.03 | R31: =+M31-O31-Q31 -> 1.35 | T31: =IF(L31<40,"30 - 39 Cm",IF(L31<50,"40 - 49 Cm",IF(L31<60,"50 - 59 Cm",IF(L31<70,"60 - 69 Cm",IF(L31<80,"70 - 79 Cm",IF(L31<90,"80 - 89 Cm",IF(L31<100,"90 - 99 Cm",IF(L31>99,"100 Cm Up")))))))) -> 30 - 39 Cm | U31: 45968 | V31: =VLOOKUP(A31,'Supply Log'!$E$6:$V$1999,18,FALSE) -> 45971 | W31: A01- | X31: NL | Y31: U01- | AA31: /25- | AB31: =W31&C31&B31&AA31&Y31&A31 -> A01-NL449/25-U01-172 | AC31: 172 | AD31: 26 | AE31: =IF(COUNTIF($B$2:$B$46837,B31)>1,"DOUBLE","") | AF31: 4.3 | AG31: 3.3 | AH31: 3.3 | AI31: 3.4 | AN31: =F31-AF31-AG31-AH31-AI31-AJ31-AK31-AL31-AM31 -> 4.4408921e-16
A32: 173 | B32: 465 | C32: NL | D32: Ulin | E32: 1 | F32: 9.4 | G32: 34 | H32: 31 | I32: 36 | J32: 39 | K32: =+(G32+H32+I32+J32)/4 -> 35 | L32: =ROUND(K32,0) -> 35 | M32: =+ROUND((L32*L32*F32*0.7854)/10000,2) -> 0.9 | O32: =ROUND(((N32*N32*(F32-P32)*0.7854)/10000),2) -> 0 | P32: 1.5 | Q32: =+ROUND((L32*L32*P32*0.7854)/10000,2) -> 0.14 | R32: =+M32-O32-Q32 -> 0.76 | T32: =IF(L32<40,"30 - 39 Cm",IF(L32<50,"40 - 49 Cm",IF(L32<60,"50 - 59 Cm",IF(L32<70,"60 - 69 Cm",IF(L32<80,"70 - 79 Cm",IF(L32<90,"80 - 89 Cm",IF(L32<100,"90 - 99 Cm",IF(L32>99,"100 Cm Up")))))))) -> 30 - 39 Cm | U32: 45968 | V32: =VLOOKUP(A32,'Supply Log'!$E$6:$V$1999,18,FALSE) -> 45971 | W32: A01- | X32: NL | Y32: U01- | AA32: /25- | AB32: =W32&C32&B32&AA32&Y32&A32 -> A01-NL465/25-U01-173 | AC32: 173 | AD32: 27 | AE32: =IF(COUNTIF($B$2:$B$46837,B32)>1,"DOUBLE","") | AF32: 2.9 | AG32: 4.3 | AH32: 2.2 | AN32: =F32-AF32-AG32-AH32-AI32-AJ32-AK32-AL32-AM32 -> 0
A33: 174 | B33: 426 | C33: NL | D33: Ulin | E33: 1 | F33: 9.5 | G33: 31 | H33: 31 | I33: 40 | J33: 43 | K33: =+(G33+H33+I33+J33)/4 -> 36.25 | L33: =ROUND(K33,0) -> 36 | M33: =+ROUND((L33*L33*F33*0.7854)/10000,2) -> 0.97 | O33: =ROUND(((N33*N33*(F33-P33)*0.7854)/10000),2) -> 0 | P33: 1 | Q33: =+ROUND((L33*L33*P33*0.7854)/10000,2) -> 0.1 | R33: =+M33-O33-Q33 -> 0.87 | T33: =IF(L33<40,"30 - 39 Cm",IF(L33<50,"40 - 49 Cm",IF(L33<60,"50 - 59 Cm",IF(L33<70,"60 - 69 Cm",IF(L33<80,"70 - 79 Cm",IF(L33<90,"80 - 89 Cm",IF(L33<100,"90 - 99 Cm",IF(L33>99,"100 Cm Up")))))))) -> 30 - 39 Cm | U33: 45968 | V33: =VLOOKUP(A33,'Supply Log'!$E$6:$V$1999,18,FALSE) -> 45971 | W33: A01- | X33: NL | Y33: U01- | AA33: /25- | AB33: =W33&C33&B33&AA33&Y33&A33 -> A01-NL426/25-U01-174 | AC33: 174 | AD33: 28 | AE33: =IF(COUNTIF($B$2:$B$46837,B33)>1,"DOUBLE","") | AF33: 4.75 | AG33: 4.75 | AN33: =F33-AF33-AG33-AH33-AI33-AJ33-AK33-AL33-AM33 -> 0
A34: 170 | B34: 464 | C34: NL | D34: Ulin | E34: 1 | F34: 8.1 | G34: 43 | H34: 43 | I34: 33 | J34: 38 | K34: =+(G34+H34+I34+J34)/4 -> 39.25 | L34: =ROUND(K34,0) -> 39 | M34: =+ROUND((L34*L34*F34*0.7854)/10000,2) -> 0.97 | O34: =ROUND(((N34*N34*(F34-P34)*0.7854)/10000),2) -> 0 | P34: 1 | Q34: =+ROUND((L34*L34*P34*0.7854)/10000,2) -> 0.12 | R34: =+M34-O34-Q34 -> 0.85 | T34: =IF(L34<40,"30 - 39 Cm",IF(L34<50,"40 - 49 Cm",IF(L34<60,"50 - 59 Cm",IF(L34<70,"60 - 69 Cm",IF(L34<80,"70 - 79 Cm",IF(L34<90,"80 - 89 Cm",IF(L34<100,"90 - 99 Cm",IF(L34>99,"100 Cm Up")))))))) -> 30 - 39 Cm | U34: 45968 | V34: =VLOOKUP(A34,'Supply Log'!$E$6:$V$1999,18,FALSE) -> 45971 | W34: A01- | X34: NL | Y34: U01- | AA34: /25- | AB34: =W34&C34&B34&AA34&Y34&A34 -> A01-NL464/25-U01-170 | AC34: 170 | AD34: 29 | AE34: =IF(COUNTIF($B$2:$B$46837,B34)>1,"DOUBLE","") | AF34: 4.05 | AG34: 4.05 | AN34: =F34-AF34-AG34-AH34-AI34-AJ34-AK34-AL34-AM34 -> 0
A35: 171 | B35: 447 | C35: NL | D35: Ulin | E35: 1 | F35: 8.9 | G35: 36 | H35: 45 | I35: 36 | J35: 39 | K35: =+(G35+H35+I35+J35)/4 -> 39 | L35: =ROUND(K35,0) -> 39 | M35: =+ROUND((L35*L35*F35*0.7854)/10000,2) -> 1.06 | O35: =ROUND(((N35*N35*(F35-P35)*0.7854)/10000),2) -> 0 | P35: 0.5 | Q35: =+ROUND((L35*L35*P35*0.7854)/10000,2) -> 0.06 | R35: =+M35-O35-Q35 -> 1 | T35: =IF(L35<40,"30 - 39 Cm",IF(L35<50,"40 - 49 Cm",IF(L35<60,"50 - 59 Cm",IF(L35<70,"60 - 69 Cm",IF(L35<80,"70 - 79 Cm",IF(L35<90,"80 - 89 Cm",IF(L35<100,"90 - 99 Cm",IF(L35>99,"100 Cm Up")))))))) -> 30 - 39 Cm | U35: 45968 | V35: =VLOOKUP(A35,'Supply Log'!$E$6:$V$1999,18,FALSE) -> 45971 | W35: A01- | X35: NL | Y35: U01- | AA35: /25- | AB35: =W35&C35&B35&AA35&Y35&A35 -> A01-NL447/25-U01-171 | AC35: 171 | AD35: 30 | AE35: =IF(COUNTIF($B$2:$B$46837,B35)>1,"DOUBLE","") | AF35: 3.05 | AG35: 2.95 | AH35: 2.9 | AN35: =F35-AF35-AG35-AH35-AI35-AJ35-AK35-AL35-AM35 -> 4.4408921e-16
A36: 1 | B36: 564 | C36: NL | D36: Ulin | E36: 1 | F36: 17.8 | G36: 60 | H36: 67 | I36: 44 | J36: 50 | K36: =+(G36+H36+I36+J36)/4 -> 55.25 | L36: =ROUND(K36,0) -> 55 | M36: =+ROUND((L36*L36*F36*0.7854)/10000,2) -> 4.23 | O36: =ROUND(((N36*N36*(F36-P36)*0.7854)/10000),2) -> 0 | P36: 1 | Q36: =+ROUND((L36*L36*P36*0.7854)/10000,2) -> 0.24 | R36: =+M36-O36-Q36 -> 3.99 | T36: =IF(L36<40,"30 - 39 Cm",IF(L36<50,"40 - 49 Cm",IF(L36<60,"50 - 59 Cm",IF(L36<70,"60 - 69 Cm",IF(L36<80,"70 - 79 Cm",IF(L36<90,"80 - 89 Cm",IF(L36<100,"90 - 99 Cm",IF(L36>99,"100 Cm Up")))))))) -> 50 - 59 Cm | U36: 45967 | V36: =VLOOKUP(A36,'Supply Log'!$E$6:$V$1999,18,FALSE) -> #N/A | W36: A01- | X36: NL | Y36: U01- | Z36: 00 | AA36: /25- | AB36: =W36&C36&B36&AA36&Y36&A36 -> A01-NL564/25-U01-1 | AE36: =IF(COUNTIF($B$2:$B$46837,B36)>1,"DOUBLE","") | AN36: =F36-AF36-AG36-AH36-AI36-AJ36-AK36-AL36-AM36 -> 17.8
A37: 2 | B37: 696 | C37: NL | D37: Ulin | E37: 1 | F37: 9.1 | G37: 64 | H37: 67 | I37: 57 | J37: 63 | K37: =+(G37+H37+I37+J37)/4 -> 62.75 | L37: =ROUND(K37,0) -> 63 | M37: =+ROUND((L37*L37*F37*0.7854)/10000,2) -> 2.84 | O37: =ROUND(((N37*N37*(F37-P37)*0.7854)/10000),2) -> 0 | P37: 1 | Q37: =+ROUND((L37*L37*P37*0.7854)/10000,2) -> 0.31 | R37: =+M37-O37-Q37 -> 2.53 | T37: =IF(L37<40,"30 - 39 Cm",IF(L37<50,"40 - 49 Cm",IF(L37<60,"50 - 59 Cm",IF(L37<70,"60 - 69 Cm",IF(L37<80,"70 - 79 Cm",IF(L37<90,"80 - 89 Cm",IF(L37<100,"90 - 99 Cm",IF(L37>99,"100 Cm Up")))))))) -> 60 - 69 Cm | U37: 45967 | V37: =VLOOKUP(A37,'Supply Log'!$E$6:$V$1999,18,FALSE) -> #N/A | W37: A01- | X37: NL | Y37: U01- | Z37: 00 | AA37: /25- | AB37: =W37&C37&B37&AA37&Y37&A37 -> A01-NL696/25-U01-2 | AE37: =IF(COUNTIF($B$2:$B$46837,B37)>1,"DOUBLE","") | AN37: =F37-AF37-AG37-AH37-AI37-AJ37-AK37-AL37-AM37 -> 9.1
A38: 3 | B38: 554 | C38: NL | D38: Ulin | E38: 1 | F38: 7.9 | G38: 60 | H38: 64 | I38: 63 | J38: 68 | K38: =+(G38+H38+I38+J38)/4 -> 63.75 | L38: =ROUND(K38,0) -> 64 | M38: =+ROUND((L38*L38*F38*0.7854)/10000,2) -> 2.54 | O38: =ROUND(((N38*N38*(F38-P38)*0.7854)/10000),2) -> 0 | P38: 0.5 | Q38: =+ROUND((L38*L38*P38*0.7854)/10000,2) -> 0.16 | R38: =+M38-O38-Q38 -> 2.38 | T38: =IF(L38<40,"30 - 39 Cm",IF(L38<50,"40 - 49 Cm",IF(L38<60,"50 - 59 Cm",IF(L38<70,"60 - 69 Cm",IF(L38<80,"70 - 79 Cm",IF(L38<90,"80 - 89 Cm",IF(L38<100,"90 - 99 Cm",IF(L38>99,"100 Cm Up")))))))) -> 60 - 69 Cm | U38: 45967 | V38: =VLOOKUP(A38,'Supply Log'!$E$6:$V$1999,18,FALSE) -> #N/A | W38: A01- | X38: NL | Y38: U01- | Z38: 00 | AA38: /25- | AB38: =W38&C38&B38&AA38&Y38&A38 -> A01-NL554/25-U01-3 | AE38: =IF(COUNTIF($B$2:$B$46837,B38)>1,"DOUBLE","") | AN38: =F38-AF38-AG38-AH38-AI38-AJ38-AK38-AL38-AM38 -> 7.9
A39: 4 | B39: 558 | C39: NL | D39: Ulin | E39: 1 | F39: 11.4 | G39: 51 | H39: 52 | I39: 45 | J39: 50 | K39: =+(G39+H39+I39+J39)/4 -> 49.5 | L39: =ROUND(K39,0) -> 50 | M39: =+ROUND((L39*L39*F39*0.7854)/10000,2) -> 2.24 | O39: =ROUND(((N39*N39*(F39-P39)*0.7854)/10000),2) -> 0 | P39: 0.5 | Q39: =+ROUND((L39*L39*P39*0.7854)/10000,2) -> 0.1 | R39: =+M39-O39-Q39 -> 2.14 | T39: =IF(L39<40,"30 - 39 Cm",IF(L39<50,"40 - 49 Cm",IF(L39<60,"50 - 59 Cm",IF(L39<70,"60 - 69 Cm",IF(L39<80,"70 - 79 Cm",IF(L39<90,"80 - 89 Cm",IF(L39<100,"90 - 99 Cm",IF(L39>99,"100 Cm Up")))))))) -> 50 - 59 Cm | U39: 45967 | V39: =VLOOKUP(A39,'Supply Log'!$E$6:$V$1999,18,FALSE) -> #N/A | W39: A01- | X39: NL | Y39: U01- | Z39: 00 | AA39: /25- | AB39: =W39&C39&B39&AA39&Y39&A39 -> A01-NL558/25-U01-4 | AE39: =IF(COUNTIF($B$2:$B$46837,B39)>1,"DOUBLE","") | AN39: =F39-AF39-AG39-AH39-AI39-AJ39-AK39-AL39-AM39 -> 11.4
A40: 5 | B40: 603 | C40: NL | D40: Ulin | E40: 1 | F40: 8.2 | G40: 47 | H40: 50 | I40: 48 | J40: 59 | K40: =+(G40+H40+I40+J40)/4 -> 51 | L40: =ROUND(K40,0) -> 51 | M40: =+ROUND((L40*L40*F40*0.7854)/10000,2) -> 1.68 | O40: =ROUND(((N40*N40*(F40-P40)*0.7854)/10000),2) -> 0 | P40: 1 | Q40: =+ROUND((L40*L40*P40*0.7854)/10000,2) -> 0.2 | R40: =+M40-O40-Q40 -> 1.48 | T40: =IF(L40<40,"30 - 39 Cm",IF(L40<50,"40 - 49 Cm",IF(L40<60,"50 - 59 Cm",IF(L40<70,"60 - 69 Cm",IF(L40<80,"70 - 79 Cm",IF(L40<90,"80 - 89 Cm",IF(L40<100,"90 - 99 Cm",IF(L40>99,"100 Cm Up")))))))) -> 50 - 59 Cm | U40: 45967 | V40: =VLOOKUP(A40,'Supply Log'!$E$6:$V$1999,18,FALSE) -> #N/A | W40: A01- | X40: NL | Y40: U01- | Z40: 00 | AA40: /25- | AB40: =W40&C40&B40&AA40&Y40&A40 -> A01-NL603/25-U01-5 | AE40: =IF(COUNTIF($B$2:$B$46837,B40)>1,"DOUBLE","") | AN40: =F40-AF40-AG40-AH40-AI40-AJ40-AK40-AL40-AM40 -> 8.2
...

Sheet Supply Log
P1: Tidak di potong chainsaw ( langsung masuk ke log yard )
O3: Pake Vol ini | T3: U/Opr ch
E4: ISI MANUAL | M4: Ø | N4: Ø2
A5: CEK | B5: NO | C5: S | D5: TANGGAL | E5: NO LOG | F5: KODE | G5: JENIS | H5: PJG LOG | I5: D1 | J5: D2 | K5: D3 | L5: D4 | O5: Brutto | P5: GR | Q5: M3 | R5: Trimming | S5: Vol Tr | T5: Netto | U5: SUM | V5: TGL2 | W5: No Log Asal
A6: =IF(COUNTIF($E$2:$E$47178,E6)>1,"DOUBLE","") | B6: 1 | C6: =IF(D6="","",(IF(D7=D6,"",1))) | D6: 45971 | E6: 199 | F6: =VLOOKUP(E6,DUKB!$A$6:$R$658,3,FALSE) -> NL | G6: =VLOOKUP(E6,DUKB!$A$6:$R$658,4,FALSE) -> Ulin | H6: =VLOOKUP(E6,DUKB!$A$6:$R$658,6,FALSE) -> 11 | I6: =VLOOKUP(E6,DUKB!$A$6:$R$658,7,FALSE) -> 39 | J6: =VLOOKUP(E6,DUKB!$A$6:$R$658,8,FALSE) -> 43 | K6: =VLOOKUP(E6,DUKB!$A$6:$R$658,9,FALSE) -> 25 | L6: =VLOOKUP(E6,DUKB!$A$6:$R$658,10,FALSE) -> 32 | M6: =VLOOKUP(E6,DUKB!$A$6:$R$658,11,FALSE) -> 34.75 | N6: =VLOOKUP(E6,DUKB!$A$6:$R$658,12,FALSE) -> 35 | O6: =VLOOKUP(E6,DUKB!$A$6:$R$658,13,FALSE) -> 1.06 | P6: =VLOOKUP(E6,DUKB!$A$6:$R$658,14,FALSE) -> 0 | Q6: =VLOOKUP(E6,DUKB!$A$6:$R$658,15,FALSE) -> 0 | R6: =VLOOKUP(E6,DUKB!$A$6:$R$658,16,FALSE) -> 1.5 | S6: =VLOOKUP(E6,DUKB!$A$6:$R$658,17,FALSE) -> 0.14 | T6: =VLOOKUP(E6,DUKB!$A$6:$R$658,18,FALSE) -> 0.92 | U6: =IF(C6="","",(SUMIF($D$2:$D$25115,D6,$O$2:$O$25115))) | V6: =D6 -> 45971 | W6: =VLOOKUP(E6,DUKB!$A$6:$B$565,2,FALSE) -> 419 | X6: =VLOOKUP(E6,DUKB!$A$6:$T$560,19,FALSE) -> 0 | Z6: =E6 -> 199 | AA6: =W6 -> 419 | AB6: =X6 -> 0 | AC6: =G6 -> Ulin | AD6: =H6 -> 11 | AE6: =N6 -> 35 | AF6: =O6 -> 1.06 | AH6: =E6 -> 199 | AI6: =B6 -> 1
A7: =IF(COUNTIF($E$2:$E$47178,E7)>1,"DOUBLE","") | B7: =B6+1 -> 2 | C7: =IF(D7="","",(IF(D8=D7,"",1))) | D7: 45971 | E7: 200 | F7: =VLOOKUP(E7,DUKB!$A$6:$R$658,3,FALSE) -> NL | G7: =VLOOKUP(E7,DUKB!$A$6:$R$658,4,FALSE) -> Ulin | H7: =VLOOKUP(E7,DUKB!$A$6:$R$658,6,FALSE) -> 14.2 | I7: =VLOOKUP(E7,DUKB!$A$6:$R$658,7,FALSE) -> 38 | J7: =VLOOKUP(E7,DUKB!$A$6:$R$658,8,FALSE) -> 44 | K7: =VLOOKUP(E7,DUKB!$A$6:$R$658,9,FALSE) -> 30 | L7: =VLOOKUP(E7,DUKB!$A$6:$R$658,10,FALSE) -> 34 | M7: =VLOOKUP(E7,DUKB!$A$6:$R$658,11,FALSE) -> 36.5 | N7: =VLOOKUP(E7,DUKB!$A$6:$R$658,12,FALSE) -> 37 | O7: =VLOOKUP(E7,DUKB!$A$6:$R$658,13,FALSE) -> 1.53 | P7: =VLOOKUP(E7,DUKB!$A$6:$R$658,14,FALSE) -> 0 | Q7: =VLOOKUP(E7,DUKB!$A$6:$R$658,15,FALSE) -> 0 | R7: =VLOOKUP(E7,DUKB!$A$6:$R$658,16,FALSE) -> 0.5 | S7: =VLOOKUP(E7,DUKB!$A$6:$R$658,17,FALSE) -> 0.05 | T7: =VLOOKUP(E7,DUKB!$A$6:$R$658,18,FALSE) -> 1.48 | U7: =IF(C7="","",(SUMIF($D$2:$D$25115,D7,$O$2:$O$25115))) | V7: =D7 -> 45971 | W7: =VLOOKUP(E7,DUKB!$A$6:$B$565,2,FALSE) -> 411 | X7: =VLOOKUP(E7,DUKB!$A$6:$T$560,19,FALSE) -> 0 | Z7: =E7 -> 200 | AA7: =W7 -> 411 | AB7: =X7 -> 0 | AC7: =G7 -> Ulin | AD7: =H7 -> 14.2 | AE7: =N7 -> 37 | AF7: =O7 -> 1.53 | AH7: =E7 -> 200 | AI7: =B7 -> 2
A8: =IF(COUNTIF($E$2:$E$47178,E8)>1,"DOUBLE","") | B8: =B7+1 -> 3 | C8: =IF(D8="","",(IF(D9=D8,"",1))) | D8: 45971 | E8: 196 | F8: =VLOOKUP(E8,DUKB!$A$6:$R$658,3,FALSE) -> NL | G8: =VLOOKUP(E8,DUKB!$A$6:$R$658,4,FALSE) -> Ulin | H8: =VLOOKUP(E8,DUKB!$A$6:$R$658,6,FALSE) -> 6.6 | I8: =VLOOKUP(E8,DUKB!$A$6:$R$658,7,FALSE) -> 36 | J8: =VLOOKUP(E8,DUKB!$A$6:$R$658,8,FALSE) -> 40 | K8: =VLOOKUP(E8,DUKB!$A$6:$R$658,9,FALSE) -> 31 | L8: =VLOOKUP(E8,DUKB!$A$6:$R$658,10,FALSE) -> 35 | M8: =VLOOKUP(E8,DUKB!$A$6:$R$658,11,FALSE) -> 35.5 | N8: =VLOOKUP(E8,DUKB!$A$6:$R$658,12,FALSE) -> 36 | O8: =VLOOKUP(E8,DUKB!$A$6:$R$658,13,FALSE) -> 0.67 | P8: =VLOOKUP(E8,DUKB!$A$6:$R$658,14,FALSE) -> 0 | Q8: =VLOOKUP(E8,DUKB!$A$6:$R$658,15,FALSE) -> 0 | R8: =VLOOKUP(E8,DUKB!$A$6:$R$658,16,FALSE) -> 0 | S8: =VLOOKUP(E8,DUKB!$A$6:$R$658,17,FALSE) -> 0 | T8: =VLOOKUP(E8,DUKB!$A$6:$R$658,18,FALSE) -> 0.67 | U8: =IF(C8="","",(SUMIF($D$2:$D$25115,D8,$O$2:$O$25115))) | V8: =D8 -> 45971 | W8: =VLOOKUP(E8,DUKB!$A$6:$B$565,2,FALSE) -> 425 | X8: =VLOOKUP(E8,DUKB!$A$6:$T$560,19,FALSE) -> 0 | Z8: =E8 -> 196 | AA8: =W8 -> 425 | AB8: =X8 -> 0 | AC8: =G8 -> Ulin | AD8: =H8 -> 6.6 | AE8: =N8 -> 36 | AF8: =O8 -> 0.67 | AH8: =E8 -> 196 | AI8: =B8 -> 3
A9: =IF(COUNTIF($E$2:$E$47178,E9)>1,"DOUBLE","") | B9: =B8+1 -> 4 | C9: =IF(D9="","",(IF(D10=D9,"",1))) | D9: 45971 | E9: 197 | F9: =VLOOKUP(E9,DUKB!$A$6:$R$658,3,FALSE) -> NL | G9: =VLOOKUP(E9,DUKB!$A$6:$R$658,4,FALSE) -> Ulin | H9: =VLOOKUP(E9,DUKB!$A$6:$R$658,6,FALSE) -> 11.5 | I9: =VLOOKUP(E9,DUKB!$A$6:$R$658,7,FALSE) -> 34 | J9: =VLOOKUP(E9,DUKB!$A$6:$R$658,8,FALSE) -> 38 | K9: =VLOOKUP(E9,DUKB!$A$6:$R$658,9,FALSE) -> 26 | L9: =VLOOKUP(E9,DUKB!$A$6:$R$658,10,FALSE) -> 31 | M9: =VLOOKUP(E9,DUKB!$A$6:$R$658,11,FALSE) -> 32.25 | N9: =VLOOKUP(E9,DUKB!$A$6:$R$658,12,FALSE) -> 32 | O9: =VLOOKUP(E9,DUKB!$A$6:$R$658,13,FALSE) -> 0.92 | P9: =VLOOKUP(E9,DUKB!$A$6:$R$658,14,FALSE) -> 0 | Q9: =VLOOKUP(E9,DUKB!$A$6:$R$658,15,FALSE) -> 0 | R9: =VLOOKUP(E9,DUKB!$A$6:$R$658,16,FALSE) -> 0.5 | S9: =VLOOKUP(E9,DUKB!$A$6:$R$658,17,FALSE) -> 0.04 | T9: =VLOOKUP(E9,DUKB!$A$6:$R$658,18,FALSE) -> 0.88 | U9: =IF(C9="","",(SUMIF($D$2:$D$25115,D9,$O$2:$O$25115))) | V9: =D9 -> 45971 | W9: =VLOOKUP(E9,DUKB!$A$6:$B$565,2,FALSE) -> 404 | X9: =VLOOKUP(E9,DUKB!$A$6:$T$560,19,FALSE) -> 0 | Z9: =E9 -> 197 | AA9: =W9 -> 404 | AB9: =X9 -> 0 | AC9: =G9 -> Ulin | AD9: =H9 -> 11.5 | AE9: =N9 -> 32 | AF9: =O9 -> 0.92 | AH9: =E9 -> 197 | AI9: =B9 -> 4
A10: =IF(COUNTIF($E$2:$E$47178,E10)>1,"DOUBLE","") | B10: =B9+1 -> 5 | C10: =IF(D10="","",(IF(D11=D10,"",1))) | D10: 45971 | E10: 198 | F10: =VLOOKUP(E10,DUKB!$A$6:$R$658,3,FALSE) -> NL | G10: =VLOOKUP(E10,DUKB!$A$6:$R$658,4,FALSE) -> Ulin | H10: =VLOOKUP(E10,DUKB!$A$6:$R$658,6,FALSE) -> 9.1 | I10: =VLOOKUP(E10,DUKB!$A$6:$R$658,7,FALSE) -> 30 | J10: =VLOOKUP(E10,DUKB!$A$6:$R$658,8,FALSE) -> 32 | K10: =VLOOKUP(E10,DUKB!$A$6:$R$658,9,FALSE) -> 41 | L10: =VLOOKUP(E10,DUKB!$A$6:$R$658,10,FALSE) -> 47 | M10: =VLOOKUP(E10,DUKB!$A$6:$R$658,11,FALSE) -> 37.5 | N10: =VLOOKUP(E10,DUKB!$A$6:$R$658,12,FALSE) -> 38 | O10: =VLOOKUP(E10,DUKB!$A$6:$R$658,13,FALSE) -> 1.03 | P10: =VLOOKUP(E10,DUKB!$A$6:$R$658,14,FALSE) -> 0 | Q10: =VLOOKUP(E10,DUKB!$A$6:$R$658,15,FALSE) -> 0 | R10: =VLOOKUP(E10,DUKB!$A$6:$R$658,16,FALSE) -> 0.5 | S10: =VLOOKUP(E10,DUKB!$A$6:$R$658,17,FALSE) -> 0.06 | T10: =VLOOKUP(E10,DUKB!$A$6:$R$658,18,FALSE) -> 0.97 | U10: =IF(C10="","",(SUMIF($D$2:$D$25115,D10,$O$2:$O$25115))) | V10: =D10 -> 45971 | W10: =VLOOKUP(E10,DUKB!$A$6:$B$565,2,FALSE) -> 921 | X10: =VLOOKUP(E10,DUKB!$A$6:$T$560,19,FALSE) -> 0 | Z10: =E10 -> 198 | AA10: =W10 -> 921 | AB10: =X10 -> 0 | AC10: =G10 -> Ulin | AD10: =H10 -> 9.1 | AE10: =N10 -> 38 | AF10: =O10 -> 1.03 | AH10: =E10 -> 198 | AI10: =B10 -> 5
A11: =IF(COUNTIF($E$2:$E$47178,E11)>1,"DOUBLE","") | B11: =B10+1 -> 6 | C11: =IF(D11="","",(IF(D12=D11,"",1))) | D11: 45971 | E11: 195 | F11: =VLOOKUP(E11,DUKB!$A$6:$R$658,3,FALSE) -> NL | G11: =VLOOKUP(E11,DUKB!$A$6:$R$658,4,FALSE) -> Ulin | H11: =VLOOKUP(E11,DUKB!$A$6:$R$658,6,FALSE) -> 17.9 | I11: =VLOOKUP(E11,DUKB!$A$6:$R$658,7,FALSE) -> 26 | J11: =VLOOKUP(E11,DUKB!$A$6:$R$658,8,FALSE) -> 30 | K11: =VLOOKUP(E11,DUKB!$A$6:$R$658,9,FALSE) -> 48 | L11: =VLOOKUP(E11,DUKB!$A$6:$R$658,10,FALSE) -> 49 | M11: =VLOOKUP(E11,DUKB!$A$6:$R$658,11,FALSE) -> 38.25 | N11: =VLOOKUP(E11,DUKB!$A$6:$R$658,12,FALSE) -> 38 | O11: =VLOOKUP(E11,DUKB!$A$6:$R$658,13,FALSE) -> 2.03 | P11: =VLOOKUP(E11,DUKB!$A$6:$R$658,14,FALSE) -> 0 | Q11: =VLOOKUP(E11,DUKB!$A$6:$R$658,15,FALSE) -> 0 | R11: =VLOOKUP(E11,DUKB!$A$6:$R$658,16,FALSE) -> 1 | S11: =VLOOKUP(E11,DUKB!$A$6:$R$658,17,FALSE) -> 0.11 | T11: =VLOOKUP(E11,DUKB!$A$6:$R$658,18,FALSE) -> 1.92 | U11: =IF(C11="","",(SUMIF($D$2:$D$25115,D11,$O$2:$O$25115))) | V11: =D11 -> 45971 | W11: =VLOOKUP(E11,DUKB!$A$6:$B$565,2,FALSE) -> 611 | X11: =VLOOKUP(E11,DUKB!$A$6:$T$560,19,FALSE) -> 0 | Z11: =E11 -> 195 | AA11: =W11 -> 611 | AB11: =X11 -> 0 | AC11: =G11 -> Ulin | AD11: =H11 -> 17.9 | AE11: =N11 -> 38 | AF11: =O11 -> 2.03 | AH11: =E11 -> 195 | AI11: =B11 -> 6
A12: =IF(COUNTIF($E$2:$E$47178,E12)>1,"DOUBLE","") | B12: =B11+1 -> 7 | C12: =IF(D12="","",(IF(D13=D12,"",1))) | D12: 45971 | E12: 192 | F12: =VLOOKUP(E12,DUKB!$A$6:$R$658,3,FALSE) -> NL | G12: =VLOOKUP(E12,DUKB!$A$6:$R$658,4,FALSE) -> Ulin | H12: =VLOOKUP(E12,DUKB!$A$6:$R$658,6,FALSE) -> 11 | I12: =VLOOKUP(E12,DUKB!$A$6:$R$658,7,FALSE) -> 28 | J12: =VLOOKUP(E12,DUKB!$A$6:$R$658,8,FALSE) -> 31 | K12: =VLOOKUP(E12,DUKB!$A$6:$R$658,9,FALSE) -> 35 | L12: =VLOOKUP(E12,DUKB!$A$6:$R$658,10,FALSE) -> 40 | M12: =VLOOKUP(E12,DUKB!$A$6:$R$658,11,FALSE) -> 33.5 | N12: =VLOOKUP(E12,DUKB!$A$6:$R$658,12,FALSE) -> 34 | O12: =VLOOKUP(E12,DUKB!$A$6:$R$658,13,FALSE) -> 1 | P12: =VLOOKUP(E12,DUKB!$A$6:$R$658,14,FALSE) -> 0 | Q12: =VLOOKUP(E12,DUKB!$A$6:$R$658,15,FALSE) -> 0 | R12: =VLOOKUP(E12,DUKB!$A$6:$R$658,16,FALSE) -> 0 | S12: =VLOOKUP(E12,DUKB!$A$6:$R$658,17,FALSE) -> 0 | T12: =VLOOKUP(E12,DUKB!$A$6:$R$658,18,FALSE) -> 1 | U12: =IF(C12="","",(SUMIF($D$2:$D$25115,D12,$O$2:$O$25115))) | V12: =D12 -> 45971 | W12: =VLOOKUP(E12,DUKB!$A$6:$B$565,2,FALSE) -> 430 | X12: =VLOOKUP(E12,DUKB!$A$6:$T$560,19,FALSE) -> 0 | Z12: =E12 -> 192 | AA12: =W12 -> 430 | AB12: =X12 -> 0 | AC12: =G12 -> Ulin | AD12: =H12 -> 11 | AE12: =N12 -> 34 | AF12: =O12 -> 1 | AH12: =E12 -> 192 | AI12: =B12 -> 7
A13: =IF(COUNTIF($E$2:$E$47178,E13)>1,"DOUBLE","") | B13: =B12+1 -> 8 | C13: =IF(D13="","",(IF(D14=D13,"",1))) | D13: 45971 | E13: 193 | F13: =VLOOKUP(E13,DUKB!$A$6:$R$658,3,FALSE) -> NL | G13: =VLOOKUP(E13,DUKB!$A$6:$R$658,4,FALSE) -> Ulin | H13: =VLOOKUP(E13,DUKB!$A$6:$R$658,6,FALSE) -> 5.3 | I13: =VLOOKUP(E13,DUKB!$A$6:$R$658,7,FALSE) -> 35 | J13: =VLOOKUP(E13,DUKB!$A$6:$R$658,8,FALSE) -> 27 | K13: =VLOOKUP(E13,DUKB!$A$6:$R$658,9,FALSE) -> 26 | L13: =VLOOKUP(E13,DUKB!$A$6:$R$658,10,FALSE) -> 31 | M13: =VLOOKUP(E13,DUKB!$A$6:$R$658,11,FALSE) -> 29.75 | N13: =VLOOKUP(E13,DUKB!$A$6:$R$658,12,FALSE) -> 30 | O13: =VLOOKUP(E13,DUKB!$A$6:$R$658,13,FALSE) -> 0.37 | P13: =VLOOKUP(E13,DUKB!$A$6:$R$658,14,FALSE) -> 0 | Q13: =VLOOKUP(E13,DUKB!$A$6:$R$658,15,FALSE) -> 0 | R13: =VLOOKUP(E13,DUKB!$A$6:$R$658,16,FALSE) -> 0.5 | S13: =VLOOKUP(E13,DUKB!$A$6:$R$658,17,FALSE) -> 0.04 | T13: =VLOOKUP(E13,DUKB!$A$6:$R$658,18,FALSE) -> 0.33 | U13: =IF(C13="","",(SUMIF($D$2:$D$25115,D13,$O$2:$O$25115))) | V13: =D13 -> 45971 | W13: =VLOOKUP(E13,DUKB!$A$6:$B$565,2,FALSE) -> 413 | X13: =VLOOKUP(E13,DUKB!$A$6:$T$560,19,FALSE) -> 0 | Z13: =E13 -> 193 | AA13: =W13 -> 413 | AB13: =X13 -> 0 | AC13: =G13 -> Ulin | AD13: =H13 -> 5.3 | AE13: =N13 -> 30 | AF13: =O13 -> 0.37 | AH13: =E13 -> 193 | AI13: =B13 -> 8
A14: =IF(COUNTIF($E$2:$E$47178,E14)>1,"DOUBLE","") | B14: =B13+1 -> 9 | C14: =IF(D14="","",(IF(D15=D14,"",1))) | D14: 45971 | E14: 194 | F14: =VLOOKUP(E14,DUKB!$A$6:$R$658,3,FALSE) -> NL | G14: =VLOOKUP(E14,DUKB!$A$6:$R$658,4,FALSE) -> Ulin | H14: =VLOOKUP(E14,DUKB!$A$6:$R$658,6,FALSE) -> 8.8 | I14: =VLOOKUP(E14,DUKB!$A$6:$R$658,7,FALSE) -> 34 | J14: =VLOOKUP(E14,DUKB!$A$6:$R$658,8,FALSE) -> 31 | K14: =VLOOKUP(E14,DUKB!$A$6:$R$658,9,FALSE) -> 33 | L14: =VLOOKUP(E14,DUKB!$A$6:$R$658,10,FALSE) -> 39 | M14: =VLOOKUP(E14,DUKB!$A$6:$R$658,11,FALSE) -> 34.25 | N14: =VLOOKUP(E14,DUKB!$A$6:$R$658,12,FALSE) -> 34 | O14: =VLOOKUP(E14,DUKB!$A$6:$R$658,13,FALSE) -> 0.8 | P14: =VLOOKUP(E14,DUKB!$A$6:$R$658,14,FALSE) -> 0 | Q14: =VLOOKUP(E14,DUKB!$A$6:$R$658,15,FALSE) -> 0 | R14: =VLOOKUP(E14,DUKB!$A$6:$R$658,16,FALSE) -> 1 | S14: =VLOOKUP(E14,DUKB!$A$6:$R$658,17,FALSE) -> 0.09 | T14: =VLOOKUP(E14,DUKB!$A$6:$R$658,18,FALSE) -> 0.71 | U14: =IF(C14="","",(SUMIF($D$2:$D$25115,D14,$O$2:$O$25115))) | V14: =D14 -> 45971 | W14: =VLOOKUP(E14,DUKB!$A$6:$B$565,2,FALSE) -> 454 | X14: =VLOOKUP(E14,DUKB!$A$6:$T$560,19,FALSE) -> 0 | Z14: =E14 -> 194 | AA14: =W14 -> 454 | AB14: =X14 -> 0 | AC14: =G14 -> Ulin | AD14: =H14 -> 8.8 | AE14: =N14 -> 34 | AF14: =O14 -> 0.8 | AH14: =E14 -> 194 | AI14: =B14 -> 9
A15: =IF(COUNTIF($E$2:$E$47178,E15)>1,"DOUBLE","") | B15: =B14+1 -> 10 | C15: =IF(D15="","",(IF(D16=D15,"",1))) | D15: 45971 | E15: 189 | F15: =VLOOKUP(E15,DUKB!$A$6:$R$658,3,FALSE) -> NL | G15: =VLOOKUP(E15,DUKB!$A$6:$R$658,4,FALSE) -> Ulin | H15: =VLOOKUP(E15,DUKB!$A$6:$R$658,6,FALSE) -> 13.3 | I15: =VLOOKUP(E15,DUKB!$A$6:$R$658,7,FALSE) -> 27 | J15: =VLOOKUP(E15,DUKB!$A$6:$R$658,8,FALSE) -> 32 | K15: =VLOOKUP(E15,DUKB!$A$6:$R$658,9,FALSE) -> 36 | L15: =VLOOKUP(E15,DUKB!$A$6:$R$658,10,FALSE) -> 42 | M15: =VLOOKUP(E15,DUKB!$A$6:$R$658,11,FALSE) -> 34.25 | N15: =VLOOKUP(E15,DUKB!$A$6:$R$658,12,FALSE) -> 34 | O15: =VLOOKUP(E15,DUKB!$A$6:$R$658,13,FALSE) -> 1.21 | P15: =VLOOKUP(E15,DUKB!$A$6:$R$658,14,FALSE) -> 0 | Q15: =VLOOKUP(E15,DUKB!$A$6:$R$658,15,FALSE) -> 0 | R15: =VLOOKUP(E15,DUKB!$A$6:$R$658,16,FALSE) -> 0.5 | S15: =VLOOKUP(E15,DUKB!$A$6:$R$658,17,FALSE) -> 0.05 | T15: =VLOOKUP(E15,DUKB!$A$6:$R$658,18,FALSE) -> 1.16 | U15: =IF(C15="","",(SUMIF($D$2:$D$25115,D15,$O$2:$O$25115))) | V15: =D15 -> 45971 | W15: =VLOOKUP(E15,DUKB!$A$6:$B$565,2,FALSE) -> 402 | X15: =VLOOKUP(E15,DUKB!$A$6:$T$560,19,FALSE) -> 0 | Z15: =E15 -> 189 | AA15: =W15 -> 402 | AB15: =X15 -> 0 | AC15: =G15 -> Ulin | AD15: =H15 -> 13.3 | AE15: =N15 -> 34 | AF15: =O15 -> 1.21 | AH15: =E15 -> 189 | AI15: =B15 -> 10
A16: =IF(COUNTIF($E$2:$E$47178,E16)>1,"DOUBLE","") | B16: =B15+1 -> 11 | C16: =IF(D16="","",(IF(D17=D16,"",1))) | D16: 45971 | E16: 190 | F16: =VLOOKUP(E16,DUKB!$A$6:$R$658,3,FALSE) -> NL | G16: =VLOOKUP(E16,DUKB!$A$6:$R$658,4,FALSE) -> Ulin | H16: =VLOOKUP(E16,DUKB!$A$6:$R$658,6,FALSE) -> 7.5 | I16: =VLOOKUP(E16,DUKB!$A$6:$R$658,7,FALSE) -> 31 | J16: =VLOOKUP(E16,DUKB!$A$6:$R$658,8,FALSE) -> 39 | K16: =VLOOKUP(E16,DUKB!$A$6:$R$658,9,FALSE) -> 27 | L16: =VLOOKUP(E16,DUKB!$A$6:$R$658,10,FALSE) -> 38 | M16: =VLOOKUP(E16,DUKB!$A$6:$R$658,11,FALSE) -> 33.75 | N16: =VLOOKUP(E16,DUKB!$A$6:$R$658,12,FALSE) -> 34 | O16: =VLOOKUP(E16,DUKB!$A$6:$R$658,13,FALSE) -> 0.68 | P16: =VLOOKUP(E16,DUKB!$A$6:$R$658,14,FALSE) -> 0 | Q16: =VLOOKUP(E16,DUKB!$A$6:$R$658,15,FALSE) -> 0 | R16: =VLOOKUP(E16,DUKB!$A$6:$R$658,16,FALSE) -> 0.5 | S16: =VLOOKUP(E16,DUKB!$A$6:$R$658,17,FALSE) -> 0.05 | T16: =VLOOKUP(E16,DUKB!$A$6:$R$658,18,FALSE) -> 0.63 | U16: =IF(C16="","",(SUMIF($D$2:$D$25115,D16,$O$2:$O$25115))) | V16: =D16 -> 45971 | W16: =VLOOKUP(E16,DUKB!$A$6:$B$565,2,FALSE) -> 428 | X16: =VLOOKUP(E16,DUKB!$A$6:$T$560,19,FALSE) -> 0 | Z16: =E16 -> 190 | AA16: =W16 -> 428 | AB16: =X16 -> 0 | AC16: =G16 -> Ulin | AD16: =H16 -> 7.5 | AE16: =N16 -> 34 | AF16: =O16 -> 0.68 | AH16: =E16 -> 190 | AI16: =B16 -> 11
A17: =IF(COUNTIF($E$2:$E$47178,E17)>1,"DOUBLE","") | B17: =B16+1 -> 12 | C17: =IF(D17="","",(IF(D18=D17,"",1))) | D17: 45971 | E17: 191 | F17: =VLOOKUP(E17,DUKB!$A$6:$R$658,3,FALSE) -> NL | G17: =VLOOKUP(E17,DUKB!$A$6:$R$658,4,FALSE) -> Ulin | H17: =VLOOKUP(E17,DUKB!$A$6:$R$658,6,FALSE) -> 8.1 | I17: =VLOOKUP(E17,DUKB!$A$6:$R$658,7,FALSE) -> 36 | J17: =VLOOKUP(E17,DUKB!$A$6:$R$658,8,FALSE) -> 41 | K17: =VLOOKUP(E17,DUKB!$A$6:$R$658,9,FALSE) -> 28 | L17: =VLOOKUP(E17,DUKB!$A$6:$R$658,10,FALSE) -> 36 | M17: =VLOOKUP(E17,DUKB!$A$6:$R$658,11,FALSE) -> 35.25 | N17: =VLOOKUP(E17,DUKB!$A$6:$R$658,12,FALSE) -> 35 | O17: =VLOOKUP(E17,DUKB!$A$6:$R$658,13,FALSE) -> 0.78 | P17: =VLOOKUP(E17,DUKB!$A$6:$R$658,14,FALSE) -> 0 | Q17: =VLOOKUP(E17,DUKB!$A$6:$R$658,15,FALSE) -> 0 | R17: =VLOOKUP(E17,DUKB!$A$6:$R$658,16,FALSE) -> 0 | S17: =VLOOKUP(E17,DUKB!$A$6:$R$658,17,FALSE) -> 0 | T17: =VLOOKUP(E17,DUKB!$A$6:$R$658,18,FALSE) -> 0.78 | U17: =IF(C17="","",(SUMIF($D$2:$D$25115,D17,$O$2:$O$25115))) | V17: =D17 -> 45971 | W17: =VLOOKUP(E17,DUKB!$A$6:$B$565,2,FALSE) -> 451 | X17: =VLOOKUP(E17,DUKB!$A$6:$T$560,19,FALSE) -> 0 | Z17: =E17 -> 191 | AA17: =W17 -> 451 | AB17: =X17 -> 0 | AC17: =G17 -> Ulin | AD17: =H17 -> 8.1 | AE17: =N17 -> 35 | AF17: =O17 -> 0.78 | AH17: =E17 -> 191 | AI17: =B17 -> 12
A18: =IF(COUNTIF($E$2:$E$47178,E18)>1,"DOUBLE","") | B18: =B17+1 -> 13 | C18: =IF(D18="","",(IF(D19=D18,"",1))) | D18: 45971 | E18: 187 | F18: =VLOOKUP(E18,DUKB!$A$6:$R$658,3,FALSE) -> NL | G18: =VLOOKUP(E18,DUKB!$A$6:$R$658,4,FALSE) -> Ulin | H18: =VLOOKUP(E18,DUKB!$A$6:$R$658,6,FALSE) -> 13.3 | I18: =VLOOKUP(E18,DUKB!$A$6:$R$658,7,FALSE) -> 30 | J18: =VLOOKUP(E18,DUKB!$A$6:$R$658,8,FALSE) -> 35 | K18: =VLOOKUP(E18,DUKB!$A$6:$R$658,9,FALSE) -> 43 | L18: =VLOOKUP(E18,DUKB!$A$6:$R$658,10,FALSE) -> 44 | M18: =VLOOKUP(E18,DUKB!$A$6:$R$658,11,FALSE) -> 38 | N18: =VLOOKUP(E18,DUKB!$A$6:$R$658,12,FALSE) -> 38 | O18: =VLOOKUP(E18,DUKB!$A$6:$R$658,13,FALSE) -> 1.51 | P18: =VLOOKUP(E18,DUKB!$A$6:$R$658,14,FALSE) -> 0 | Q18: =VLOOKUP(E18,DUKB!$A$6:$R$658,15,FALSE) -> 0 | R18: =VLOOKUP(E18,DUKB!$A$6:$R$658,16,FALSE) -> 1.5 | S18: =VLOOKUP(E18,DUKB!$A$6:$R$658,17,FALSE) -> 0.17 | T18: =VLOOKUP(E18,DUKB!$A$6:$R$658,18,FALSE) -> 1.34 | U18: =IF(C18="","",(SUMIF($D$2:$D$25115,D18,$O$2:$O$25115))) | V18: =D18 -> 45971 | W18: =VLOOKUP(E18,DUKB!$A$6:$B$565,2,FALSE) -> 453 | X18: =VLOOKUP(E18,DUKB!$A$6:$T$560,19,FALSE) -> 0 | Z18: =E18 -> 187 | AA18: =W18 -> 453 | AB18: =X18 -> 0 | AC18: =G18 -> Ulin | AD18: =H18 -> 13.3 | AE18: =N18 -> 38 | AF18: =O18 -> 1.51 | AH18: =E18 -> 187 | AI18: =B18 -> 13
... A35: =IF(COUNTIF($E$2:$E$47178,E35)>1,"DOUBLE","") | B35: =B34+1 -> 30 | C35: =IF(D35="","",(IF(D36=D35,"",1))) -> 1 | D35: 45971 | E35: 171 | F35: =VLOOKUP(E35,DUKB!$A$6:$R$658,3,FALSE) -> NL | G35: =VLOOKUP(E35,DUKB!$A$6:$R$658,4,FALSE) -> Ulin | H35: =VLOOKUP(E35,DUKB!$A$6:$R$658,6,FALSE) -> 8.9 | I35: =VLOOKUP(E35,DUKB!$A$6:$R$658,7,FALSE) -> 36 | J35: =VLOOKUP(E35,DUKB!$A$6:$R$658,8,FALSE) -> 45 | K35: =VLOOKUP(E35,DUKB!$A$6:$R$658,9,FALSE) -> 36 | L35: =VLOOKUP(E35,DUKB!$A$6:$R$658,10,FALSE) -> 39 | M35: =VLOOKUP(E35,DUKB!$A$6:$R$658,11,FALSE) -> 39 | N35: =VLOOKUP(E35,DUKB!$A$6:$R$658,12,FALSE) -> 39 | O35: =VLOOKUP(E35,DUKB!$A$6:$R$658,13,FALSE) -> 1.06 | P35: =VLOOKUP(E35,DUKB!$A$6:$R$658,14,FALSE) -> 0 | Q35: =VLOOKUP(E35,DUKB!$A$6:$R$658,15,FALSE) -> 0 | R35: =VLOOKUP(E35,DUKB!$A$6:$R$658,16,FALSE) -> 0.5 | S35: =VLOOKUP(E35,DUKB!$A$6:$R$658,17,FALSE) -> 0.06 | T35: =VLOOKUP(E35,DUKB!$A$6:$R$658,18,FALSE) -> 1 | U35: =IF(C35="","",(SUMIF($D$2:$D$25115,D35,$O$2:$O$25115))) -> 28.41 | V35: =D35 -> 45971 | W35: =VLOOKUP(E35,DUKB!$A$6:$B$565,2,FALSE) -> 447 | X35: =VLOOKUP(E35,DUKB!$A$6:$T$560,19,FALSE) -> 0 | Z35: =E35 -> 171 | AA35: =W35 -> 447 | AB35: =X35 -> 0 | AC35: =G35 -> Ulin | AD35: =H35 -> 8.9 | AE35: =N35 -> 39 | AF35: =O35 -> 1.06 | AH35: =E35 -> 171 | AI35: =B35 -> 30
A36: =IF(COUNTIF($E$2:$E$47178,E36)>1,"DOUBLE","") | B36: 1 | C36: =IF(D36="","",(IF(D37=D36,"",1))) | F36: =VLOOKUP(E36,DUKB!$A$6:$R$658,3,FALSE) -> #N/A | G36: =VLOOKUP(E36,DUKB!$A$6:$R$658,4,FALSE) -> #N/A | H36: =VLOOKUP(E36,DUKB!$A$6:$R$658,6,FALSE) -> #N/A | I36: =VLOOKUP(E36,DUKB!$A$6:$R$658,7,FALSE) -> #N/A | J36: =VLOOKUP(E36,DUKB!$A$6:$R$658,8,FALSE) -> #N/A | K36: =VLOOKUP(E36,DUKB!$A$6:$R$658,9,FALSE) -> #N/A | L36: =VLOOKUP(E36,DUKB!$A$6:$R$658,10,FALSE) -> #N/A | M36: =VLOOKUP(E36,DUKB!$A$6:$R$658,11,FALSE) -> #N/A | N36: =VLOOKUP(E36,DUKB!$A$6:$R$658,12,FALSE) -> #N/A | O36: =VLOOKUP(E36,DUKB!$A$6:$R$658,13,FALSE) -> #N/A | P36: =VLOOKUP(E36,DUKB!$A$6:$R$658,14,FALSE) -> #N/A | Q36: =VLOOKUP(E36,DUKB!$A$6:$R$658,15,FALSE) -> #N/A | R36: =VLOOKUP(E36,DUKB!$A$6:$R$658,16,FALSE) -> #N/A | S36: =VLOOKUP(E36,DUKB!$A$6:$R$658,17,FALSE) -> #N/A | T36: =VLOOKUP(E36,DUKB!$A$6:$R$658,18,FALSE) -> #N/A | U36: =IF(C36="","",(SUMIF($D$2:$D$25115,D36,$O$2:$O$25115))) | V36: =D36 -> 0 | W36: =VLOOKUP(E36,DUKB!$A$6:$B$565,2,FALSE) -> #N/A | X36: =VLOOKUP(E36,DUKB!$A$6:$T$560,19,FALSE) -> #N/A | Z36: =E36 -> 0 | AA36: =W36 -> #N/A | AB36: =X36 -> #N/A | AC36: =G36 -> #N/A | AD36: =H36 -> #N/A | AE36: =N36 -> #N/A | AF36: =O36 -> #N/A | AH36: =E36 -> 0 | AI36: =B36 -> 1
A37: =IF(COUNTIF($E$2:$E$47178,E37)>1,"DOUBLE","") | B37: =B36+1 -> 2 | C37: =IF(D37="","",(IF(D38=D37,"",1))) | F37: =VLOOKUP(E37,DUKB!$A$6:$R$658,3,FALSE) -> #N/A | G37: =VLOOKUP(E37,DUKB!$A$6:$R$658,4,FALSE) -> #N/A | H37: =VLOOKUP(E37,DUKB!$A$6:$R$658,6,FALSE) -> #N/A | I37: =VLOOKUP(E37,DUKB!$A$6:$R$658,7,FALSE) -> #N/A | J37: =VLOOKUP(E37,DUKB!$A$6:$R$658,8,FALSE) -> #N/A | K37: =VLOOKUP(E37,DUKB!$A$6:$R$658,9,FALSE) -> #N/A | L37: =VLOOKUP(E37,DUKB!$A$6:$R$658,10,FALSE) -> #N/A | M37: =VLOOKUP(E37,DUKB!$A$6:$R$658,11,FALSE) -> #N/A | N37: =VLOOKUP(E37,DUKB!$A$6:$R$658,12,FALSE) -> #N/A | O37: =VLOOKUP(E37,DUKB!$A$6:$R$658,13,FALSE) -> #N/A | P37: =VLOOKUP(E37,DUKB!$A$6:$R$658,14,FALSE) -> #N/A | Q37: =VLOOKUP(E37,DUKB!$A$6:$R$658,15,FALSE) -> #N/A | R37: =VLOOKUP(E37,DUKB!$A$6:$R$658,16,FALSE) -> #N/A | S37: =VLOOKUP(E37,DUKB!$A$6:$R$658,17,FALSE) -> #N/A | T37: =VLOOKUP(E37,DUKB!$A$6:$R$658,18,FALSE) -> #N/A | U37: =IF(C37="","",(SUMIF($D$2:$D$25115,D37,$O$2:$O$25115))) | V37: =D37 -> 0 | W37: =VLOOKUP(E37,DUKB!$A$6:$B$565,2,FALSE) -> #N/A | X37: =VLOOKUP(E37,DUKB!$A$6:$T$560,19,FALSE) -> #N/A | Z37: =E37 -> 0 | AA37: =W37 -> #N/A | AB37: =X37 -> #N/A | AC37: =G37 -> #N/A | AD37: =H37 -> #N/A | AE37: =N37 -> #N/A | AF37: =O37 -> #N/A | AH37: =E37 -> 0 | AI37: =B37 -> 2
A38: =IF(COUNTIF($E$2:$E$47178,E38)>1,"DOUBLE","") | B38: =B37+1 -> 3 | C38: =IF(D38="","",(IF(D39=D38,"",1))) | F38: =VLOOKUP(E38,DUKB!$A$6:$R$658,3,FALSE) -> #N/A | G38: =VLOOKUP(E38,DUKB!$A$6:$R$658,4,FALSE) -> #N/A | H38: =VLOOKUP(E38,DUKB!$A$6:$R$658,6,FALSE) -> #N/A | I38: =VLOOKUP(E38,DUKB!$A$6:$R$658,7,FALSE) -> #N/A | J38: =VLOOKUP(E38,DUKB!$A$6:$R$658,8,FALSE) -> #N/A | K38: =VLOOKUP(E38,DUKB!$A$6:$R$658,9,FALSE) -> #N/A | L38: =VLOOKUP(E38,DUKB!$A$6:$R$658,10,FALSE) -> #N/A | M38: =VLOOKUP(E38,DUKB!$A$6:$R$658,11,FALSE) -> #N/A | N38: =VLOOKUP(E38,DUKB!$A$6:$R$658,12,FALSE) -> #N/A | O38: =VLOOKUP(E38,DUKB!$A$6:$R$658,13,FALSE) -> #N/A | P38: =VLOOKUP(E38,DUKB!$A$6:$R$658,14,FALSE) -> #N/A | Q38: =VLOOKUP(E38,DUKB!$A$6:$R$658,15,FALSE) -> #N/A | R38: =VLOOKUP(E38,DUKB!$A$6:$R$658,16,FALSE) -> #N/A | S38: =VLOOKUP(E38,DUKB!$A$6:$R$658,17,FALSE) -> #N/A | T38: =VLOOKUP(E38,DUKB!$A$6:$R$658,18,FALSE) -> #N/A | U38: =IF(C38="","",(SUMIF($D$2:$D$25115,D38,$O$2:$O$25115))) | V38: =D38 -> 0 | W38: =VLOOKUP(E38,DUKB!$A$6:$B$565,2,FALSE) -> #N/A | X38: =VLOOKUP(E38,DUKB!$A$6:$T$560,19,FALSE) -> #N/A | Z38: =E38 -> 0 | AA38: =W38 -> #N/A | AB38: =X38 -> #N/A | AC38: =G38 -> #N/A | AD38: =H38 -> #N/A | AE38: =N38 -> #N/A | AF38: =O38 -> #N/A | AH38: =E38 -> 0 | AI38: =B38 -> 3
A39: =IF(COUNTIF($E$2:$E$47178,E39)>1,"DOUBLE","") | B39: =B38+1 -> 4 | C39: =IF(D39="","",(IF(D40=D39,"",1))) | F39: =VLOOKUP(E39,DUKB!$A$6:$R$658,3,FALSE) -> #N/A | G39: =VLOOKUP(E39,DUKB!$A$6:$R$658,4,FALSE) -> #N/A | H39: =VLOOKUP(E39,DUKB!$A$6:$R$658,6,FALSE) -> #N/A | I39: =VLOOKUP(E39,DUKB!$A$6:$R$658,7,FALSE) -> #N/A | J39: =VLOOKUP(E39,DUKB!$A$6:$R$658,8,FALSE) -> #N/A | K39: =VLOOKUP(E39,DUKB!$A$6:$R$658,9,FALSE) -> #N/A | L39: =VLOOKUP(E39,DUKB!$A$6:$R$658,10,FALSE) -> #N/A | M39: =VLOOKUP(E39,DUKB!$A$6:$R$658,11,FALSE) -> #N/A | N39: =VLOOKUP(E39,DUKB!$A$6:$R$658,12,FALSE) -> #N/A | O39: =VLOOKUP(E39,DUKB!$A$6:$R$658,13,FALSE) -> #N/A | P39: =VLOOKUP(E39,DUKB!$A$6:$R$658,14,FALSE) -> #N/A | Q39: =VLOOKUP(E39,DUKB!$A$6:$R$658,15,FALSE) -> #N/A | R39: =VLOOKUP(E39,DUKB!$A$6:$R$658,16,FALSE) -> #N/A | S39: =VLOOKUP(E39,DUKB!$A$6:$R$658,17,FALSE) -> #N/A | T39: =VLOOKUP(E39,DUKB!$A$6:$R$658,18,FALSE) -> #N/A | U39: =IF(C39="","",(SUMIF($D$2:$D$25115,D39,$O$2:$O$25115))) | V39: =D39 -> 0 | W39: =VLOOKUP(E39,DUKB!$A$6:$B$565,2,FALSE) -> #N/A | X39: =VLOOKUP(E39,DUKB!$A$6:$T$560,19,FALSE) -> #N/A | Z39: =E39 -> 0 | AA39: =W39 -> #N/A | AB39: =X39 -> #N/A | AC39: =G39 -> #N/A | AD39: =H39 -> #N/A | AE39: =N39 -> #N/A | AF39: =O39 -> #N/A | AH39: =E39 -> 0 | AI39: =B39 -> 4
A40: =IF(COUNTIF($E$2:$E$47178,E40)>1,"DOUBLE","") | B40: =B39+1 -> 5 | C40: =IF(D40="","",(IF(D41=D40,"",1))) | F40: =VLOOKUP(E40,DUKB!$A$6:$R$658,3,FALSE) -> #N/A | G40: =VLOOKUP(E40,DUKB!$A$6:$R$658,4,FALSE) -> #N/A | H40: =VLOOKUP(E40,DUKB!$A$6:$R$658,6,FALSE) -> #N/A | I40: =VLOOKUP(E40,DUKB!$A$6:$R$658,7,FALSE) -> #N/A | J40: =VLOOKUP(E40,DUKB!$A$6:$R$658,8,FALSE) -> #N/A | K40: =VLOOKUP(E40,DUKB!$A$6:$R$658,9,FALSE) -> #N/A | L40: =VLOOKUP(E40,DUKB!$A$6:$R$658,10,FALSE) -> #N/A | M40: =VLOOKUP(E40,DUKB!$A$6:$R$658,11,FALSE) -> #N/A | N40: =VLOOKUP(E40,DUKB!$A$6:$R$658,12,FALSE) -> #N/A | O40: =VLOOKUP(E40,DUKB!$A$6:$R$658,13,FALSE) -> #N/A | P40: =VLOOKUP(E40,DUKB!$A$6:$R$658,14,FALSE) -> #N/A | Q40: =VLOOKUP(E40,DUKB!$A$6:$R$658,15,FALSE) -> #N/A | R40: =VLOOKUP(E40,DUKB!$A$6:$R$658,16,FALSE) -> #N/A | S40: =VLOOKUP(E40,DUKB!$A$6:$R$658,17,FALSE) -> #N/A | T40: =VLOOKUP(E40,DUKB!$A$6:$R$658,18,FALSE) -> #N/A | U40: =IF(C40="","",(SUMIF($D$2:$D$25115,D40,$O$2:$O$25115))) | V40: =D40 -> 0 | W40: =VLOOKUP(E40,DUKB!$A$6:$B$565,2,FALSE) -> #N/A | X40: =VLOOKUP(E40,DUKB!$A$6:$T$560,19,FALSE) -> #N/A | Z40: =E40 -> 0 | AA40: =W40 -> #N/A | AB40: =X40 -> #N/A | AC40: =G40 -> #N/A | AD40: =H40 -> #N/A | AE40: =N40 -> #N/A | AF40: =O40 -> #N/A | AH40: =E40 -> 0 | AI40: =B40 -> 5
A41: =IF(COUNTIF($E$2:$E$47178,E41)>1,"DOUBLE","") | B41: =B40+1 -> 6 | C41: =IF(D41="","",(IF(D42=D41,"",1))) | F41: =VLOOKUP(E41,DUKB!$A$6:$R$658,3,FALSE) -> #N/A | G41: =VLOOKUP(E41,DUKB!$A$6:$R$658,4,FALSE) -> #N/A | H41: =VLOOKUP(E41,DUKB!$A$6:$R$658,6,FALSE) -> #N/A | I41: =VLOOKUP(E41,DUKB!$A$6:$R$658,7,FALSE) -> #N/A | J41: =VLOOKUP(E41,DUKB!$A$6:$R$658,8,FALSE) -> #N/A | K41: =VLOOKUP(E41,DUKB!$A$6:$R$658,9,FALSE) -> #N/A | L41: =VLOOKUP(E41,DUKB!$A$6:$R$658,10,FALSE) -> #N/A | M41: =VLOOKUP(E41,DUKB!$A$6:$R$658,11,FALSE) -> #N/A | N41: =VLOOKUP(E41,DUKB!$A$6:$R$658,12,FALSE) -> #N/A | O41: =VLOOKUP(E41,DUKB!$A$6:$R$658,13,FALSE) -> #N/A | P41: =VLOOKUP(E41,DUKB!$A$6:$R$658,14,FALSE) -> #N/A | Q41: =VLOOKUP(E41,DUKB!$A$6:$R$658,15,FALSE) -> #N/A | R41: =VLOOKUP(E41,DUKB!$A$6:$R$658,16,FALSE) -> #N/A | S41: =VLOOKUP(E41,DUKB!$A$6:$R$658,17,FALSE) -> #N/A | T41: =VLOOKUP(E41,DUKB!$A$6:$R$658,18,FALSE) -> #N/A | U41: =IF(C41="","",(SUMIF($D$2:$D$25115,D41,$O$2:$O$25115))) | V41: =D41 -> 0 | W41: =VLOOKUP(E41,DUKB!$A$6:$B$565,2,FALSE) -> #N/A | X41: =VLOOKUP(E41,DUKB!$A$6:$T$560,19,FALSE) -> #N/A | Z41: =E41 -> 0 | AA41: =W41 -> #N/A | AB41: =X41 -> #N/A | AC41: =G41 -> #N/A | AD41: =H41 -> #N/A | AE41: =N41 -> #N/A | AF41: =O41 -> #N/A | AH41: =E41 -> 0 | AI41: =B41 -> 6
