Workbook

Sheet REKAP
M1: INPUT LOG MERANTI | X1: REKAP HASIL GESEK MERANTI | AF1: REKAP BELI MASAK | AN1: REKAP BENGKIRAI PLAT
B2: REKAP GRAND TOTAL
X3: EX - LOG | AB3: PER TGL 30 JUNI 2026
B4: PER TGL 18 JULI 2026 | G4: OUTPUT | I4: MUAT FUSO | M4: NO | N4: CODE | O4: JENIS | P4: VOLUME | V4: KET | X4: UKURAN | AA4: VOLUME | AC4: VOLUME | AF4: UKURAN | AI4: VOLUME | AK4: VOLUME | AN4: UKURAN KAYU | AQ4: VOLUME | AS4: VOLUME
B5: LOG MERANTI | E5: =SUM('[1]LOG LIST'!E572) -> 373.54928 | F5: BLK | G5: =SUM([1]MERANTI!N1926) -> 202.36703 | H5: =SUM(G5/E5) -> 0.54174119 | I5: 1 | J5: 34.1596 | P5: PJG | Q5: PKL | R5: UJUNG | S5: RT | T5: M3 | U5: JML | X5: T | Y5: L | Z5: P | AA5: PCS | AB5: M3 | AC5: PCS | AD5: M3 | AF5: T | AG5: L | AH5: P | AI5: PCS | AJ5: M3 | AK5: PCS | AL5: M3 | AN5: T | AO5: L | AP5: P | AQ5: PCS | AR5: M3 | AS5: PCS | AT5: M4
B6: BLM PROSES | E6: =SUM('[1]LOG LIST'!E573) -> 48.826119 | F6: RENG | G6: =SUM([1]MERANTI!N1927) -> 66.4652 | H6: =SUM(G6/E5) -> 0.17792887 | I6: 2 | J6: 35.8378 | M6: 1 | N6: 5372 | O6: MRT | P6: 400 | Q6: 38 | R6: 38 | S6: 38 | T6: =0.7854*P6*S6*S6/1000000 -> 0.45364704 | V6: EX P ARI | X6: 15 | Y6: 33 | Z6: 400 | AA6: 11 | AB6: =X6*Y6*Z6*AA6/1000000 -> 2.178 | AF6: 4 | AG6: 10 | AH6: 400 | AI6: 475 | AJ6: =AF6*AG6*AH6*AI6/1000000 -> 7.6 | AN6: 2 | AO6: 3 | AP6: 400 | AQ6: 25 | AR6: =AN6*AO6*AP6*AQ6/1000000 -> 0.06 | AS6: =SUM(AQ6) -> 25 | AT6: =SUM(AR6) -> 0.06
E7: =SUM(E5:E6) -> 422.3754 | G7: =SUM(G5:G6) -> 268.83223 | H7: =SUM(G7/E5) -> 0.71967006 | I7: 3 | J7: 37.355 | M7: 2 | N7: 5351 | O7: MRT | P7: 400 | Q7: 37 | R7: 37 | S7: 37 | T7: =0.7854*P7*S7*S7/1000000 -> 0.43008504 | V7: EX P ARI | X7: 15 | Y7: 30 | Z7: 400 | AA7: 23 | AB7: =X7*Y7*Z7*AA7/1000000 -> 4.14 | AF7: 4 | AG7: 10 | AH7: 360 | AI7: 44 | AJ7: =AF7*AG7*AH7*AI7/1000000 -> 0.6336 | AN7: 2 | AO7: 10 | AP7: 400 | AQ7: 6 | AR7: =AN7*AO7*AP7*AQ7/1000000 -> 0.048 | AS7: =SUM(AQ7) -> 6 | AT7: =SUM(AR7) -> 0.048
G8: 10.428 | H8: MASAK | I8: 4 | J8: 10.756 | M8: 3 | N8: 5366 | O8: MRT | P8: 400 | Q8: 39 | R8: 39 | S8: 39 | T8: =0.7854*P8*S8*S8/1000000 -> 0.47783736 | V8: EX P ARI | X8: 15 | Y8: 28 | Z8: 400 | AA8: 6 | AB8: =X8*Y8*Z8*AA8/1000000 -> 1.008 | AF8: 4 | AG8: 10 | AH8: 300 | AI8: 44 | AJ8: =AF8*AG8*AH8*AI8/1000000 -> 0.528 | AN8: 3 | AO8: 13 | AP8: 400 | AQ8: 8 | AR8: =AN8*AO8*AP8*AQ8/1000000 -> 0.1248
G9: =SUM(G7:G8) -> 279.26023 | I9: 5 | J9: 35.0564 | M9: 4 | N9: 5355 | O9: MRT | P9: 400 | Q9: 39 | R9: 39 | S9: 39 | T9: =0.7854*P9*S9*S9/1000000 -> 0.47783736 | V9: EX P ARI | X9: 15 | Y9: 25 | Z9: 400 | AA9: 46 | AB9: =X9*Y9*Z9*AA9/1000000 -> 6.9 | AF9: 4 | AG9: 7 | AH9: 400 | AI9: 76 | AJ9: =AF9*AG9*AH9*AI9/1000000 -> 0.8512 | AN9: 3 | AO9: 15 | AP9: 400 | AQ9: =9+5 -> 14 | AR9: =AN9*AO9*AP9*AQ9/1000000 -> 0.252
I10: 6 | J10: 37.1529 | M10: 5 | N10: 5426 | O10: MRT | P10: 400 | Q10: 35 | R10: 35 | S10: 35 | T10: =0.7854*P10*S10*S10/1000000 -> 0.384846 | V10: EX P ARI | X10: 15 | Y10: 23 | Z10: 400 | AA10: 6 | AB10: =X10*Y10*Z10*AA10/1000000 -> 0.828 | AF10: 4 | AG10: 7 | AH10: 360 | AI10: 8 | AJ10: =AF10*AG10*AH10*AI10/1000000 -> 0.08064 | AN10: 3 | AO10: 20 | AP10: 400 | AQ10: 3 | AR10: =AN10*AO10*AP10*AQ10/1000000 -> 0.072
I11: 7 | J11: 36.7154 | M11: 6 | N11: 5502 | O11: MRT | P11: 400 | Q11: 30 | R11: 30 | S11: 30 | T11: =0.7854*P11*S11*S11/1000000 -> 0.282744 | V11: EX RM | X11: 15 | Y11: 20 | Z11: 400 | AA11: 45 | AB11: =X11*Y11*Z11*AA11/1000000 -> 5.4 | AF11: 4 | AG11: 7 | AH11: 300 | AI11: 14 | AJ11: =AF11*AG11*AH11*AI11/1000000 -> 0.1176 | AN11: 3 | AO11: 25 | AP11: 400 | AQ11: 2 | AR11: =AN11*AO11*AP11*AQ11/1000000 -> 0.06 | AS11: =SUM(AQ8:AQ11) -> 27 | AT11: =SUM(AR8:AR11) -> 0.5088
I12: 8 | J12: 1.728 | M12: 7 | N12: 5449 | O12: MRT | P12: 400 | Q12: 35 | R12: 36 | S12: 35 | T12: =0.7854*P12*S12*S12/1000000 -> 0.384846 | V12: EX RM | X12: 15 | Y12: 18 | Z12: 400 | AA12: 19 | AB12: =X12*Y12*Z12*AA12/1000000 -> 2.052 | AF12: 3 | AG12: 7 | AH12: 400 | AI12: 55 | AJ12: =AF12*AG12*AH12*AI12/1000000 -> 0.462 | AN12: 4 | AO12: 20 | AP12: 400 | AQ12: 1 | AR12: =AN12*AO12*AP12*AQ12/1000000 -> 0.032 | AS12: =SUM(AQ12) -> 1 | AT12: =SUM(AR12) -> 0.032
I13: 9 | J13: 35.1909 | M13: 8 | N13: 5344 | O13: MRT | P13: 400 | Q13: 37 | R13: 37 | S13: 37 | T13: =0.7854*P13*S13*S13/1000000 -> 0.43008504 | V13: EX P IS | X13: 15 | Y13: 15 | Z13: 400 | AA13: 37 | AB13: =X13*Y13*Z13*AA13/1000000 -> 3.33 | AF13: 3 | AG13: 7 | AH13: 360 | AI13: 3 | AJ13: =AF13*AG13*AH13*AI13/1000000 -> 0.02268 | AN13: 5 | AO13: 20 | AP13: 400 | AQ13: 1 | AR13: =AN13*AO13*AP13*AQ13/1000000 -> 0.04 | AS13: =SUM(AQ13) -> 1 | AT13: =SUM(AR13) -> 0.04
J14: =SUM(J5:J13) -> 263.952 | M14: 9 | N14: 5317 | O14: MRT | P14: 400 | Q14: 34 | R14: 42 | S14: 38 | T14: =0.7854*P14*S14*S14/1000000 -> 0.45364704 | V14: EX P BADI | X14: 15 | Y14: 13 | Z14: 400 | AA14: 3 | AB14: =X14*Y14*Z14*AA14/1000000 -> 0.234 | AF14: 3 | AG14: 7 | AH14: 300 | AI14: 21 | AJ14: =AF14*AG14*AH14*AI14/1000000 -> 0.1323 | AK14: =SUM(AI6:AI14) -> 740 | AL14: =SUM(AJ6:AJ14) -> 10.42802 | AN14: 6 | AO14: 13 | AP14: 400 | AQ14: 2 | AR14: =AN14*AO14*AP14*AQ14/1000000 -> 0.0624
M15: 10 | N15: 5322 | O15: MRT | P15: 300 | Q15: 30 | R15: 30 | S15: 30 | T15: =0.7854*P15*S15*S15/1000000 -> 0.212058 | V15: EX P BADI | X15: 15 | Y15: 12 | Z15: 400 | AA15: 4 | AB15: =X15*Y15*Z15*AA15/1000000 -> 0.288 | AF15: MERANTI | AI15: =SUM(AI6:AI14) -> 740 | AJ15: =SUM(AJ6:AJ14) -> 10.42802 | AK15: =SUM(AK6:AK14) -> 740 | AL15: =SUM(AL6:AL14) -> 10.42802 | AN15: 6 | AO15: 15 | AP15: 400 | AQ15: 8 | AR15: =AN15*AO15*AP15*AQ15/1000000 -> 0.288 | AS15: =SUM(AQ14:AQ15) -> 10 | AT15: =SUM(AR14:AR15) -> 0.3504
G16: STOCK MERANTI | J16: =SUM(G9-J14) -> 15.30823 | M16: 11 | N16: 354 | O16: MRT | P16: 400 | Q16: 39 | R16: 38 | S16: 38 | T16: =0.7854*P16*S16*S16/1000000 -> 0.45364704 | U16: =SUM(T6:T16) -> 4.4412799 | V16: EX BJB | X16: 15 | Y16: 10 | Z16: 400 | AA16: 24 | AB16: =X16*Y16*Z16*AA16/1000000 -> 1.44 | AF16: 15 | AG16: 20 | AH16: 400 | AI16: 1 | AJ16: =AF16*AG16*AH16*AI16/1000000 -> 0.12 | AN16: 7 | AO16: 13 | AP16: 400 | AQ16: 1 | AR16: =AN16*AO16*AP16*AQ16/1000000 -> 0.0364 | AS16: =SUM(AQ16) -> 1 | AT16: =SUM(AR16) -> 0.0364
M17: 12 | N17: 5320 | O17: MRT | P17: 400 | Q17: 51 | R17: 55 | S17: 53 | T17: =0.7854*P17*S17*S17/1000000 -> 0.88247544 | V17: EX P BADI | X17: 15 | Y17: 8 | Z17: 400 | AA17: 10 | AB17: =X17*Y17*Z17*AA17/1000000 -> 0.48 | AF17: 15 | AG17: 15 | AH17: 400 | AI17: 8 | AJ17: =AF17*AG17*AH17*AI17/1000000 -> 0.72 | AK17: =SUM(AI16:AI17) -> 9 | AL17: =SUM(AJ16:AJ17) -> 0.84 | AN17: 8 | AO17: 15 | AP17: 400 | AQ17: 4 | AR17: =AN17*AO17*AP17*AQ17/1000000 -> 0.192 | AS17: =SUM(AQ17) -> 4 | AT17: =SUM(AR17) -> 0.192
G18: OUTPUT | I18: MUAT FUSO | M18: 13 | N18: 5302 | O18: MRT | P18: 400 | Q18: 55 | R18: 57 | S18: 56 | T18: =0.7854*P18*S18*S18/1000000 -> 0.98520576 | V18: EX P BADI | X18: 15 | Y18: 5 | Z18: 400 | AA18: 12 | AB18: =X18*Y18*Z18*AA18/1000000 -> 0.36 | AC18: =SUM(AA6:AA18) -> 246 | AD18: =SUM(AB6:AB18) -> 28.638 | AF18: 12 | AG18: 15 | AH18: 400 | AI18: 9 | AJ18: =AF18*AG18*AH18*AI18/1000000 -> 0.648 | AK18: =SUM(AI18) -> 9 | AL18: =SUM(AJ18) -> 0.648 | AN18: 13 | AO18: 13 | AP18: 300 | AQ18: 1 | AR18: =AN18*AO18*AP18*AQ18/1000000 -> 0.0507
B19: LOG BENGKIRAI | E19: 9.1766 | G19: 11.3544 | H19: BLK | I19: 4 | J19: 21.8096 | M19: 14 | N19: 5359 | O19: MRT | P19: 400 | Q19: 40 | R19: 40 | S19: 40 | T19: =0.7854*P19*S19*S19/1000000 -> 0.502656 | V19: EX P ARI | X19: 13 | Y19: 33 | Z19: 400 | AA19: 2 | AB19: =X19*Y19*Z19*AA19/1000000 -> 0.3432 | AF19: 10 | AG19: 15 | AH19: 400 | AI19: 15 | AJ19: =AF19*AG19*AH19*AI19/1000000 -> 0.9 | AK19: =SUM(AI19) -> 15 | AL19: =SUM(AJ19) -> 0.9 | AN19: 13 | AO19: 13 | AP19: 400 | AQ19: 1 | AR19: =AN19*AO19*AP19*AQ19/1000000 -> 0.0676
E20: 9.9033 | G20: 2.25 | H20: RENG | I20: 8 | J20: 28.2147 | M20: 15 | N20: 5296 | O20: MRT | P20: 400 | Q20: 41 | R20: 41 | S20: 41 | T20: =0.7854*P20*S20*S20/1000000 -> 0.52810296 | V20: EX P ARI | X20: 13 | Y20: 30 | Z20: 400 | AA20: 15 | AB20: =X20*Y20*Z20*AA20/1000000 -> 2.34 | AF20: 9.5 | AG20: 9.5 | AH20: 400 | AI20: 10 | AJ20: =AF20*AG20*AH20*AI20/1000000 -> 0.361 | AK20: =SUM(AI20) -> 10 | AL20: =SUM(AJ20) -> 0.361 | AN20: 13 | AO20: 15 | AP20: 400 | AQ20: 2 | AR20: =AN20*AO20*AP20*AQ20/1000000 -> 0.156 | AS20: =SUM(AQ18:AQ20) -> 4 | AT20: =SUM(AR18:AR20) -> 0.2743
E21: 2.7627 | G21: =SUM(G19:G20) -> 13.6044 | J21: =SUM(J19) -> 21.8096 | M21: 16 | N21: 5318 | O21: MRT | P21: 400 | Q21: 63 | R21: 63 | S21: 63 | T21: =0.7854*P21*S21*S21/1000000 -> 1.246901 | V21: EX P ARI | X21: 13 | Y21: 28 | Z21: 400 | AA21: 2 | AB21: =X21*Y21*Z21*AA21/1000000 -> 0.2912 | AF21: 8 | AG21: 15 | AH21: 400 | AI21: 3 | AJ21: =AF21*AG21*AH21*AI21/1000000 -> 0.144 | AK21: =SUM(AI21) -> 3 | AL21: =SUM(AJ21) -> 0.144 | AN21: 15 | AO21: 15 | AP21: 400 | AQ21: 29 | AR21: =AN21*AO21*AP21*AQ21/1000000 -> 2.61
E22: =SUM(E19:E21) -> 21.8426 | G22: =SUM([1]BENGKIRAI!S99) -> 0.7152 | H22: MASAK | M22: 17 | N22: 5328 | O22: MRT | P22: 400 | Q22: 57 | R22: 57 | S22: 57 | T22: =0.7854*P22*S22*S22/1000000 -> 1.0207058 | V22: EX P ARI | X22: 13 | Y22: 25 | Z22: 400 | AA22: 24 | AB22: =X22*Y22*Z22*AA22/1000000 -> 3.12 | AF22: 6 | AG22: 15 | AH22: 400 | AI22: 14 | AJ22: =AF22*AG22*AH22*AI22/1000000 -> 0.504 | AN22: 15 | AO22: 20 | AP22: 400 | AQ22: 6 | AR22: =AN22*AO22*AP22*AQ22/1000000 -> 0.72
G23: =SUM('[1]BELI MASAK MERANTI BENGKIRAI'!H19) -> 4.701936 | H23: MASAK | M23: 18 | N23: 5386 | O23: MRT | P23: 400 | Q23: 49 | R23: 49 | S23: 49 | T23: =0.7854*P23*S23*S23/1000000 -> 0.75429816 | V23: EX P ARI | X23: 13 | Y23: 23 | Z23: 400 | AA23: 14 | AB23: =X23*Y23*Z23*AA23/1000000 -> 1.6744 | AF23: 6 | AG23: 12 | AH23: 400 | AI23: 2 | AJ23: =AF23*AG23*AH23*AI23/1000000 -> 0.0576 | AN23: 15 | AO23: 24 | AP23: 400 | AQ23: 2 | AR23: =AN23*AO23*AP23*AQ23/1000000 -> 0.288
G24: =SUM('[1]PLAT BENGKIRAI'!P41) -> 5.3099 | H24: PLAT | M24: 19 | N24: 5389 | O24: MRT | P24: 400 | Q24: 48 | R24: 48 | S24: 48 | T24: =0.7854*P24*S24*S24/1000000 -> 0.72382464 | V24: EX P ARI | X24: 13 | Y24: 20 | Z24: 400 | AA24: 30 | AB24: =X24*Y24*Z24*AA24/1000000 -> 3.12 | AF24: 6 | AG24: 10 | AH24: 400 | AI24: 2 | AJ24: =AF24*AG24*AH24*AI24/1000000 -> 0.048 | AK24: =SUM(AI22:AI24) -> 18 | AL24: =SUM(AJ22:AJ24) -> 0.6096 | AN24: 15 | AO24: 25 | AP24: 400 | AQ24: 1 | AR24: =AN24*AO24*AP24*AQ24/1000000 -> 0.15 | AS24: =SUM(AQ21:AQ24) -> 38 | AT24: =SUM(AR21:AR24) -> 3.768
G25: =SUM('[1]PLAT BENGKIRAI'!P42) -> 0.208 | H25: MASAK | M25: 20 | N25: 5323 | O25: MRT | P25: 400 | Q25: 46 | R25: 46 | S25: 46 | T25: =0.7854*P25*S25*S25/1000000 -> 0.66476256 | V25: EX P ARI | X25: 13 | Y25: 18 | Z25: 400 | AA25: 14 | AB25: =X25*Y25*Z25*AA25/1000000 -> 1.3104 | AF25: 4.5 | AG25: 10 | AH25: 400 | AI25: 10 | AJ25: =AF25*AG25*AH25*AI25/1000000 -> 0.18 | AN25: BENGKIRAI PLAT | AQ25: =SUM(AQ6:AQ24) -> 117 | AR25: =SUM(AR6:AR24) -> 5.3099 | AS25: =SUM(AS6:AS24) -> 117 | AT25: =SUM(AT6:AT24) -> 5.3099
G26: =SUM(G21:G25) -> 24.539436 | M26: 21 | N26: 5273 | O26: MRT | P26: 400 | Q26: 43 | R26: 43 | S26: 43 | T26: =0.7854*P26*S26*S26/1000000 -> 0.58088184 | V26: EX P ARI | X26: 13 | Y26: 15 | Z26: 400 | AA26: 22 | AB26: =X26*Y26*Z26*AA26/1000000 -> 1.716 | AF26: 4.5 | AG26: 9.5 | AH26: 400 | AI26: 22 | AJ26: =AF26*AG26*AH26*AI26/1000000 -> 0.3762 | AK26: =SUM(AI25:AI26) -> 32 | AL26: =SUM(AJ25:AJ26) -> 0.5562 | AN26: 6 | AO26: 15 | AP26: 400 | AQ26: 2 | AR26: =AN26*AO26*AP26*AQ26/1000000 -> 0.072
M27: 22 | N27: 5326 | O27: MRT | P27: 400 | Q27: 64 | R27: 64 | S27: 64 | T27: =0.7854*P27*S27*S27/1000000 -> 1.2867994 | V27: EX P ARI | X27: 13 | Y27: 13 | Z27: 400 | AA27: 3 | AB27: =X27*Y27*Z27*AA27/1000000 -> 0.2028 | AF27: 4.2 | AG27: 4.2 | AH27: 400 | AI27: 6 | AJ27: =AF27*AG27*AH27*AI27/1000000 -> 0.042336 | AK27: =SUM(AI27) -> 6 | AL27: =SUM(AJ27) -> 0.042336 | AN27: 2 | AO27: 10 | AP27: 400 | AQ27: 14 | AR27: =AN27*AO27*AP27*AQ27/1000000 -> 0.112
G28: STOCK BENGKIRAI | J28: =SUM(G26-J21) -> 2.729836 | M28: 23 | N28: 5392 | O28: MRT | P28: 400 | Q28: 66 | R28: 66 | S28: 66 | T28: =0.7854*P28*S28*S28/1000000 -> 1.368481 | V28: EX P ARI | X28: 13 | Y28: 10 | Z28: 400 | AA28: 2 | AB28: =X28*Y28*Z28*AA28/1000000 -> 0.104 | AF28: 3 | AG28: 15 | AH28: 400 | AI28: 7 | AJ28: =AF28*AG28*AH28*AI28/1000000 -> 0.126 | AK28: =SUM(AI28) -> 7 | AL28: =SUM(AJ28) -> 0.126 | AN28: 2 | AO28: 10 | AP28: 300 | AQ28: 4 | AR28: =AN28*AO28*AP28*AQ28/1000000 -> 0.024 | AS28: =SUM(AQ26:AQ28) -> 20 | AT28: =SUM(AR26:AR28) -> 0.208
M29: 24 | N29: 5385 | O29: MRT | P29: 400 | Q29: 69 | R29: 69 | S29: 69 | T29: =0.7854*P29*S29*S29/1000000 -> 1.4957158 | V29: EX P ARI | X29: 13 | Y29: 8 | Z29: 400 | AA29: 1 | AB29: =X29*Y29*Z29*AA29/1000000 -> 0.0416 | AF29: 3 | AG29: 12.5 | AH29: 400 | AI29: 2 | AJ29: =AF29*AG29*AH29*AI29/1000000 -> 0.03 | AK29: =SUM(AI29) -> 2 | AL29: =SUM(AJ29) -> 0.03 | AN29: BELI MASAK EX PLAT | AQ29: =SUM(AQ26:AQ28) -> 20 | AR29: =SUM(AR26:AR28) -> 0.208 | AS29: =SUM(AS26:AS28) -> 20 | AT29: =SUM(AT26:AT28) -> 0.208
B30: PENERIMAAN APM | M30: 25 | N30: 5343 | O30: MRT | P30: 400 | Q30: 68 | R30: 68 | S30: 68 | T30: =0.7854*P30*S30*S30/1000000 -> 1.4526758 | V30: EX P ARI | X30: 13 | Y30: 5 | Z30: 400 | AA30: 2 | AB30: =X30*Y30*Z30*AA30/1000000 -> 0.052 | AC30: =SUM(AA19:AA30) -> 131 | AD30: =SUM(AB19:AB30) -> 14.3156 | AF30: 2 | AG30: 15 | AH30: 400 | AI30: 2 | AJ30: =AF30*AG30*AH30*AI30/1000000 -> 0.024 | AK30: =SUM(AI30) -> 2 | AL30: =SUM(AJ30) -> 0.024 | AQ30: =SUM(AQ25,AQ29) -> 137 | AR30: =SUM(AR25,AR29) -> 5.5179 | AS30: =SUM(AS25,AS29) -> 137 | AT30: =SUM(AT25,AT29) -> 5.5179
B31: EX KLATENG | E31: GRADE APM | G31: LKL / AF | H31: JUAL LOKAL | J31: SISA STOCK | M31: 26 | N31: 5381 | O31: MRT | P31: 400 | Q31: 75 | R31: 75 | S31: 75 | T31: =0.7854*P31*S31*S31/1000000 -> 1.76715 | V31: EX P ARI | X31: 12 | Y31: 25 | Z31: 400 | AA31: 2 | AB31: =X31*Y31*Z31*AA31/1000000 -> 0.24 | AF31: 2 | AG31: 10 | AH31: 400 | AI31: 45 | AJ31: =AF31*AG31*AH31*AI31/1000000 -> 0.36
B32: 1 | C32: 34.1596 | E32: 26.0721 | G32: 8.155 | J32: =SUM(G32-H32) -> 8.155 | M32: 27 | N32: 5382 | O32: MRT | P32: 400 | Q32: 66 | R32: 66 | S32: 66 | T32: =0.7854*P32*S32*S32/1000000 -> 1.368481 | V32: EX P ARI | X32: 12 | Y32: 15 | Z32: 400 | AA32: 1 | AB32: =X32*Y32*Z32*AA32/1000000 -> 0.072 | AC32: =SUM(AA31:AA32) -> 3 | AD32: =SUM(AB31:AB32) -> 0.312 | AF32: 2 | AG32: 10 | AH32: 250 | AI32: 2 | AJ32: =AF32*AG32*AH32*AI32/1000000 -> 0.01
B33: 2 | C33: 35.8378 | E33: 24.0445 | G33: 11.4261 | H33: 10.308 | J33: =SUM(G33-H33) -> 1.1181 | M33: 28 | N33: 5365 | O33: MRT | P33: 400 | Q33: 60 | R33: 60 | S33: 60 | T33: =0.7854*P33*S33*S33/1000000 -> 1.130976 | V33: EX P ARI | X33: 10 | Y33: 33 | Z33: 400 | AA33: 6 | AB33: =X33*Y33*Z33*AA33/1000000 -> 0.792 | AF33: 2 | AG33: 10 | AH33: 200 | AI33: 3 | AJ33: =AF33*AG33*AH33*AI33/1000000 -> 0.012 | AK33: =SUM(AI31:AI33) -> 50 | AL33: =SUM(AJ31:AJ33) -> 0.382
B34: 3 | C34: 37.355 | E34: 27.5829 | G34: 8.6632 | J34: =SUM(G34-H34) -> 8.6632 | M34: 29 | N34: 5321 | O34: MRT | P34: 400 | Q34: 58 | R34: 58 | S34: 58 | T34: =0.7854*P34*S34*S34/1000000 -> 1.0568342 | V34: EX P ARI | X34: 10 | Y34: 30 | Z34: 400 | AA34: 42 | AB34: =X34*Y34*Z34*AA34/1000000 -> 5.04 | AF34: BENGKIRAI | AI34: =SUM(AI16:AI33) -> 163 | AJ34: =SUM(AJ16:AJ33) -> 4.663136 | AK34: =SUM(AK16:AK33) -> 163 | AL34: =SUM(AL16:AL33) -> 4.663136
B35: 5 | C35: 35.0564 | E35: 21.4274 | G35: 12.9822 | J35: =SUM(G35-H35) -> 12.9822 | M35: 30 | N35: 5245 | O35: MRT | P35: 400 | Q35: 66 | R35: 66 | S35: 66 | T35: =0.7854*P35*S35*S35/1000000 -> 1.368481 | V35: EX P ARI | X35: 10 | Y35: 28 | Z35: 400 | AA35: 4 | AB35: =X35*Y35*Z35*AA35/1000000 -> 0.448 | AI35: =SUM(AI34,AI15) -> 903 | AJ35: =SUM(AJ34,AJ15) -> 15.091156 | AK35: =SUM(AK34,AK15) -> 903 | AL35: =SUM(AL34,AL15) -> 15.091156
C36: =SUM(C32:D34) -> 107.3524 | E36: =SUM(E32:F35) -> 99.1269 | G36: =SUM(G32:G35) -> 41.2265 | H36: =SUM(H33:H34) -> 10.308 | J36: =SUM(G36-H36) -> 30.9185 | M36: 31 | N36: 5358 | O36: MRT | P36: 400 | Q36: 65 | R36: 65 | S36: 65 | T36: =0.7854*P36*S36*S36/1000000 -> 1.327326 | V36: EX P ARI | X36: 10 | Y36: 25 | Z36: 400 | AA36: 104 | AB36: =X36*Y36*Z36*AA36/1000000 -> 10.4
M37: 32 | N37: 5356 | O37: MRT | P37: 400 | Q37: 49 | R37: 49 | S37: 49 | T37: =0.7854*P37*S37*S37/1000000 -> 0.75429816 | V37: EX P ARI | X37: 10 | Y37: 23 | Z37: 400 | AA37: 31 | AB37: =X37*Y37*Z37*AA37/1000000 -> 2.852
B38: PENERIMAAN BABAT LAMONGAN | M38: 33 | N38: 5347 | O38: MRT | P38: 400 | Q38: 45 | R38: 45 | S38: 45 | T38: =0.7854*P38*S38*S38/1000000 -> 0.636174 | V38: EX P ARI | X38: 10 | Y38: 20 | Z38: 400 | AA38: 148 | AB38: =X38*Y38*Z38*AA38/1000000 -> 11.84
B39: EX KLATENG | E39: OK GRADE BKR | G39: LKL / AF | H39: JUAL LOKAL | J39: SISA STOCK | M39: 34 | N39: 5341 | O39: MRT | P39: 400 | Q39: 55 | R39: 55 | S39: 55 | T39: =0.7854*P39*S39*S39/1000000 -> 0.950334 | V39: EX P ARI | X39: 10 | Y39: 18 | Z39: 400 | AA39: 37 | AB39: =X39*Y39*Z39*AA39/1000000 -> 2.664
B40: 4 | C40: =SUM('[2]DATA MUAT'!$X$23,'[2]DATA MUAT'!$X$55,'[2]DATA MUAT'!$X$92) -> 21.809575 | E40: =SUM('[3]HASIL GRADE'!$F$35) -> 9.7577 | G40: =SUM('[3]HASIL GRADE'!$H$72,'[3]HASIL GRADE'!$H$75,'[3]HASIL GRADE'!$H$80) -> 12.0765 | H40: =SUM('[1]INV-LOKAL MERANTI KALTENG'!G52,'[1]INV-LOKAL MERANTI KALTENG'!G30) -> 2.743 | J40: =SUM(G40-H40) -> 9.3335 | M40: 35 | N40: 5336 | O40: MRT | P40: 400 | Q40: 55 | R40: 55 | S40: 55 | T40: =0.7854*P40*S40*S40/1000000 -> 0.950334 | V40: EX P ARI | X40: 10 | Y40: 15 | Z40: 400 | AA40: 91 | AB40: =X40*Y40*Z40*AA40/1000000 -> 5.46
...

Sheet INPUT LOG
B1: INPUT LOG MERANTI | N1: INPUT LOG BENGKIRAI | X1: INPUT LOG BENGKIRAI
B4: TGL | C4: CODE | D4: JENIS | E4: VOLUME | K4: KET | N4: TGL | O4: CODE | P4: JENIS | Q4: VOLUME | U4: KET | X4: TGL | Y4: CODE | Z4: JENIS | AA4: VOLUME | AE4: KET
E5: PJG | F5: PKL | G5: UJUNG | H5: RT | I5: M3 | J5: JML | Q5: PJG | R5: RT | S5: M3 | T5: JML | AA5: PJG | AB5: RT | AC5: M3 | AD5: JML
B6: OUT | C6: 5357 | D6: MRT | E6: 400 | F6: 48 | G6: 48 | H6: 48 | I6: =0.7854*E6*H6*H6/1000000 -> 0.72382464 | K6: EX P ARI | N6: 46172 | O6: 5367 | P6: BKR | Q6: 400 | R6: 32 | S6: =0.7854*Q6*R6*R6/1000000 -> 0.32169984 | U6: EX P IS | X6: 46172 | Y6: 5367 | Z6: BKR | AA6: 400 | AB6: 32 | AC6: =0.7854*AA6*AB6*AB6/1000000 -> 0.32169984 | AE6: EX P IS
C7: 5746 | D7: MRT | E7: 400 | F7: 48 | G7: 48 | H7: 48 | I7: =0.7854*E7*H7*H7/1000000 -> 0.72382464 | K7: EX P BADI | N7: 46172 | O7: 5375 | P7: BKR | Q7: 400 | R7: 34 | S7: =0.7854*Q7*R7*R7/1000000 -> 0.36316896 | U7: EX P IS | X7: 46172 | Y7: 5375 | Z7: BKR | AA7: 400 | AB7: 34 | AC7: =0.7854*AA7*AB7*AB7/1000000 -> 0.36316896 | AE7: EX P IS
C8: 5766 | D8: MRT | E8: 400 | F8: 41 | G8: 41 | H8: 41 | I8: =0.7854*E8*H8*H8/1000000 -> 0.52810296 | K8: EX P BADI | N8: 46172 | O8: 5334 | P8: BKR | Q8: 400 | R8: 37 | S8: =0.7854*Q8*R8*R8/1000000 -> 0.43008504 | U8: EX P IS | X8: 46172 | Y8: 5334 | Z8: BKR | AA8: 400 | AB8: 37 | AC8: =0.7854*AA8*AB8*AB8/1000000 -> 0.43008504 | AE8: EX P IS
C9: 5750 | D9: MRT | E9: 400 | F9: 62 | G9: 62 | H9: 62 | I9: =0.7854*E9*H9*H9/1000000 -> 1.207631 | K9: EX P BADI | N9: 46172 | O9: 5378 | P9: BKR | Q9: 400 | R9: 37 | S9: =0.7854*Q9*R9*R9/1000000 -> 0.43008504 | U9: EX P IS | X9: 46172 | Y9: 5378 | Z9: BKR | AA9: 400 | AB9: 37 | AC9: =0.7854*AA9*AB9*AB9/1000000 -> 0.43008504 | AE9: EX P IS
C10: 5751 | D10: MRT | E10: 400 | F10: 45 | G10: 45 | H10: 45 | I10: =0.7854*E10*H10*H10/1000000 -> 0.636174 | K10: EX P BADI | N10: 46172 | O10: 5345 | P10: BKR | Q10: 400 | R10: 45 | S10: =0.7854*Q10*R10*R10/1000000 -> 0.636174 | U10: EX P IS | X10: 46172 | Y10: 5345 | Z10: BKR | AA10: 400 | AB10: 45 | AC10: =0.7854*AA10*AB10*AB10/1000000 -> 0.636174 | AE10: EX P IS
C11: 5743 | D11: MRT | E11: 400 | F11: 42 | G11: 42 | H11: 42 | I11: =0.7854*E11*H11*H11/1000000 -> 0.55417824 | J11: =SUM(I6:I11) -> 4.3737355 | K11: EX P BADI | N11: 46172 | O11: 5360 | P11: BKR | Q11: 300 | R11: 40 | S11: =0.7854*Q11*R11*R11/1000000 -> 0.376992 | U11: EX P IS | X11: 46172 | Y11: 5360 | Z11: BKR | AA11: 300 | AB11: 40 | AC11: =0.7854*AA11*AB11*AB11/1000000 -> 0.376992 | AE11: EX P IS
B12: 19/06 | C12: 5630 | D12: MRT | E12: 400 | F12: 40 | G12: 40 | H12: 40 | I12: =0.7854*E12*H12*H12/1000000 -> 0.502656 | K12: EX P AMG | N12: 46168 | O12: 5327 | P12: BKR | Q12: 400 | R12: 47 | S12: =0.7854*Q12*R12*R12/1000000 -> 0.69397944 | U12: EX P BADI | X12: 46168 | Y12: 5327 | Z12: BKR | AA12: 400 | AB12: 47 | AC12: =0.7854*AA12*AB12*AB12/1000000 -> 0.69397944 | AE12: EX P BADI
C13: 5800 | D13: MRT | E13: 400 | F13: 36 | G13: 36 | H13: 36 | I13: =0.7854*E13*H13*H13/1000000 -> 0.40715136 | K13: EX P BADI | N13: 46146 | O13: 5240 | P13: BKR | Q13: 400 | R13: 40 | S13: =0.7854*Q13*R13*R13/1000000 -> 0.502656 | U13: EX P APIN | X13: 46146 | Y13: 5240 | Z13: BKR | AA13: 400 | AB13: 40 | AC13: =0.7854*AA13*AB13*AB13/1000000 -> 0.502656 | AE13: EX P APIN
C14: 5694 | D14: MRT | E14: 400 | F14: 41 | G14: 41 | H14: 41 | I14: =0.7854*E14*H14*H14/1000000 -> 0.52810296 | K14: EX P BADI | O14: 5516 | P14: BKR | Q14: 400 | R14: 32 | S14: =0.7854*Q14*R14*R14/1000000 -> 0.32169984 | T14: =SUM(S6:S14) -> 4.0765402 | U14: EX P APIN | Y14: 5516 | Z14: BKR | AA14: 400 | AB14: 32 | AC14: =0.7854*AA14*AB14*AB14/1000000 -> 0.32169984 | AD14: =SUM(AC6:AC14) -> 4.0765402 | AE14: EX P APIN
C15: 5742 | D15: MRT | E15: 400 | F15: 37 | G15: 37 | H15: 37 | I15: =0.7854*E15*H15*H15/1000000 -> 0.43008504 | K15: EX P BADI | N15: 46173 | O15: 5349 | P15: BKR | Q15: 400 | R15: 53 | S15: =0.7854*Q15*R15*R15/1000000 -> 0.88247544 | X15: 46173 | Y15: 5349 | Z15: BKR | AA15: 400 | AB15: 53 | AC15: =0.7854*AA15*AB15*AB15/1000000 -> 0.88247544
B16: 21/06 | C16: 5582 | D16: MRT | E16: 400 | F16: 73 | G16: 73 | H16: 73 | I16: =0.7854*E16*H16*H16/1000000 -> 1.6741586 | K16: EX P IS | N16: 46173 | O16: 5379 | P16: BKR | Q16: 400 | R16: 52 | S16: =0.7854*Q16*R16*R16/1000000 -> 0.84948864 | X16: 46173 | Y16: 5379 | Z16: BKR | AA16: 400 | AB16: 52 | AC16: =0.7854*AA16*AB16*AB16/1000000 -> 0.84948864
C17: 6050 | D17: MRT | E17: 400 | F17: 54 | G17: 54 | H17: 54 | I17: =0.7854*E17*H17*H17/1000000 -> 0.91609056 | K17: EX P BADI | N17: 46173 | O17: 5350 | P17: BKR | Q17: 400 | R17: 51 | S17: =0.7854*Q17*R17*R17/1000000 -> 0.81713016 | X17: 46173 | Y17: 5350 | Z17: BKR | AA17: 400 | AB17: 51 | AC17: =0.7854*AA17*AB17*AB17/1000000 -> 0.81713016
C18: 6053 | D18: MRT | E18: 400 | F18: 47 | G18: 47 | H18: 47 | I18: =0.7854*E18*H18*H18/1000000 -> 0.69397944 | K18: EX P BADI | N18: 46173 | O18: 5377 | P18: BKR | Q18: 400 | R18: 54 | S18: =0.7854*Q18*R18*R18/1000000 -> 0.91609056 | X18: 46173 | Y18: 5377 | Z18: BKR | AA18: 400 | AB18: 54 | AC18: =0.7854*AA18*AB18*AB18/1000000 -> 0.91609056
C19: 5979 | D19: MRT | E19: 400 | F19: 50 | G19: 50 | H19: 50 | I19: =0.7854*E19*H19*H19/1000000 -> 0.7854 | K19: EX P BADI | N19: 46168 | O19: 5316 | P19: BKR | Q19: 400 | R19: 50 | S19: =0.7854*Q19*R19*R19/1000000 -> 0.7854 | X19: 46168 | Y19: 5316 | Z19: BKR | AA19: 400 | AB19: 50 | AC19: =0.7854*AA19*AB19*AB19/1000000 -> 0.7854
C20: 5954 | D20: MRT | E20: 400 | F20: 52 | G20: 52 | H20: 52 | I20: =0.7854*E20*H20*H20/1000000 -> 0.84948864 | K20: EX P BADI | N20: 46168 | O20: 5375 | P20: BKR | Q20: 400 | R20: 52 | S20: =0.7854*Q20*R20*R20/1000000 -> 0.84948864 | T20: =SUM(S15:S20) -> 5.1000734 | X20: 46168 | Y20: 5375 | Z20: BKR | AA20: 400 | AB20: 52 | AC20: =0.7854*AA20*AB20*AB20/1000000 -> 0.84948864 | AD20: =SUM(AC15:AC20) -> 5.1000734
C21: 5970 | D21: MRT | E21: 400 | F21: 56 | G21: 56 | H21: 56 | I21: =0.7854*E21*H21*H21/1000000 -> 0.98520576 | K21: EX P BADI | N21: LOG INV - 001 | S21: =SUM(S6:S20) -> 9.1766136 | T21: =SUM(T6:T20) -> 9.1766136 | X21: LOG INV - 001 | AC21: =SUM(AC6:AC20) -> 9.1766136 | AD21: =SUM(AD6:AD20) -> 9.1766136
C22: 5937 | D22: MRT | E22: 400 | F22: 43 | G22: 43 | H22: 43 | I22: =0.7854*E22*H22*H22/1000000 -> 0.58088184 | K22: EX P HR | N22: 46182 | O22: 1 | P22: BKR | Q22: 400 | R22: 55 | S22: =0.7854*Q22*R22*R22/1000000 -> 0.950334 | U22: EX P IS | X22: 46182 | Y22: 1 | Z22: BKR | AA22: 400 | AB22: 55 | AC22: =0.7854*AA22*AB22*AB22/1000000 -> 0.950334 | AE22: EX P IS
C23: 5957 | D23: MRT | E23: 400 | F23: 61 | G23: 61 | H23: 61 | I23: =0.7854*E23*H23*H23/1000000 -> 1.1689894 | J23: =SUM(I12:I23) -> 9.5221896 | K23: EX P BADI | O23: 2 | P23: BKR | Q23: 400 | R23: 62 | S23: =0.7854*Q23*R23*R23/1000000 -> 1.207631 | U23: EX P IS | Y23: 2 | Z23: BKR | AA23: 400 | AB23: 62 | AC23: =0.7854*AA23*AB23*AB23/1000000 -> 1.207631 | AE23: EX P IS
C24: 6067 | D24: MRT | E24: 400 | F24: 64 | G24: 64 | H24: 64 | I24: =0.7854*E24*H24*H24/1000000 -> 1.2867994 | K24: EX P BADI | O24: 3 | P24: BKR | Q24: 400 | R24: 58 | S24: =0.7854*Q24*R24*R24/1000000 -> 1.0568342 | U24: EX P IS | Y24: 3 | Z24: BKR | AA24: 400 | AB24: 58 | AC24: =0.7854*AA24*AB24*AB24/1000000 -> 1.0568342 | AE24: EX P IS
C25: 6195 | D25: MRT | E25: 400 | F25: 41 | G25: 41 | H25: 41 | I25: =0.7854*E25*H25*H25/1000000 -> 0.52810296 | K25: EX P IS | O25: 4 | P25: BKR | Q25: 400 | R25: 57 | S25: =0.7854*Q25*R25*R25/1000000 -> 1.0207058 | U25: EX P IS | Y25: 4 | Z25: BKR | AA25: 400 | AB25: 57 | AC25: =0.7854*AA25*AB25*AB25/1000000 -> 1.0207058 | AE25: EX P IS
C26: 6196 | D26: MRT | E26: 400 | F26: 42 | G26: 42 | H26: 42 | I26: =0.7854*E26*H26*H26/1000000 -> 0.55417824 | K26: EX P IS | O26: 5 | P26: BKR | Q26: 400 | R26: 68 | S26: =0.7854*Q26*R26*R26/1000000 -> 1.4526758 | U26: EX P IS | Y26: 5 | Z26: BKR | AA26: 400 | AB26: 68 | AC26: =0.7854*AA26*AB26*AB26/1000000 -> 1.4526758 | AE26: EX P IS
C27: 6159 | D27: MRT | E27: 400 | F27: 44 | G27: 44 | H27: 44 | I27: =0.7854*E27*H27*H27/1000000 -> 0.60821376 | K27: EX P IS | O27: 5498 | P27: BKR | Q27: 400 | R27: 50 | S27: =0.7854*Q27*R27*R27/1000000 -> 0.7854 | T27: =SUM(S22:S27) -> 6.473581 | U27: EX P BADI | Y27: 5498 | Z27: BKR | AA27: 400 | AB27: 50 | AC27: =0.7854*AA27*AB27*AB27/1000000 -> 0.7854 | AD27: =SUM(AC22:AC27) -> 6.473581 | AE27: EX P BADI
C28: 6164 | D28: MRT | E28: 400 | F28: 43 | G28: 43 | H28: 43 | I28: =0.7854*E28*H28*H28/1000000 -> 0.58088184 | K28: EX P IS | N28: 46182 | O28: 5393 | P28: BKR | Q28: 400 | R28: 49 | S28: =0.7854*Q28*R28*R28/1000000 -> 0.75429816 | U28: EX P RASOK | X28: 46182 | Y28: 5393 | Z28: BKR | AA28: 400 | AB28: 49 | AC28: =0.7854*AA28*AB28*AB28/1000000 -> 0.75429816 | AE28: EX P RASOK
C29: 6160 | D29: MRT | E29: 400 | F29: 30 | G29: 30 | H29: 30 | I29: =0.7854*E29*H29*H29/1000000 -> 0.282744 | J29: =SUM(I24:I29) -> 3.8409202 | K29: EX P IS | O29: 5399 | P29: BKR | Q29: 400 | R29: 44 | S29: =0.7854*Q29*R29*R29/1000000 -> 0.60821376 | U29: EX P RASOK | Y29: 5399 | Z29: BKR | AA29: 400 | AB29: 44 | AC29: =0.7854*AA29*AB29*AB29/1000000 -> 0.60821376 | AE29: EX P RASOK
I30: =SUM(I6:I29) -> 17.736845 | J30: =SUM(J29,J23,J11) -> 17.736845 | O30: 441 | P30: BKR | Q30: 400 | R30: 40 | S30: =0.7854*Q30*R30*R30/1000000 -> 0.502656 | U30: EX P RASOK | Y30: 441 | Z30: BKR | AA30: 400 | AB30: 40 | AC30: =0.7854*AA30*AB30*AB30/1000000 -> 0.502656 | AE30: EX P RASOK
A31: 1 | C31: 5372 | D31: MRT | E31: 400 | F31: 38 | G31: 38 | H31: 38 | I31: =0.7854*E31*H31*H31/1000000 -> 0.45364704 | K31: EX P ARI | N31: 46179 | O31: 5402 | P31: BKR | Q31: 400 | R31: 44 | S31: =0.7854*Q31*R31*R31/1000000 -> 0.60821376 | U31: EX P IS | X31: 46179 | Y31: 5402 | Z31: BKR | AA31: 400 | AB31: 44 | AC31: =0.7854*AA31*AB31*AB31/1000000 -> 0.60821376 | AE31: EX P IS
A32: 2 | C32: 5351 | D32: MRT | E32: 400 | F32: 37 | G32: 37 | H32: 37 | I32: =0.7854*E32*H32*H32/1000000 -> 0.43008504 | K32: EX P ARI | O32: 5433 | P32: BKR | Q32: 400 | R32: 38 | S32: =0.7854*Q32*R32*R32/1000000 -> 0.45364704 | U32: EX P BADI | Y32: 5433 | Z32: BKR | AA32: 400 | AB32: 38 | AC32: =0.7854*AA32*AB32*AB32/1000000 -> 0.45364704 | AE32: EX P BADI
A33: 3 | C33: 5366 | D33: MRT | E33: 400 | F33: 39 | G33: 39 | H33: 39 | I33: =0.7854*E33*H33*H33/1000000 -> 0.47783736 | K33: EX P ARI | O33: 5521 | P33: BKR | Q33: 400 | R33: 40 | S33: =0.7854*Q33*R33*R33/1000000 -> 0.502656 | T33: =SUM(S28:S33) -> 3.4296847 | U33: EX P BADI | Y33: 5521 | Z33: BKR | AA33: 400 | AB33: 40 | AC33: =0.7854*AA33*AB33*AB33/1000000 -> 0.502656 | AD33: =SUM(AC28:AC33) -> 3.4296847 | AE33: EX P BADI
A34: 4 | C34: 5355 | D34: MRT | E34: 400 | F34: 39 | G34: 39 | H34: 39 | I34: =0.7854*E34*H34*H34/1000000 -> 0.47783736 | K34: EX P ARI | N34: LOG INV - 002 | S34: =SUM(S22:S33) -> 9.9032657 | T34: =SUM(T22:T33) -> 9.9032657 | X34: LOG INV - 002 | AC34: =SUM(AC22:AC33) -> 9.9032657 | AD34: =SUM(AD22:AD33) -> 9.9032657
A35: 5 | C35: 5426 | D35: MRT | E35: 400 | F35: 35 | G35: 35 | H35: 35 | I35: =0.7854*E35*H35*H35/1000000 -> 0.384846 | K35: EX P ARI | N35: 46144 | O35: 5268 | P35: BKR | Q35: 400 | R35: 53 | S35: =0.7854*Q35*R35*R35/1000000 -> 0.88247544 | U35: EX P IS | X35: 46144 | Y35: 5268 | Z35: BKR | AA35: 400 | AB35: 53 | AC35: =0.7854*AA35*AB35*AB35/1000000 -> 0.88247544 | AE35: EX P IS
A36: 6 | C36: 5502 | D36: MRT | E36: 400 | F36: 30 | G36: 30 | H36: 30 | I36: =0.7854*E36*H36*H36/1000000 -> 0.282744 | K36: EX RM | N36: 46144 | O36: 5265 | P36: BKR | Q36: 400 | R36: 41 | S36: =0.7854*Q36*R36*R36/1000000 -> 0.52810296 | U36: EX P IS | X36: 46144 | Y36: 5265 | Z36: BKR | AA36: 400 | AB36: 41 | AC36: =0.7854*AA36*AB36*AB36/1000000 -> 0.52810296 | AE36: EX P IS
A37: 7 | C37: 5449 | D37: MRT | E37: 400 | F37: 35 | G37: 36 | H37: 35 | I37: =0.7854*E37*H37*H37/1000000 -> 0.384846 | K37: EX RM | N37: 46144 | O37: 5270 | P37: BKR | Q37: 400 | R37: 40 | S37: =0.7854*Q37*R37*R37/1000000 -> 0.502656 | U37: EX P IS | X37: 46144 | Y37: 5270 | Z37: BKR | AA37: 400 | AB37: 40 | AC37: =0.7854*AA37*AB37*AB37/1000000 -> 0.502656 | AE37: EX P IS
A38: 8 | C38: 5344 | D38: MRT | E38: 400 | F38: 37 | G38: 37 | H38: 37 | I38: =0.7854*E38*H38*H38/1000000 -> 0.43008504 | K38: EX P IS | N38: 46144 | O38: 5240 | P38: BKR | Q38: 400 | R38: 52 | S38: =0.7854*Q38*R38*R38/1000000 -> 0.84948864 | T38: =SUM(S35:S38) -> 2.762723 | U38: EX P IS | X38: 46144 | Y38: 5240 | Z38: BKR | AA38: 400 | AB38: 52 | AC38: =0.7854*AA38*AB38*AB38/1000000 -> 0.84948864 | AD38: =SUM(AC35:AC38) -> 2.762723 | AE38: EX P IS
A39: 9 | C39: 5317 | D39: MRT | E39: 400 | F39: 34 | G39: 42 | H39: 38 | I39: =0.7854*E39*H39*H39/1000000 -> 0.45364704 | K39: EX P BADI | N39: LOG INV - 003 | S39: =SUM(S35:S38) -> 2.762723 | T39: =SUM(T38) -> 2.762723 | X39: LOG INV - 003 | AC39: =SUM(AC35:AC38) -> 2.762723 | AD39: =SUM(AD38) -> 2.762723
A40: 10 | C40: 5322 | D40: MRT | E40: 300 | F40: 30 | G40: 30 | H40: 30 | I40: =0.7854*E40*H40*H40/1000000 -> 0.212058 | K40: EX P BADI | S40: =SUM(S39,S34,S21) -> 21.842602 | T40: =SUM(T39,T34,T21) -> 21.842602 | AC40: =SUM(AC39,AC34,AC21) -> 21.842602 | AD40: =SUM(AD39,AD34,AD21) -> 21.842602
A41: 11 | C41: 354 | D41: MRT | E41: 400 | F41: 39 | G41: 38 | H41: 38 | I41: =0.7854*E41*H41*H41/1000000 -> 0.45364704 | J41: =SUM(I31:I41) -> 4.4412799 | K41: EX BJB
A42: 12 | B42: 46168 | C42: 5320 | D42: MRT | E42: 400 | F42: 51 | G42: 55 | H42: 53 | I42: =0.7854*E42*H42*H42/1000000 -> 0.88247544 | K42: EX P BADI | N42: INPUT LOG BENGKIRAI | X42: INPUT LOG BENGKIRAI
...

Sheet MERANTI
B1: INPUT LOG MERANTI | J1: HASIL PRODUKSI KAYU GERGAJIAN
B3: HARI/TGL : SABTU / 09 MEI 2026 | J3: HARI/TGL : SABTU / 09 MEI 2026
B4: NO | C4: CODE | D4: JENIS | E4: VOLUME | H4: KET | J4: NO | K4: JENIS KAYU | L4: UKURAN | O4: VOLUME | R4: KET
E5: P | F5: RT | G5: M3 | L5: T | M5: L | N5: P | O5: PAK | P5: PCS | Q5: M3
B6: 1 | C6: 366 | D6: MRT | E6: 400 | F6: 41 | G6: =0.7854*E6*F6*F6/1000000 -> 0.52810296 | H6: KOP P HERY | J6: 1 | K6: MERANTI | L6: 10 | M6: 25 | N6: 400 | P6: 1 | Q6: =L6*M6*N6*P6/1000000 -> 0.1
B7: 2 | C7: 394 | D7: MRT | E7: 400 | F7: 45 | G7: =0.7854*E7*F7*F7/1000000 -> 0.636174 | H7: KOP P HERY | J7: 2 | L7: 8 | M7: 25 | N7: 400 | P7: 3 | Q7: =L7*M7*N7*P7/1000000 -> 0.24
B8: 3 | C8: 354 | D8: MRT | E8: 400 | F8: 38 | G8: =0.7854*E8*F8*F8/1000000 -> 0.45364704 | H8: KOP P HERY | J8: 3 | L8: 10 | M8: 20 | N8: 400 | P8: 1 | Q8: =L8*M8*N8*P8/1000000 -> 0.08
B9: 4 | C9: 367 | D9: MRT | E9: 400 | F9: 45 | G9: =0.7854*E9*F9*F9/1000000 -> 0.636174 | H9: KOP P HERY | J9: 4 | L9: 8 | M9: 20 | N9: 400 | P9: 2 | Q9: =L9*M9*N9*P9/1000000 -> 0.128
B10: KAYU MERANTI | G10: =SUM(G6:G9) -> 2.254098 | J10: 5 | L10: 15 | M10: 15 | N10: 400 | P10: 1 | Q10: =L10*M10*N10*P10/1000000 -> 0.09
G11: =SUM(G10) -> 2.254098 | H11: =SUM(Q23/G11) -> 0.7057812 | J11: 6 | L11: 8 | M11: 15 | N11: 400 | P11: 1 | Q11: =L11*M11*N11*P11/1000000 -> 0.048 | R11: P HERY
J12: 7 | L12: 8 | M12: 5 | N12: 400 | P12: 1 | Q12: =L12*M12*N12*P12/1000000 -> 0.016
B13: JENIS | C13: INPUT | E13: OUTPUT | G13: RDM | J13: 8 | L13: 3.2 | M13: 13 | N13: 400 | P13: 3 | Q13: =L13*M13*N13*P13/1000000 -> 0.04992
C14: PCS | D14: M3 | E14: PCS | F14: M3 | J14: 9 | L14: 3.2 | M14: 11 | N14: 400 | P14: 1 | Q14: =L14*M14*N14*P14/1000000 -> 0.01408
A15: 09/05 | B15: MERANTI | C15: =SUM(B9) -> 4 | D15: =SUM(G11) -> 2.254098 | E15: =SUM(P23) -> 174 | F15: =SUM(Q23) -> 1.5909 | G15: =SUM(F15/D15) -> 0.7057812 | J15: 10 | L15: 4.2 | M15: 10 | N15: 400 | P15: 6 | Q15: =L15*M15*N15*P15/1000000 -> 0.1008
B16: GT | C16: =SUM(C15) -> 4 | D16: =SUM(D15) -> 2.254098 | E16: =SUM(E15) -> 174 | F16: =SUM(F15) -> 1.5909 | G16: =SUM(G15) -> 0.7057812 | J16: 11 | L16: 4.2 | M16: 7 | N16: 400 | P16: 5 | Q16: =L16*M16*N16*P16/1000000 -> 0.0588
J17: 12 | L17: 4.2 | M17: 7 | N17: 300 | P17: 1 | Q17: =L17*M17*N17*P17/1000000 -> 0.00882
B18: MERANTI | D18: =SUM(Q19) -> 1.0509 | E18: =SUM(D18/D16) -> 0.46621753 | J18: 13 | L18: 3.2 | M18: 7 | N18: 400 | P18: 13 | Q18: =L18*M18*N18*P18/1000000 -> 0.11648
B19: RENG | D19: =SUM(Q22) -> 0.54 | E19: =SUM(D19/D16) -> 0.23956367 | P19: =SUM(P6:P18) -> 39 | Q19: =SUM(Q6:Q18) -> 1.0509 | R19: =SUM(Q19/G11) -> 0.46621753
D20: =SUM(D18:D19) -> 1.5909 | E20: =SUM(E18:E19) -> 0.7057812 | J20: 14 | L20: 3 | M20: 5 | N20: 400 | O20: 5 | P20: 60 | Q20: =L20*M20*N20*P20/1000000 -> 0.36
J21: 15 | L21: 2 | M21: 3 | N21: 400 | O21: 3 | P21: 75 | Q21: =L21*M21*N21*P21/1000000 -> 0.18
O22: =SUM(O20:O21) -> 8 | P22: =SUM(P20:P21) -> 135 | Q22: =SUM(Q20:Q21) -> 0.54 | R22: =SUM(Q22/G11) -> 0.23956367
O23: =SUM(O20:O22) -> 16 | P23: =SUM(P22,P19) -> 174 | Q23: =SUM(Q22,Q19) -> 1.5909 | R23: =SUM(Q23/G11) -> 0.7057812
B25: INPUT LOG MERANTI | J25: HASIL PRODUKSI KAYU GERGAJIAN
B27: HARI/TGL: RABU / 27 MEI 2026 | J27: HARI/TGL : RABU / 27 MEI 2026
B28: NO | C28: CODE | D28: JENIS | E28: VOLUME | H28: KET | J28: NO | K28: JENIS KAYU | L28: UKURAN | O28: VOLUME | R28: KET
E29: P | F29: RT | G29: M3 | L29: T | M29: L | N29: P | O29: PAK | P29: PCS | Q29: M3
B30: 1 | C30: 5388 | D30: MRT | E30: 400 | F30: 52 | G30: =0.7854*E30*F30*F30/1000000 -> 0.84948864 | H30: EX BPK IS | J30: 1 | K30: MERANTI | L30: 15 | M30: 20 | N30: 400 | P30: 1 | Q30: =L30*M30*N30*P30/1000000 -> 0.12
B31: 2 | C31: 5387 | D31: MRT | E31: 400 | F31: 57 | G31: =0.7854*E31*F31*F31/1000000 -> 1.0207058 | H31: EX BPK IS | J31: 2 | L31: 10 | M31: 25 | N31: 400 | P31: 1 | Q31: =L31*M31*N31*P31/1000000 -> 0.1
B32: 3 | C32: 5330 | D32: MRT | E32: 400 | F32: 49 | G32: =0.7854*E32*F32*F32/1000000 -> 0.75429816 | H32: EX BPK IS | J32: 3 | L32: 10 | M32: 20 | N32: 400 | P32: 3 | Q32: =L32*M32*N32*P32/1000000 -> 0.24
B33: 4 | C33: 5370 | D33: MRT | E33: 400 | F33: 56 | G33: =0.7854*E33*F33*F33/1000000 -> 0.98520576 | H33: EX BPK IS | J33: 4 | L33: 8 | M33: 25 | N33: 400 | P33: 2 | Q33: =L33*M33*N33*P33/1000000 -> 0.16
B34: 5 | C34: 5369 | D34: MRT | E34: 400 | F34: 60 | G34: =0.7854*E34*F34*F34/1000000 -> 1.130976 | H34: EX BPK IS | J34: 5 | L34: 8 | M34: 20 | N34: 400 | P34: 1 | Q34: =L34*M34*N34*P34/1000000 -> 0.064 | R34: P HERY
G35: =SUM(G30:G34) -> 4.7406744 | J35: 6 | L35: 8 | M35: 15 | N35: 400 | P35: 4 | Q35: =L35*M35*N35*P35/1000000 -> 0.192
G36: =SUM(G35) -> 4.7406744 | H36: =SUM(Q48/G36) -> 0.58437255 | J36: 7 | L36: 8 | M36: 10 | N36: 400 | P36: 2 | Q36: =L36*M36*N36*P36/1000000 -> 0.064
J37: 8 | L37: 8 | M37: 5 | N37: 400 | P37: 1 | Q37: =L37*M37*N37*P37/1000000 -> 0.016
B38: TGL 09-27 MEI 2026 | J38: 9 | L38: 3.2 | M38: 13 | N38: 400 | P38: 4 | Q38: =L38*M38*N38*P38/1000000 -> 0.06656
B39: JENIS | C39: INPUT | E39: OUTPUT | G39: RDM | J39: 10 | L39: 3.2 | M39: 11 | N39: 400 | P39: 5 | Q39: =L39*M39*N39*P39/1000000 -> 0.0704
C40: PCS | D40: M3 | E40: PCS | F40: M3 | J40: 11 | L40: 3.2 | M40: 11 | N40: 300 | P40: 1 | Q40: =L40*M40*N40*P40/1000000 -> 0.01056
A41: 09/05 | B41: MERANTI | C41: =SUM(C15) -> 4 | D41: =SUM(D15) -> 2.254098 | E41: =SUM(E15) -> 174 | F41: =SUM(F15) -> 1.5909 | G41: =SUM(F41/D41) -> 0.7057812 | J41: 12 | L41: 4.2 | M41: 10 | N41: 400 | P41: 6 | Q41: =L41*M41*N41*P41/1000000 -> 0.1008
A42: 27/05 | B42: MERANTI | C42: =SUM(B34) -> 5 | D42: =SUM(G36) -> 4.7406744 | E42: =SUM(P48) -> 301 | F42: =SUM(Q48) -> 2.77032 | G42: =SUM(F42/D42) -> 0.58437255 | J42: 13 | L42: 4.2 | M42: 7 | N42: 400 | P42: 19 | Q42: =L42*M42*N42*P42/1000000 -> 0.22344
B43: GT | C43: =SUM(C41:C42) -> 9 | D43: =SUM(D41:D42) -> 6.9947724 | E43: =SUM(E41:E42) -> 475 | F43: =SUM(F41:F42) -> 4.36122 | G43: =SUM(F43/D43) -> 0.62349706 | J43: 14 | L43: 3.2 | M43: 7 | N43: 400 | P43: 36 | Q43: =L43*M43*N43*P43/1000000 -> 0.32256
...

Sheet BENGKIRAI
B1: INPUT LOG BENGKIRAI | J1: OUTPUT LOG BENGKIRAI | T1: REKAP OUTPUT GESEK BENGKIRAI EX LOG | AB1: REKAP PEMBELIAN MASAK | AH1: REKAP PLAT BENGKIRAI
B3: HARI/TGL: SABTU / 02 MEI 2026 | J3: HARI/TGL: SABTU / 02 MEI 2026
B4: NO | C4: CODE | D4: JENIS | E4: VOLUME | H4: KET | J4: NO | K4: JENIS KAYU | L4: UKURAN | O4: VOLUME | R4: KET | T4: TGL | U4: JENIS KAYU | V4: IN / OUT LOG | Z4: JUMLAH | AB4: TGL | AC4: JENIS KAYU | AD4: VOLUME | AF4: JUMLAH | AH4: TGL | AI4: JENIS KAYU | AJ4: VOLUME | AN4: JUMLAH
E5: P | F5: RT | G5: M3 | L5: T | M5: L | N5: P | O5: PAK | P5: PCS | Q5: M3 | V5: INPUT LOG | W5: BALOK | X5: RENG | Y5: MASAK | AD5: BALOK | AE5: 2X10 | AJ5: INPUT | AK5: BALOK | AL5: RENG | AM5: MASAK
B6: 1 | C6: 5265 | D6: BKR | E6: 400 | F6: 41 | G6: =0.7854*E6*F6*F6/1000000 -> 0.52810296 | H6: ISWANTO | J6: 1 | K6: BKR | L6: 15 | M6: 15 | N6: 400 | P6: 5 | Q6: =L6*M6*N6*P6/1000000 -> 0.45 | T6: 46144 | U6: BKR | V6: 2.7627 | W6: 1.5905 | X6: 0.36 | Z6: =SUM(W6:Y6) -> 1.9505 | AB6: 46145 | AC6: BKR | AD6: 0.6619 | AE6: 0.032 | AF6: =SUM(AD6:AE6) -> 0.6939 | AH6: 46138 | AI6: BKR | AJ6: 2.7028 | AK6: 3.2316 | AL6: 0.06 | AN6: =SUM(AK6:AM6) -> 3.2916
B7: 2 | C7: 5240 | D7: BKR | E7: 400 | F7: 52 | G7: =0.7854*E7*F7*F7/1000000 -> 0.84948864 | H7: ISWANTO | J7: 2 | L7: 12 | M7: 15 | N7: 400 | P7: 2 | Q7: =L7*M7*N7*P7/1000000 -> 0.144 | T7: 46170 | V7: 2.3289 | W7: 1.0694 | X7: 0.345 | Z7: =SUM(W7:Y7) -> 1.4144 | AB7: 46186 | AD7: 0.2342 | AF7: =SUM(AD7:AE7) -> 0.2342 | AH7: 46139 | AJ7: 1.972 | AK7: 2.0183 | AM7: 0.208 | AN7: =SUM(AK7:AM7) -> 2.2263
B8: 3 | C8: 5268 | D8: BKR | E8: 400 | F8: 53 | G8: =0.7854*E8*F8*F8/1000000 -> 0.88247544 | H8: ISWANTO | J8: 3 | L8: 12 | M8: 15 | N8: 300 | P8: 1 | Q8: =L8*M8*N8*P8/1000000 -> 0.054 | T8: 46174 | V8: 1.6666 | W8: 0.8731 | X8: 0.12 | Z8: =SUM(W8:Y8) -> 0.9931 | AD8: 0.3182 | AE8: 0.008 | AF8: =SUM(AD8:AE8) -> 0.3262 | AH8: 46209 | AJ8: 13.3378 | AK8: 5.0787 | AM8: 0.036 | AN8: =SUM(AK8:AM8) -> 5.1147
B9: 4 | C9: 5270 | D9: BKR | E9: 400 | F9: 40 | G9: =0.7854*E9*F9*F9/1000000 -> 0.502656 | H9: ISWANTO | J9: 4 | L9: 10 | M9: 15 | N9: 400 | P9: 4 | Q9: =L9*M9*N9*P9/1000000 -> 0.24 | V9: 2.5582 | W9: 1.1688 | X9: 0.225 | Z9: =SUM(W9:Y9) -> 1.3938 | AB9: 46193 | AD9: 0.384 | AE9: 0.024 | AF9: =SUM(AD9:AE9) -> 0.408 | AK9: 7.2833 | AN9: =SUM(AK9:AM9) -> 7.2833
B10: KAYU BENGKIRAI | G10: =SUM(G6:G9) -> 2.762723 | J10: 5 | L10: 8 | M10: 15 | N10: 400 | P10: 1 | Q10: =L10*M10*N10*P10/1000000 -> 0.048 | R10: BJB | T10: 46175 | V10: 0.8825 | W10: 0.4142 | X10: 0.12 | Z10: =SUM(W10:Y10) -> 0.5342 | AB10: 46194 | AD10: 0.186 | AF10: =SUM(AD10:AE10) -> 0.186 | AK10: 0.6503 | AN10: =SUM(AK10:AM10) -> 0.6503
G11: =SUM(G10) -> 2.762723 | H11: =SUM(Q23/G11) -> 0.70600635 | J11: 6 | L11: 6 | M11: 15 | N11: 400 | P11: 3 | Q11: =L11*M11*N11*P11/1000000 -> 0.108 | T11: 46176 | V11: 0.9161 | W11: 0.397 | X11: 0.06 | Z11: =SUM(W11:Y11) -> 0.457 | AB11: 46199 | AD11: 0.462 | AE11: 0.136 | AF11: =SUM(AD11:AE11) -> 0.598 | AH11: 46213 | AJ11: 6.3305 | AK11: 6.3957 | AL11: 0.06 | AN11: =SUM(AK11:AM11) -> 6.4557
B12: TGL 02 MEI 2026 | J12: 7 | L12: 3 | M12: 15 | N12: 400 | P12: 4 | Q12: =L12*M12*N12*P12/1000000 -> 0.072 | T12: 46180 | V12: 0.8244 | W12: 0.4666 | X12: 0.06 | Z12: =SUM(W12:Y12) -> 0.5266 | AB12: 46201 | AD12: 1.598 | AE12: 0.16 | AF12: =SUM(AD12:AE12) -> 1.758 | AJ12: =SUM(AJ6:AJ11) -> 24.3431 | AK12: =SUM(AK6:AK11) -> 24.6579 | AL12: =SUM(AL6:AL11) -> 0.12 | AM12: =SUM(AM6:AM11) -> 0.244 | AN12: =SUM(AN6:AN11) -> 25.0219
B13: JENIS | C13: INPUT | E13: OUTPUT | G13: RDM | J13: 8 | L13: 3 | M13: 13 | N13: 400 | P13: 2 | Q13: =L13*M13*N13*P13/1000000 -> 0.0312 | T13: 46181 | V13: 1.7417 | W13: 1.0472 | X13: 0.12 | Z13: =SUM(W13:Y13) -> 1.1672 | AB13: 46202 | AD13: 0.49 | AF13: =SUM(AD13:AE13) -> 0.49
C14: PCS | D14: M3 | E14: PCS | F14: M3 | J14: 9 | L14: 9.5 | M14: 9.5 | N14: 400 | P14: 3 | Q14: =L14*M14*N14*P14/1000000 -> 0.1083 | T14: 46182 | V14: 0.6082 | W14: 0.76 | X14: 0 | Y14: 0.7152 | Z14: =SUM(W14:Y14) -> 1.4752 | AB14: 46208 | AD14: 0.384 | AE14: 0.07 | AF14: =SUM(AD14:AE14) -> 0.454 | AH14: REKAP BENGKIRAI
A15: 02/05 | B15: BKR | C15: =SUM(B9) -> 4 | D15: =SUM(G11) -> 2.762723 | E15: =SUM(P23) -> 190 | F15: =SUM(Q23) -> 1.9505 | G15: =SUM(F15/D15) -> 0.70600635 | J15: 10 | L15: 2 | M15: 10 | N15: 400 | P15: 36 | Q15: =L15*M15*N15*P15/1000000 -> 0.288 | V15: 1.8652 | W15: 0.7896 | X15: 0.24 | Z15: =SUM(W15:Y15) -> 1.0296 | AB15: 46210 | AD15: 0.348 | AF15: =SUM(AD15:AE15) -> 0.348 | AH15: INPUT GESEK | AJ15: 26.0288
B16: GT | C16: =SUM(C15) -> 4 | D16: =SUM(D15) -> 2.762723 | E16: =SUM(E15) -> 190 | F16: =SUM(F15) -> 1.9505 | G16: =SUM(G15) -> 0.70600635 | J16: 11 | L16: 2 | M16: 10 | N16: 300 | P16: 4 | Q16: =L16*M16*N16*P16/1000000 -> 0.024 | T16: 46183 | V16: 5.6882 | W16: 3.1621 | X16: 0.6 | Z16: =SUM(W16:Y16) -> 3.7621 | AB16: 46211 | AD16: 3.1204 | AE16: 0.314 | AF16: =SUM(AD16:AE16) -> 3.4344 | AH16: OUTPUT GESEK | AJ16: 14.0637
J17: 12 | L17: 2 | M17: 10 | N17: 250 | P17: 3 | Q17: =L17*M17*N17*P17/1000000 -> 0.015 | V17: 0.7543 | W17: 0.3892 | X17: 0 | Z17: =SUM(W17:Y17) -> 0.3892 | AD17: 0.09 | AF17: =SUM(AD17:AE17) -> 0.09 | AH17: RENG | AJ17: 2.8388 | AK17: =SUM(AJ16:AJ17) -> 16.9025 | AL17: =SUM(AK17/AJ15) -> 0.64937684
B18: BENGKIRAI | D18: =SUM(Q19) -> 1.5905 | J18: 13 | L18: 2 | M18: 10 | N18: 200 | P18: 2 | Q18: =L18*M18*N18*P18/1000000 -> 0.008 | T18: 46232 | V18: 2.767 | W18: 1.6708 | X18: 0.3552 | Z18: =SUM(W18:Y18) -> 2.026 | AB18: 46210 | AD18: 0.5045 | AE18: 0.134 | AF18: =SUM(AD18:AE18) -> 0.6385 | AH18: BELI MASAK | AJ18: 17.4464
B19: RENG | D19: =SUM(Q22) -> 0.36 | J19: JUMLAH | O19: =SUM(O6:O18) -> 0 | P19: =SUM(P6:P18) -> 70 | Q19: =SUM(Q6:Q18) -> 1.5905 | R19: =SUM(Q19/G11) -> 0.57570013 | T19: 46233 | V19: 0.6648 | W19: 0.2652 | X19: 0.2336 | Z19: =SUM(W19:Y19) -> 0.4988 | AD19: 2.348 | AE19: 0.172 | AF19: =SUM(AD19:AE19) -> 2.52 | AH19: 2X10 | AJ19: 2.216 | AK19: =SUM(AJ18:AJ19) -> 19.6624
D20: =SUM(D18:D19) -> 1.9505 | J20: 14 | L20: 3 | M20: 5 | N20: 400 | O20: 2 | P20: 20 | Q20: =L20*M20*N20*P20/1000000 -> 0.12 | V20: =SUM(V6:V19) -> 26.0288 | W20: =SUM(W6:W19) -> 14.0637 | X20: =SUM(X6:X19) -> 2.8388 | Y20: =SUM(Y6:Y19) -> 0.7152 | Z20: =SUM(Z6:Z19) -> 17.6177 | AB20: 46221 | AD20: 0.288 | AE20: 0.08 | AF20: =SUM(AD20:AE20) -> 0.368
J21: 15 | L21: 2 | M21: 3 | N21: 400 | O21: 4 | P21: 100 | Q21: =L21*M21*N21*P21/1000000 -> 0.24 | R21: BJB | AB21: 46222 | AD21: 0.408 | AE21: 0.11 | AF21: =SUM(AD21:AE21) -> 0.518 | AH21: INPUT PLAT | AJ21: 24.3431
J22: JUMLAH | O22: =SUM(O9:O21) -> 6 | P22: =SUM(P20:P21) -> 120 | Q22: =SUM(Q20:Q21) -> 0.36 | R22: =SUM(Q22/G11) -> 0.13030622 | AB22: 46223 | AD22: 3.215 | AE22: 0.32 | AF22: =SUM(AD22:AE22) -> 3.535 | AH22: BALOK | AJ22: 24.6579
O23: =SUM(O22,O19) -> 6 | P23: =SUM(P22,P19) -> 190 | Q23: =SUM(Q22,Q19) -> 1.9505 | R23: =SUM(Q23/G11) -> 0.70600635 | AB23: 46224 | AD23: 0.4705 | AE23: 0.076 | AF23: =SUM(AD23:AE23) -> 0.5465 | AH23: RENG | AJ23: 0.12 | AL23: {=SUM(AJ22:AJ23/AJ21)} -> 1.0178613
AD24: 0.342 | AE24: 0.114 | AF24: =SUM(AD24:AE24) -> 0.456 | AH24: MASAK | AJ24: 0.244 | AK24: =SUM(AJ22:AJ24) -> 25.0219
B25: INPUT LOG BENGKIRAI | J25: HASIL PRODUKSI KAYU GERGAJIAN | AB25: 46225 | AD25: 0.162 | AE25: 0.016 | AF25: =SUM(AD25:AE25) -> 0.178 | AK25: =SUM(AK17:AK24) -> 61.5868
AB26: 46226 | AD26: 0.294 | AF26: =SUM(AD26:AE26) -> 0.294 | AI26: FUSO 4 | AJ26: 21.8096
B27: HARI/TGL: SELASA / 26 MEI 2026 | J27: HARI/TGL : KAMIS / 28 MEI 2026 | AB27: 46228 | AD27: 0.132 | AF27: =SUM(AD27:AE27) -> 0.132 | AI27: FUSO 8 | AJ27: 28.2147 | AK27: =SUM(AJ26:AJ27) -> 50.0243
B28: NO | C28: CODE | D28: JENIS | E28: VOLUME | H28: KET | J28: NO | K28: JENIS KAYU | L28: UKURAN | O28: VOLUME | R28: KET | AB28: 46231 | AD28: 0.8897 | AF28: =SUM(AD28:AE28) -> 0.8897 | AK28: =SUM(AK25-AK27) -> 11.5625 | AL28: STOCK KALTENG
E29: P | F29: RT | G29: M3 | L29: T | M29: L | N29: P | O29: PAK | P29: PCS | Q29: M3 | AB29: 46233 | AD29: 0.116 | AE29: 0.45 | AF29: =SUM(AD29:AE29) -> 0.566
B30: 1 | C30: 5316 | D30: BKR | E30: 400 | F30: 50 | G30: =0.7854*E30*F30*F30/1000000 -> 0.7854 | H30: EX BPK BADI | J30: 1 | K30: BENGKIRAI | L30: 12 | M30: 15 | N30: 400 | P30: 2 | Q30: =L30*M30*N30*P30/1000000 -> 0.144 | AD30: =SUM(AD6:AD29) -> 17.4464 | AE30: =SUM(AE6:AE29) -> 2.216 | AF30: =SUM(AF6:AF29) -> 19.6624
B31: 2 | C31: 5327 | D31: BKR | E31: 400 | F31: 47 | G31: =0.7854*E31*F31*F31/1000000 -> 0.69397944 | H31: EX BPK BADI | J31: 2 | L31: 10 | M31: 15 | N31: 400 | P31: 4 | Q31: =L31*M31*N31*P31/1000000 -> 0.24
B32: 3 | C32: 5275 | D32: BKR | E32: 400 | F32: 52 | G32: =0.7854*E32*F32*F32/1000000 -> 0.84948864 | H32: EX BPK BADI | J32: 3 | L32: 6 | M32: 15 | N32: 400 | P32: 1 | Q32: =L32*M32*N32*P32/1000000 -> 0.036
B33: KAYU BENGKIRAI | G33: =SUM(G30:G32) -> 2.3288681 | J33: 4 | L33: 3 | M33: 15 | N33: 400 | P33: 5 | Q33: =L33*M33*N33*P33/1000000 -> 0.09
G34: =SUM(G33) -> 2.3288681 | H34: =SUM(Q45/G34) -> 0.60732165 | J34: 5 | L34: 9.5 | M34: 9.5 | N34: 400 | P34: 3 | Q34: =L34*M34*N34*P34/1000000 -> 0.1083
B35: TGL 02 MEI 2026-28 MEI 2026 | J35: 6 | L35: 4 | M35: 9.5 | N35: 400 | P35: 8 | Q35: =L35*M35*N35*P35/1000000 -> 0.1216
B36: JENIS | C36: INPUT | E36: OUTPUT | G36: RDM | J36: 7 | L36: 3 | M36: 13 | N36: 400 | P36: 2 | Q36: =L36*M36*N36*P36/1000000 -> 0.0312
A37: 02/05 | C37: PCS | D37: M3 | E37: PCS | F37: M3 | J37: 8 | L37: 2 | M37: 10 | N37: 400 | P37: 25 | Q37: =L37*M37*N37*P37/1000000 -> 0.2
A38: 28/05 | B38: BKR | C38: =SUM(C16) -> 4 | D38: =SUM(D16) -> 2.762723 | E38: =SUM(E16) -> 190 | F38: =SUM(F16) -> 1.9505 | G38: =SUM(F38/D38) -> 0.70600635 | J38: 9 | L38: 1.7 | M38: 10 | N38: 400 | P38: 2 | Q38: =L38*M38*N38*P38/1000000 -> 0.0136
B39: BKR | C39: =SUM(B32) -> 3 | D39: =SUM(G34) -> 2.3288681 | E39: =SUM(P45) -> 154 | F39: =SUM(Q45) -> 1.414372 | G39: =SUM(F39/D39) -> 0.60732165 | J39: 10 | L39: 4.2 | M39: 4.2 | N39: 400 | P39: 12 | Q39: =L39*M39*N39*P39/1000000 -> 0.084672
B40: GT | C40: =SUM(C38:C39) -> 7 | D40: =SUM(D38:D39) -> 5.0915911 | E40: =SUM(E38:E39) -> 344 | F40: =SUM(F38:F39) -> 3.364872 | G40: =SUM(F40/D40) -> 0.66086846 | P40: =SUM(P30:P39) -> 64 | Q40: =SUM(Q30:Q39) -> 1.069372 | R40: =SUM(Q40/G33) -> 0.45918101
J41: 11 | L41: 3 | M41: 5 | N41: 400 | P41: 30 | Q41: =L41*M41*N41*P41/1000000 -> 0.18
...

Sheet BELI MASAK
B1: HASIL GRADE MERANTI | K1: HASIL PRODUKSI KAYU GERGAJIAN
B3: HARI / TGL : SENIN / 18 MEI 2026 | K3: HARI/TGL : MINGGU / 03 MEI 2026 | R3: GROUP : P DAKE
B4: NO | C4: JENIS KAYU | D4: UKURAN | I4: KET | K4: NO | L4: JENIS KAYU | M4: UKURAN KAYU | P4: VOLUME | S4: KET
D5: T | E5: L | F5: P | G5: PCS | H5: M3 | M5: T | N5: L | O5: P | P5: PAK | Q5: PCS | R5: M3
B6: 1 | C6: MERANTI | D6: 4 | E6: 10 | F6: 400 | G6: 475 | H6: =D6*E6*F6*G6/1000000 -> 7.6 | K6: 1 | L6: BKR | M6: 15 | N6: 20 | O6: 400 | Q6: 1 | R6: =M6*N6*O6*Q6/1000000 -> 0.12
B7: 2 | D7: 4 | E7: 10 | F7: 360 | G7: 44 | H7: =D7*E7*F7*G7/1000000 -> 0.6336 | K7: 2 | M7: 12 | N7: 15 | O7: 400 | Q7: 1 | R7: =M7*N7*O7*Q7/1000000 -> 0.072
B8: 3 | D8: 4 | E8: 10 | F8: 300 | G8: 44 | H8: =D8*E8*F8*G8/1000000 -> 0.528 | K8: 3 | M8: 10 | N8: 15 | O8: 400 | Q8: 1 | R8: =M8*N8*O8*Q8/1000000 -> 0.06
K9: 4 | M9: 8 | N9: 15 | O9: 400 | Q9: 2 | R9: =M9*N9*O9*Q9/1000000 -> 0.096
B10: 4 | D10: 4 | E10: 7 | F10: 400 | G10: 76 | H10: =D10*E10*F10*G10/1000000 -> 0.8512 | K10: 5 | M10: 6 | N10: 15 | O10: 400 | Q10: 4 | R10: =M10*N10*O10*Q10/1000000 -> 0.144 | S10: BELI MASAK BJB
B11: 5 | D11: 4 | E11: 7 | F11: 360 | G11: 8 | H11: =D11*E11*F11*G11/1000000 -> 0.08064 | K11: 6 | M11: 6 | N11: 12 | O11: 400 | Q11: 2 | R11: =M11*N11*O11*Q11/1000000 -> 0.0576
B12: 6 | D12: 4 | E12: 7 | F12: 300 | G12: 14 | H12: =D12*E12*F12*G12/1000000 -> 0.1176 | K12: 7 | M12: 6 | N12: 10 | O12: 400 | Q12: 2 | R12: =M12*N12*O12*Q12/1000000 -> 0.048
K13: 8 | M13: 2 | N13: 10 | O13: 400 | Q13: 1 | R13: =M13*N13*O13*Q13/1000000 -> 0.008
B14: 7 | D14: 3 | E14: 7 | F14: 400 | G14: 55 | H14: =D14*E14*F14*G14/1000000 -> 0.462 | K14: 9 | M14: 2 | N14: 10 | O14: 250 | Q14: 2 | R14: =M14*N14*O14*Q14/1000000 -> 0.01
B15: 8 | D15: 3 | E15: 7 | F15: 360 | G15: 3 | H15: =D15*E15*F15*G15/1000000 -> 0.02268 | K15: 10 | M15: 2 | N15: 10 | O15: 200 | Q15: 1 | R15: =M15*N15*O15*Q15/1000000 -> 0.004
B16: 9 | D16: 3 | E16: 7 | F16: 300 | G16: 21 | H16: =D16*E16*F16*G16/1000000 -> 0.1323 | K16: 11 | M16: 4.2 | N16: 4.2 | O16: 400 | P16: 1 | Q16: 6 | R16: =M16*N16*O16*Q16/1000000 -> 0.042336
G17: =SUM(G6:G16) -> 740 | H17: =SUM(H6:H16) -> 10.42802 | Q17: =SUM(Q6:Q16) -> 23 | R17: =SUM(R6:R16) -> 0.661936
K18: 12 | L18: BKR | M18: 2 | N18: 10 | O18: 400 | Q18: 3 | R18: =M18*N18*O18*Q18/1000000 -> 0.024
B19: BELI MASAK MRT | D19: 10.428 | E19: 3200000 | G19: =SUM(D19*E19) -> 33369600 | K19: 13 | M19: 2 | N19: 10 | O19: 200 | Q19: 2 | R19: =M19*N19*O19*Q19/1000000 -> 0.008 | S19: BELI MASAK PRAPTO
B20: BELI MSK BKR | D20: 0.7119 | E20: 6200000 | G20: =SUM(D20*E20) -> 4413780 | L20: JUMLAH | Q20: =SUM(Q18:Q19) -> 5 | R20: =SUM(R18:R19) -> 0.032
B21: BELI MSK BKR | D21: 0.19 | E21: 5700000 | G21: =SUM(D21*E21) -> 1083000
G22: =SUM(G19:H21) -> 38866380 | L22: TOTAL | Q22: =SUM(Q20,Q17) -> 28 | R22: =SUM(R20,R17) -> 0.693936 | S22: INV-001
B24: HASIL GRADE MERANTI | K24: HASIL PRODUKSI KAYU GERGAJIAN
B26: HARI / TGL : SELASA / 18 AGUST 2026 | K26: HARI/TGL : SABTU / 13 JUNI 2026
B27: NO | C27: JENIS KAYU | D27: UKURAN | I27: KET | K27: NO | L27: JENIS KAYU | M27: UKURAN KAYU | P27: VOLUME | S27: KET
D28: T | E28: L | F28: P | G28: PCS | H28: M3 | M28: T | N28: L | O28: P | P28: PAK | Q28: PCS | R28: M3
B29: 1 | C29: MERANTI | D29: 10 | E29: 15 | F29: 400 | G29: 2 | H29: =D29*E29*F29*G29/1000000 -> 0.12 | K29: 1 | L29: BKR | M29: 6 | N29: 15 | O29: 400 | Q29: 3 | R29: =M29*N29*O29*Q29/1000000 -> 0.108
B30: 2 | D30: 10 | E30: 20 | F30: 400 | G30: 1 | H30: =D30*E30*F30*G30/1000000 -> 0.08 | K30: 2 | M30: 3 | N30: 15 | O30: 400 | Q30: 1 | R30: =M30*N30*O30*Q30/1000000 -> 0.018
B31: 3 | D31: 8 | E31: 15 | F31: 400 | G31: 1 | H31: =D31*E31*F31*G31/1000000 -> 0.048 | K31: 3 | M31: 9.5 | N31: 9.5 | O31: 400 | Q31: 2 | R31: =M31*N31*O31*Q31/1000000 -> 0.0722
B32: 4 | D32: 4.5 | E32: 15 | F32: 400 | G32: 1 | H32: =D32*E32*F32*G32/1000000 -> 0.027 | K32: 4 | M32: 4.5 | N32: 10 | O32: 400 | Q32: 2 | R32: =M32*N32*O32*Q32/1000000 -> 0.036 | S32: BELI MASAK
B33: 5 | D33: 7 | E33: 13 | F33: 400 | G33: 1 | H33: =D33*E33*F33*G33/1000000 -> 0.0364 | Q33: =SUM(Q29:Q32) -> 8 | R33: =SUM(R29:R32) -> 0.2342
B34: 6 | D34: 4.5 | E34: 13 | F34: 400 | G34: 1 | H34: =D34*E34*F34*G34/1000000 -> 0.0234 | L34: TOTAL | Q34: =SUM(Q33) -> 8 | R34: =SUM(R33) -> 0.2342
G35: =SUM(G29:G34) -> 7 | H35: =SUM(H29:H34) -> 0.3348 | I35: MASAK
B36: 1 | C36: MERANTI | D36: 13 | E36: 25 | F36: 400 | G36: 1 | H36: =D36*E36*F36*G36/1000000 -> 0.13 | K36: HASIL PRODUKSI KAYU GERGAJIAN
B37: 2 | D37: 10 | E37: 20 | F37: 400 | G37: 2 | H37: =D37*E37*F37*G37/1000000 -> 0.16
B38: 3 | D38: 8 | E38: 20 | F38: 400 | G38: 2 | H38: =D38*E38*F38*G38/1000000 -> 0.128 | K38: HARI/TGL : SABTU / 13 JUNI 2026
B39: 4 | D39: 7 | E39: 20 | F39: 400 | G39: 1 | H39: =D39*E39*F39*G39/1000000 -> 0.056 | K39: NO | L39: JENIS KAYU | M39: UKURAN KAYU | P39: VOLUME | S39: KET
B40: 5 | D40: 4.5 | E40: 20 | F40: 400 | G40: 2 | H40: =D40*E40*F40*G40/1000000 -> 0.072 | M40: T | N40: L | O40: P | P40: PAK | Q40: PCS | R40: M3
B41: 6 | D41: 10 | E41: 15 | F41: 400 | G41: 1 | H41: =D41*E41*F41*G41/1000000 -> 0.06 | K41: 1 | L41: BKR | M41: 15 | N41: 15 | O41: 400 | Q41: 1 | R41: =M41*N41*O41*Q41/1000000 -> 0.09
B42: 7 | D42: 4.5 | E42: 13 | F42: 400 | G42: 2 | H42: =D42*E42*F42*G42/1000000 -> 0.0468 | K42: 2 | M42: 8 | N42: 15 | O42: 400 | Q42: 1 | R42: =M42*N42*O42*Q42/1000000 -> 0.048
B43: 8 | D43: 7 | E43: 10 | F43: 400 | G43: 1 | H43: =D43*E43*F43*G43/1000000 -> 0.028 | K43: 3 | M43: 6 | N43: 15 | O43: 400 | Q43: 1 | R43: =M43*N43*O43*Q43/1000000 -> 0.036
...

Sheet PLAT BENGKIRAI
B1: INPUT PLAT BJB TIMANG | K1: HASIL PRODUKSI HARIAN KAYU GERGAJIAN
B3: HARI/TGL : MINGGU / 26 APRIL 2026 | K3: HARI/TGL : MINGGU / 26 APRIL 2026 | Q3: GROUP : P.DAKE
B4: NO | C4: JENIS KAYU | D4: UKURAN KAYU | G4: VOLUME | I4: KETERANGAN | K4: NO | L4: JENIS KAYU | M4: UKURAN KAYU | P4: VOLUME | S4: KETERANGAN
D5: T | E5: L | F5: P | G5: PCS | H5: M3 | M5: T | N5: L | O5: P | P5: PAK | Q5: PCS | R5: M3
B6: 1 | C6: BENGKIRAI | D6: 13 | E6: 15 | F6: 400 | G6: 1 | H6: =SUM(D6*E6*F6*G6/10^6) -> 0.078 | K6: 1 | L6: BKR | M6: 15 | N6: 15 | O6: 400 | Q6: 27 | R6: =M6*N6*O6*Q6/1000000 -> 2.43
B7: 2 | D7: 13 | E7: 15 | F7: 400 | G7: 1 | H7: =SUM(D7*E7*F7*G7/10^6) -> 0.078 | K7: 2 | M7: 13 | N7: 15 | O7: 400 | Q7: 1 | R7: =M7*N7*O7*Q7/1000000 -> 0.078
B8: 3 | D8: 12 | E8: 14 | F8: 400 | G8: 1 | H8: =SUM(D8*E8*F8*G8/10^6) -> 0.0672 | K8: 3 | M8: 8 | N8: 15 | O8: 400 | Q8: 4 | R8: =M8*N8*O8*Q8/1000000 -> 0.192
B9: 4 | D9: 14 | E9: 14 | F9: 400 | G9: 1 | H9: =SUM(D9*E9*F9*G9/10^6) -> 0.0784 | K9: 4 | M9: 6 | N9: 15 | O9: 400 | Q9: 6 | R9: =M9*N9*O9*Q9/1000000 -> 0.216 | S9: PLAT BJB EX TIMANG
B10: 5 | D10: 4 | E10: 15 | F10: 400 | G10: 1 | H10: =SUM(D10*E10*F10*G10/10^6) -> 0.024 | K10: 5 | M10: 3 | N10: 15 | O10: 400 | Q10: =9+5 -> 14 | R10: =M10*N10*O10*Q10/1000000 -> 0.252
B11: 6 | D11: 6 | E11: 12 | F11: 400 | G11: 1 | H11: =SUM(D11*E11*F11*G11/10^6) -> 0.0288 | K11: 6 | M11: 3 | N11: 13 | O11: 400 | Q11: 1 | R11: =M11*N11*O11*Q11/1000000 -> 0.0156
B12: 7 | D12: 7 | E12: 18 | F12: 400 | G12: 1 | H12: =SUM(D12*E12*F12*G12/10^6) -> 0.0504 | K12: 7 | M12: 2 | N12: 10 | O12: 400 | Q12: 6 | R12: =M12*N12*O12*Q12/1000000 -> 0.048
B13: 8 | D13: 5 | E13: 14 | F13: 400 | G13: 1 | H13: =SUM(D13*E13*F13*G13/10^6) -> 0.028 | K13: JUMLAH | P13: =SUM(P6:P12) -> 0 | Q13: =SUM(Q6:Q12) -> 59 | R13: =SUM(R6:R12) -> 3.2316
B14: 9 | D14: 12 | E14: 12 | F14: 400 | G14: 1 | H14: =SUM(D14*E14*F14*G14/10^6) -> 0.0576 | K14: 8 | M14: 2 | N14: 3 | O14: 400 | P14: 1 | Q14: 25 | R14: =M14*N14*O14*Q14/1000000 -> 0.06 | S14: PLAT BJB EX TIMANG
B15: 10 | D15: 15 | E15: 15 | F15: 400 | G15: 1 | H15: =SUM(D15*E15*F15*G15/10^6) -> 0.09 | K15: JUMLAH | P15: =SUM(P14) -> 1 | Q15: =SUM(Q14) -> 25 | R15: =SUM(R14) -> 0.06
B16: 11 | D16: 14 | E16: 14 | F16: 400 | G16: 1 | H16: =SUM(D16*E16*F16*G16/10^6) -> 0.0784
B17: 12 | D17: 15 | E17: 15 | F17: 400 | G17: 1 | H17: =SUM(D17*E17*F17*G17/10^6) -> 0.09 | K17: TOTAL | P17: =P13+P15 -> 1 | Q17: =Q13+Q15 -> 84 | R17: =R13+R15 -> 3.2916 | S17: =SUM(R17/H49) -> 1.2178482
B18: 13 | D18: 4 | E18: 14 | F18: 400 | G18: 1 | H18: =SUM(D18*E18*F18*G18/10^6) -> 0.0224
B19: 14 | D19: 4 | E19: 14 | F19: 400 | G19: 1 | H19: =SUM(D19*E19*F19*G19/10^6) -> 0.0224 | K19: INPUT | P19: 2.7028 | Q19: RNDMN | R19: =R17/P19 -> 1.2178482
B20: 15 | D20: 4 | E20: 14 | F20: 400 | G20: 1 | H20: =SUM(D20*E20*F20*G20/10^6) -> 0.0224 | Q20: BALOK | R20: =R13/P19 -> 1.195649
B21: 16 | D21: 15 | E21: 15 | F21: 400 | G21: 1 | H21: =SUM(D21*E21*F21*G21/10^6) -> 0.09 | Q21: USUK: | R21: =R15/P19 -> 0.022199201 | S21: INV-001
B22: 17 | D22: 6 | E22: 17 | F22: 400 | G22: 1 | H22: =SUM(D22*E22*F22*G22/10^6) -> 0.0408
B23: 18 | D23: 15 | E23: 17 | F23: 400 | G23: 1 | H23: =SUM(D23*E23*F23*G23/10^6) -> 0.102 | L23: TGL 26 MEI 2026
B24: 19 | D24: 12 | E24: 15 | F24: 400 | G24: 1 | H24: =SUM(D24*E24*F24*G24/10^6) -> 0.072 | L24: JENIS | M24: INPUT PLAT | O24: OUTPUT PLAT | Q24: RDM
B25: 20 | D25: 13 | E25: 15 | F25: 400 | G25: 1 | H25: =SUM(D25*E25*F25*G25/10^6) -> 0.078 | M25: PCS | N25: M3 | O25: PCS | P25: M3
B26: 21 | D26: 15 | E26: 15 | F26: 400 | G26: 1 | H26: =SUM(D26*E26*F26*G26/10^6) -> 0.09 | K26: 26/06 | L26: BKR | M26: =SUM(G49) -> 43 | N26: =SUM(H49) -> 2.7028 | O26: =SUM(Q17) -> 84 | P26: =SUM(R17) -> 3.2916 | Q26: =SUM(P26/N26) -> 1.2178482
B27: 22 | D27: 6 | E27: 12 | F27: 400 | G27: 1 | H27: =SUM(D27*E27*F27*G27/10^6) -> 0.0288 | L27: GT | M27: =SUM(M26:M26) -> 43 | N27: =SUM(N26:N26) -> 2.7028 | O27: =SUM(O26:O26) -> 84 | P27: =SUM(P26:P26) -> 3.2916 | Q27: =SUM(P27/N27) -> 1.2178482
B28: 23 | D28: 14 | E28: 14 | F28: 400 | G28: 1 | H28: =SUM(D28*E28*F28*G28/10^6) -> 0.0784
B29: 24 | D29: 4 | E29: 12 | F29: 400 | G29: 1 | H29: =SUM(D29*E29*F29*G29/10^6) -> 0.0192 | L29: BENGKIRAI | N29: =SUM(R13) -> 3.2316
B30: 25 | D30: 15 | E30: 15 | F30: 400 | G30: 1 | H30: =SUM(D30*E30*F30*G30/10^6) -> 0.09 | L30: RENG | N30: =SUM(R15) -> 0.06
B31: 26 | D31: 15 | E31: 15 | F31: 400 | G31: 1 | H31: =SUM(D31*E31*F31*G31/10^6) -> 0.09 | N31: =SUM(N29:N30) -> 3.2916
B32: 27 | D32: 6 | E32: 10 | F32: 400 | G32: 1 | H32: =SUM(D32*E32*F32*G32/10^6) -> 0.024
B33: 28 | D33: 4 | E33: 17 | F33: 400 | G33: 1 | H33: =SUM(D33*E33*F33*G33/10^6) -> 0.0272
B34: 29 | D34: 6 | E34: 14 | F34: 400 | G34: 1 | H34: =SUM(D34*E34*F34*G34/10^6) -> 0.0336
B35: 30 | D35: 12 | E35: 12 | F35: 400 | G35: 1 | H35: =SUM(D35*E35*F35*G35/10^6) -> 0.0576
B36: 31 | D36: 15 | E36: 15 | F36: 400 | G36: 1 | H36: =SUM(D36*E36*F36*G36/10^6) -> 0.09
B37: 32 | D37: 15 | E37: 15 | F37: 400 | G37: 1 | H37: =SUM(D37*E37*F37*G37/10^6) -> 0.09
B38: 33 | D38: 4 | E38: 13 | F38: 400 | G38: 1 | H38: =SUM(D38*E38*F38*G38/10^6) -> 0.0208
B39: 34 | D39: 13 | E39: 13 | F39: 400 | G39: 1 | H39: =SUM(D39*E39*F39*G39/10^6) -> 0.0676
B40: 35 | D40: 15 | E40: 15 | F40: 400 | G40: 1 | H40: =SUM(D40*E40*F40*G40/10^6) -> 0.09
B41: 36 | D41: 15 | E41: 15 | F41: 400 | G41: 1 | H41: =SUM(D41*E41*F41*G41/10^6) -> 0.09
...

Sheet Sheet1
B1: INPUT GESEK MERANTI EX LOG | J1: OUTPUT GESEK MERANTI EX LOG | T1: HASIL GRADE MERANTI | AC1: REKAP OUTPUT GESEK MERANTI EX LOG
B3: HARI/TGL : SABTU / 09 MEI 2026
B4: TGL | C4: CODE | D4: JENIS | E4: VOLUME | H4: KET | J4: TGL | K4: JENIS KAYU | L4: UKURAN | O4: VOLUME | R4: KET | T4: TGL | U4: JENIS KAYU | V4: UKURAN | AA4: KET | AC4: TGL | AD4: JENIS KAYU | AE4: IN / OUT LOG | AI4: JUMLAH
E5: P | F5: RT | G5: M3 | L5: T | M5: L | N5: P | O5: PAK | P5: PCS | Q5: M3 | V5: T | W5: L | X5: P | Y5: PCS | Z5: M3 | AE5: INPUT LOG | AF5: BALOK | AG5: RENG | AH5: MASAK
A6: 1 | B6: 46151 | C6: 366 | D6: MRT | E6: 400 | F6: 41 | G6: =0.7854*E6*F6*F6/1000000 -> 0.52810296 | H6: KOP P HERY | J6: 46151 | K6: MERANTI | L6: 10 | M6: 25 | N6: 400 | P6: 1 | Q6: =L6*M6*N6*P6/1000000 -> 0.1 | T6: 46160 | U6: MERANTI | V6: 4 | W6: 10 | X6: 400 | Y6: 475 | Z6: =V6*W6*X6*Y6/1000000 -> 7.6 | AC6: 46151 | AD6: MRT | AE6: 2.2541 | AF6: 1.0509 | AG6: 0.54 | AI6: =SUM(AF6:AH6) -> 1.5909
A7: 2 | B7: 2 | C7: 394 | D7: MRT | E7: 400 | F7: 45 | G7: =0.7854*E7*F7*F7/1000000 -> 0.636174 | H7: KOP P HERY | J7: 2 | L7: 8 | M7: 25 | N7: 400 | P7: 3 | Q7: =L7*M7*N7*P7/1000000 -> 0.24 | T7: 2 | V7: 4 | W7: 10 | X7: 360 | Y7: 44 | Z7: =V7*W7*X7*Y7/1000000 -> 0.6336 | AC7: 46169 | AE7: 4.7407 | AF7: 1.7503 | AG7: 1.02 | AI7: =SUM(AF7:AH7) -> 2.7703
